Workbook

Sheet Trades
A1: window_id | B1: stock1 | C1: stock2 | D1: entry_timestamp | E1: entry_price_1 | F1: entry_price_2 | G1: entry_price_1_slipped | H1: entry_price_2_slipped | I1: entry_zscore | J1: hedge_ratio_entry | K1: position_size_1 | L1: position_size_2 | M1: direction | N1: holding_minutes | O1: exit_reason | P1: exit_timestamp | Q1: exit_price_1 | R1: exit_price_2 | S1: exit_zscore | T1: gross_pnl | U1: gross_pnl_slipped | V1: transaction_costs | W1: net_pnl | X1: exit_price_age_1 | Y1: exit_price_age_2
A2: 0 | B2: JPM | C2: GS | D2: 24207 | E2: 306.355 | F2: 782.975 | G2: 306.32436 | H2: 783.0533 | I2: 3.594531 | J2: 0.66743015 | K2: -0.03264187 | L2: 0.0085242843 | M2: SHORT | N2: 7 | O2: signal | P2: 24214 | Q2: 305.615 | R2: 782.975 | S2: 0.36824447 | T2: 0.024154984 | U2: 0.020822539 | V2: 0.0033347938 | W2: 0.017487745 | X2: 305.615 | Y2: 782.975
A3: 0 | B3: JPM | C3: GS | D3: 24601 | E3: 310.255 | F3: 784.85 | G3: 310.22397 | H3: 784.92849 | I3: 3.7200374 | J3: 0.66743015 | K3: -0.032231551 | L3: 0.0085039198 | M3: SHORT | N3: 5 | O3: signal | P3: 24606 | Q3: 309.23 | R3: 786.1 | S3: 0.45860297 | T3: 0.04366724 | U3: 0.04033462 | V3: 0.0033347938 | W3: 0.036999827 | X3: 309.23 | Y3: 786.1
A4: 0 | B4: JPM | C4: GS | D4: 24832 | E4: 309.67 | F4: 784.45 | G4: 309.63903 | H4: 784.52845 | I4: 3.979432 | J4: 0.66743015 | K4: -0.03229244 | L4: 0.0085082561 | M4: SHORT | N4: 16 | O4: signal | P4: 24848 | Q4: 309.315 | R4: 783.6 | S4: 0.38578157 | T4: 0.0042317987 | U4: 0.00089880794 | V4: 0.0033347938 | W4: -0.0024359858 | X4: 309.315 | Y4: 783.6
A5: 0 | B5: JPM | C5: GS | D5: 24987 | E5: 310.945 | F5: 792.31 | G5: 310.97609 | H5: 792.23077 | I5: -4.4660855 | J5: 0.66743015 | K5: 0.032160028 | L5: -0.0084238511 | M5: LONG | N5: 9 | O5: signal | P5: 24996 | Q5: 311.59 | R5: 790.28 | S5: 0.2672345 | T5: 0.037843636 | U5: 0.034508411 | V5: 0.0033349268 | W5: 0.031173485 | X5: 311.59 | Y5: 790.28
A6: 0 | B6: JPM | C6: GS | D6: 25380 | E6: 305.665 | F6: 775.68 | G6: 305.69557 | H6: 775.60243 | I6: -3.6905639 | J6: 0.66743015 | K6: 0.032715555 | L6: -0.0086044522 | M6: LONG | N6: 12 | O6: signal | P6: 25392 | Q6: 307.425 | R6: 778.79 | S6: 0.21702582 | T6: 0.03081953 | U6: 0.027476236 | V6: 0.0033349268 | W6: 0.024141309 | X6: 307.425 | Y6: 778.79
A7: 0 | B7: JPM | C7: GS | D7: 25694 | E7: 308.605 | F7: 791.07 | G7: 308.57414 | H7: 791.14911 | I7: 3.6289486 | J7: 0.66743015 | K7: -0.032403882 | L7: 0.0084370555 | M7: SHORT | N7: 37 | O7: signal | P7: 25731 | Q7: 309.34 | R7: 792.03 | S7: 0.21396878 | T7: -0.01571728 | U7: -0.019055332 | V7: 0.0033347938 | W7: -0.022390126 | X7: 309.34 | Y7: 792.03
A8: 0 | B8: JPM | C8: GS | D8: 25752 | E8: 310.22 | F8: 793.57 | G8: 310.18898 | H8: 793.64936 | I8: 3.587045 | J8: 0.66743015 | K8: -0.032235188 | L8: 0.0084104761 | M8: SHORT | N8: 6 | O8: signal | P8: 25758 | Q8: 309.595 | R8: 792.46 | S8: 0.10046321 | T8: 0.010811364 | U8: 0.007479452 | V8: 0.0033347938 | W8: 0.0041446582 | X8: 309.595 | Y8: 792.46
A9: 0 | B9: JPM | C9: GS | D9: 26937 | E9: 316.57 | F9: 798.58 | G9: 316.60166 | H9: 798.50014 | I9: -3.6665215 | J9: 0.66743015 | K9: 0.03158859 | L9: -0.0083577118 | M9: LONG | N9: 5 | O9: signal | P9: 26942 | Q9: 319.07 | R9: 804.4 | S9: -0.22070535 | T9: 0.030329593 | U9: 0.026981971 | V9: 0.0033349268 | W9: 0.023647044 | X9: 319.07 | Y9: 804.4
A10: 0 | B10: JPM | C10: GS | D10: 27327 | E10: 318.785 | F10: 801.62 | G10: 318.75312 | H10: 801.70016 | I10: 3.8655947 | J10: 0.66743015 | K10: -0.031369105 | L10: 0.0083260167 | M10: SHORT | N10: 5 | O10: signal | P10: 27332 | Q10: 316.99 | R10: 797.74 | S10: 0.091473395 | T10: 0.024002598 | U10: 0.020676599 | V10: 0.0033347938 | W10: 0.017341805 | X10: 316.99 | Y10: 797.74
A11: 0 | B11: JPM | C11: GS | D11: 27717 | E11: 316.63 | F11: 816.83 | G11: 316.66166 | H11: 816.74832 | I11: -4.1191154 | J11: 0.66743015 | K11: 0.031582604 | L11: -0.0081709799 | M11: LONG | N11: 8 | O11: signal | P11: 27725 | Q11: 320.43 | R11: 829.34 | S11: -0.091250949 | T11: 0.017794938 | U11: 0.014437855 | V11: 0.0033349268 | W11: 0.011102928 | X11: 320.43 | Y11: 829.34
A12: 1 | B12: JPM | C12: GS | D12: 27902 | E12: 321.54 | F12: 832.99 | G12: 321.50785 | H12: 833.0733 | I12: 3.6646559 | J12: 0.65390315 | K12: -0.03110033 | L12: 0.007850072 | M12: SHORT | N12: 22 | O12: signal | P12: 27924 | Q12: 321.12 | R12: 832.625 | S12: 0.47150671 | T12: 0.010196862 | U12: 0.0068906486 | V12: 0.0033077371 | W12: 0.0035829115 | X12: 321.12 | Y12: 832.625
A13: 1 | B13: JPM | C13: GS | D13: 28497 | E13: 305.71 | F13: 787.29 | G13: 305.67943 | H13: 787.36873 | I13: 3.9612488 | J13: 0.65390315 | K13: -0.032710739 | L13: 0.0083057469 | M13: SHORT | N13: 7 | O13: signal | P13: 28504 | Q13: 304.365 | R13: 786.38 | S13: 0.030918091 | T13: 0.036437714 | U13: 0.033135063 | V13: 0.0033077371 | W13: 0.029827326 | X13: 304.365 | Y13: 786.38
... A138: 16 | B138: BAC | C138: USB | D138: 90259 | E138: 59.24 | F138: 62.225 | G138: 59.234076 | H138: 62.231223 | I138: 3.938376 | J138: 1.2019117 | K138: -0.16880486 | L138: 0.19315576 | M138: SHORT | N138: 31 | O138: signal | P138: 90290 | Q138: 59.23 | R138: 61.88 | S138: 0.19335895 | T138: -0.06495069 | U138: -0.06934768 | V138: 0.0044038639 | W138: -0.073751544 | X138: 59.23 | Y138: 61.88

Sheet trades edited
A1: window_id | B1: stock1 | C1: stock2 | D1: entry_timestamp | E1: entry_price_1 | F1: entry_price_2 | G1: entry_price_1_slipped | H1: entry_price_2_slipped | I1: entry_zscore | J1: hedge_ratio_entry | K1: position_size_1 | L1: position_size_2 | M1: direction | N1: holding_minutes | O1: exit_reason | P1: exit_timestamp | Q1: exit_price_1 | R1: exit_price_2 | S1: exit_zscore | T1: gross_pnl | U1: gross_pnl_slipped | V1: transaction_costs | W1: net_pnl | X1: Entry day | Y1: Exit day | Z1: VIX on entry | AE1: UK Date | AF1: US DATE | AG1: VIX ON ENTRY
A2: 0 | B2: JPM | C2: GS | D2: 24207 | E2: 306.355 | F2: 782.975 | G2: 306.32436 | H2: 783.0533 | I2: 3.594531 | J2: 0.66743015 | K2: -0.03264187 | L2: 0.0085242843 | M2: SHORT | N2: 7 | O2: signal | P2: 24214 | Q2: 305.615 | R2: 782.975 | S2: 0.36824447 | T2: 0.024154984 | U2: 0.020822539 | V2: 0.0033347938 | W2: 0.017487745 | X2: =WORKDAY(DATE(2025,8,2),INT(D2/390)) -> 45958 | Y2: =WORKDAY(DATE(2025,8,2),INT(P2/390)) -> 45958 | Z2: {=_xlfn.XLOOKUP(INT(X2),INT($AE$2:$AE$1000),$AG$2:$AG$1000,"")} -> 16.42 | AE2: =IF(ISNUMBER(AF2),DATE(YEAR(AF2),DAY(AF2),MONTH(AF2)),DATE(RIGHT(AF2,4),LEFT(AF2,2),MID(AF2,4,2))) -> 45870 | AF2: 45665 | AG2: 20.38 | AJ2: VIX at entry | AK2: Net PnL | AL2: Trades | AM2: Avg Net P&L | AN2: Win rate
A3: 0 | B3: JPM | C3: GS | D3: 24601 | E3: 310.255 | F3: 784.85 | G3: 310.22397 | H3: 784.92849 | I3: 3.7200374 | J3: 0.66743015 | K3: -0.032231551 | L3: 0.0085039198 | M3: SHORT | N3: 5 | O3: signal | P3: 24606 | Q3: 309.23 | R3: 786.1 | S3: 0.45860297 | T3: 0.04366724 | U3: 0.04033462 | V3: 0.0033347938 | W3: 0.036999827 | X3: =WORKDAY(DATE(2025,8,2),INT(D3/390)) -> 45959 | Y3: =WORKDAY(DATE(2025,8,2),INT(P3/390)) -> 45959 | Z3: {=_xlfn.XLOOKUP(INT(X3),INT($AE$2:$AE$1000),$AG$2:$AG$1000,"")} -> 16.92 | AE3: =IF(ISNUMBER(AF3),DATE(YEAR(AF3),DAY(AF3),MONTH(AF3)),DATE(RIGHT(AF3,4),LEFT(AF3,2),MID(AF3,4,2))) -> 45873 | AF3: 45755 | AG3: 17.52 | AJ3: <15 | AK3: =AL3*AM3 -> -1.6896569 | AL3: =COUNTIF(Z:Z,"<15") -> 107 | AM3: =AVERAGEIF(Z:Z,"<15",W:W) -> -0.015791186 | AN3: =COUNTIFS(Z:Z,"<15",T:T,">0")/COUNTIFS(Z:Z,"<15") -> 0.62616822
A4: 0 | B4: JPM | C4: GS | D4: 24832 | E4: 309.67 | F4: 784.45 | G4: 309.63903 | H4: 784.52845 | I4: 3.979432 | J4: 0.66743015 | K4: -0.03229244 | L4: 0.0085082561 | M4: SHORT | N4: 16 | O4: signal | P4: 24848 | Q4: 309.315 | R4: 783.6 | S4: 0.38578157 | T4: 0.0042317987 | U4: 0.00089880794 | V4: 0.0033347938 | W4: -0.0024359858 | X4: =WORKDAY(DATE(2025,8,2),INT(D4/390)) -> 45959 | Y4: =WORKDAY(DATE(2025,8,2),INT(P4/390)) -> 45959 | Z4: {=_xlfn.XLOOKUP(INT(X4),INT($AE$2:$AE$1000),$AG$2:$AG$1000,"")} -> 16.92 | AE4: =IF(ISNUMBER(AF4),DATE(YEAR(AF4),DAY(AF4),MONTH(AF4)),DATE(RIGHT(AF4,4),LEFT(AF4,2),MID(AF4,4,2))) -> 45874 | AF4: 45785 | AG4: 17.85 | AJ4: 15–20 | AK4: =AL4*AM4 -> 2.2099517 | AL4: =COUNTIFS(Z:Z,">=15",Z:Z,"<20") -> 293 | AM4: =AVERAGEIFS(W:W,Z:Z,">=15",Z:Z,"<20") -> 0.0075424972 | AN4: =COUNTIFS(Z:Z,">=15",Z:Z,"<20",T:T,">0")/COUNTIFS(Z:Z,">=15",Z:Z,"<20") -> 0.72013652
A5: 0 | B5: JPM | C5: GS | D5: 24987 | E5: 310.945 | F5: 792.31 | G5: 310.97609 | H5: 792.23077 | I5: -4.4660855 | J5: 0.66743015 | K5: 0.032160028 | L5: -0.0084238511 | M5: LONG | N5: 9 | O5: signal | P5: 24996 | Q5: 311.59 | R5: 790.28 | S5: 0.2672345 | T5: 0.037843636 | U5: 0.034508411 | V5: 0.0033349268 | W5: 0.031173485 | X5: =WORKDAY(DATE(2025,8,2),INT(D5/390)) -> 45960 | Y5: =WORKDAY(DATE(2025,8,2),INT(P5/390)) -> 45960 | Z5: {=_xlfn.XLOOKUP(INT(X5),INT($AE$2:$AE$1000),$AG$2:$AG$1000,"")} -> 16.91 | AE5: =IF(ISNUMBER(AF5),DATE(YEAR(AF5),DAY(AF5),MONTH(AF5)),DATE(RIGHT(AF5,4),LEFT(AF5,2),MID(AF5,4,2))) -> 45875 | AF5: 45816 | AG5: 16.77 | AJ5: >=20 | AK5: =AL5*AM5 -> 3.2875953 | AL5: =COUNTIFS(Z:Z,">=20") -> 164 | AM5: =AVERAGEIFS(W:W,Z:Z,">=20") -> 0.020046313 | AN5: =COUNTIFS(Z:Z,">=20",T:T,">0")/COUNTIFS(Z:Z,">=20") -> 0.74390244
A6: 0 | B6: JPM | C6: GS | D6: 25380 | E6: 305.665 | F6: 775.68 | G6: 305.69557 | H6: 775.60243 | I6: -3.6905639 | J6: 0.66743015 | K6: 0.032715555 | L6: -0.0086044522 | M6: LONG | N6: 12 | O6: signal | P6: 25392 | Q6: 307.425 | R6: 778.79 | S6: 0.21702582 | T6: 0.03081953 | U6: 0.027476236 | V6: 0.0033349268 | W6: 0.024141309 | X6: =WORKDAY(DATE(2025,8,2),INT(D6/390)) -> 45961 | Y6: =WORKDAY(DATE(2025,8,2),INT(P6/390)) -> 45961 | Z6: {=_xlfn.XLOOKUP(INT(X6),INT($AE$2:$AE$1000),$AG$2:$AG$1000,"")} -> 17.44 | AE6: =IF(ISNUMBER(AF6),DATE(YEAR(AF6),DAY(AF6),MONTH(AF6)),DATE(RIGHT(AF6,4),LEFT(AF6,2),MID(AF6,4,2))) -> 45876 | AF6: 45846 | AG6: 16.57
A7: 0 | B7: JPM | C7: GS | D7: 25694 | E7: 308.605 | F7: 791.07 | G7: 308.57414 | H7: 791.14911 | I7: 3.6289486 | J7: 0.66743015 | K7: -0.032403882 | L7: 0.0084370555 | M7: SHORT | N7: 37 | O7: signal | P7: 25731 | Q7: 309.34 | R7: 792.03 | S7: 0.21396878 | T7: -0.01571728 | U7: -0.019055332 | V7: 0.0033347938 | W7: -0.022390126 | X7: =WORKDAY(DATE(2025,8,2),INT(D7/390)) -> 45961 | Y7: =WORKDAY(DATE(2025,8,2),INT(P7/390)) -> 45961 | Z7: {=_xlfn.XLOOKUP(INT(X7),INT($AE$2:$AE$1000),$AG$2:$AG$1000,"")} -> 17.44 | AE7: =IF(ISNUMBER(AF7),DATE(YEAR(AF7),DAY(AF7),MONTH(AF7)),DATE(RIGHT(AF7,4),LEFT(AF7,2),MID(AF7,4,2))) -> 45877 | AF7: 45877 | AG7: 15.15
A8: 0 | B8: JPM | C8: GS | D8: 25752 | E8: 310.22 | F8: 793.57 | G8: 310.18898 | H8: 793.64936 | I8: 3.587045 | J8: 0.66743015 | K8: -0.032235188 | L8: 0.0084104761 | M8: SHORT | N8: 6 | O8: signal | P8: 25758 | Q8: 309.595 | R8: 792.46 | S8: 0.10046321 | T8: 0.010811364 | U8: 0.007479452 | V8: 0.0033347938 | W8: 0.0041446582 | X8: =WORKDAY(DATE(2025,8,2),INT(D8/390)) -> 45964 | Y8: =WORKDAY(DATE(2025,8,2),INT(P8/390)) -> 45964 | Z8: {=_xlfn.XLOOKUP(INT(X8),INT($AE$2:$AE$1000),$AG$2:$AG$1000,"")} -> 17.17 | AE8: =IF(ISNUMBER(AF8),DATE(YEAR(AF8),DAY(AF8),MONTH(AF8)),DATE(RIGHT(AF8,4),LEFT(AF8,2),MID(AF8,4,2))) -> 45880 | AF8: 45969 | AG8: 16.25
A9: 0 | B9: JPM | C9: GS | D9: 26937 | E9: 316.57 | F9: 798.58 | G9: 316.60166 | H9: 798.50014 | I9: -3.6665215 | J9: 0.66743015 | K9: 0.03158859 | L9: -0.0083577118 | M9: LONG | N9: 5 | O9: signal | P9: 26942 | Q9: 319.07 | R9: 804.4 | S9: -0.22070535 | T9: 0.030329593 | U9: 0.026981971 | V9: 0.0033349268 | W9: 0.023647044 | X9: =WORKDAY(DATE(2025,8,2),INT(D9/390)) -> 45967 | Y9: =WORKDAY(DATE(2025,8,2),INT(P9/390)) -> 45967 | Z9: {=_xlfn.XLOOKUP(INT(X9),INT($AE$2:$AE$1000),$AG$2:$AG$1000,"")} -> 19.5 | AE9: =IF(ISNUMBER(AF9),DATE(YEAR(AF9),DAY(AF9),MONTH(AF9)),DATE(RIGHT(AF9,4),LEFT(AF9,2),MID(AF9,4,2))) -> 45881 | AF9: 45999 | AG9: 14.73
A10: 0 | B10: JPM | C10: GS | D10: 27327 | E10: 318.785 | F10: 801.62 | G10: 318.75312 | H10: 801.70016 | I10: 3.8655947 | J10: 0.66743015 | K10: -0.031369105 | L10: 0.0083260167 | M10: SHORT | N10: 5 | O10: signal | P10: 27332 | Q10: 316.99 | R10: 797.74 | S10: 0.091473395 | T10: 0.024002598 | U10: 0.020676599 | V10: 0.0033347938 | W10: 0.017341805 | X10: =WORKDAY(DATE(2025,8,2),INT(D10/390)) -> 45968 | Y10: =WORKDAY(DATE(2025,8,2),INT(P10/390)) -> 45968 | Z10: {=_xlfn.XLOOKUP(INT(X10),INT($AE$2:$AE$1000),$AG$2:$AG$1000,"")} -> 19.08 | AE10: =IF(ISNUMBER(AF10),DATE(YEAR(AF10),DAY(AF10),MONTH(AF10)),DATE(RIGHT(AF10,4),LEFT(AF10,2),MID(AF10,4,2))) -> 45882 | AF10: 08/13/2025 | AG10: 14.49 | AJ10: Metric | AK10: OOS H1 | AL10: OOS H2
A11: 0 | B11: JPM | C11: GS | D11: 27717 | E11: 316.63 | F11: 816.83 | G11: 316.66166 | H11: 816.74832 | I11: -4.1191154 | J11: 0.66743015 | K11: 0.031582604 | L11: -0.0081709799 | M11: LONG | N11: 8 | O11: signal | P11: 27725 | Q11: 320.43 | R11: 829.34 | S11: -0.091250949 | T11: 0.017794938 | U11: 0.014437855 | V11: 0.0033349268 | W11: 0.011102928 | X11: =WORKDAY(DATE(2025,8,2),INT(D11/390)) -> 45971 | Y11: =WORKDAY(DATE(2025,8,2),INT(P11/390)) -> 45971 | Z11: {=_xlfn.XLOOKUP(INT(X11),INT($AE$2:$AE$1000),$AG$2:$AG$1000,"")} -> 17.6 | AE11: =IF(ISNUMBER(AF11),DATE(YEAR(AF11),DAY(AF11),MONTH(AF11)),DATE(RIGHT(AF11,4),LEFT(AF11,2),MID(AF11,4,2))) -> 45883 | AF11: 08/14/2025 | AG11: 14.83 | AJ11: Trades
A12: 1 | B12: BAC | C12: WFC | D12: 27901 | E12: 54.27 | F12: 86.98 | G12: 54.275427 | H12: 86.971302 | I12: -5.2945043 | J12: 0.78585231 | K12: 0.18426387 | L12: -0.090348621 | M12: LONG | N12: 23 | O12: signal | P12: 27924 | Q12: 54.35 | R12: 87.09 | S12: -0.49071198 | T12: 0.0048027609 | U12: 0.0012285884 | V12: 0.0035717474 | W12: -0.0023431591 | X12: =WORKDAY(DATE(2025,8,2),INT(D12/390)) -> 45971 | Y12: =WORKDAY(DATE(2025,8,2),INT(P12/390)) -> 45971 | Z12: {=_xlfn.XLOOKUP(INT(X12),INT($AE$2:$AE$1000),$AG$2:$AG$1000,"")} -> 17.6 | AE12: =IF(ISNUMBER(AF12),DATE(YEAR(AF12),DAY(AF12),MONTH(AF12)),DATE(RIGHT(AF12,4),LEFT(AF12,2),MID(AF12,4,2))) -> 45884 | AF12: 08/15/2025 | AG12: 15.09 | AJ12: Gross P&L
A13: 1 | B13: BAC | C13: WFC | D13: 28107 | E13: 53.855 | F13: 86.21 | G13: 53.860385 | H13: 86.201379 | I13: -4.2210563 | J13: 0.78585231 | K13: 0.18568378 | L13: -0.091155586 | M13: LONG | N13: 16 | O13: signal | P13: 28123 | Q13: 53.83 | R13: 86.07 | S13: -0.46599468 | T13: 0.0081196875 | U13: 0.0045497233 | V13: 0.0035717474 | W13: 0.00097797585 | X13: =WORKDAY(DATE(2025,8,2),INT(D13/390)) -> 45972 | Y13: =WORKDAY(DATE(2025,8,2),INT(P13/390)) -> 45972 | Z13: {=_xlfn.XLOOKUP(INT(X13),INT($AE$2:$AE$1000),$AG$2:$AG$1000,"")} -> 17.28 | AE13: =IF(ISNUMBER(AF13),DATE(YEAR(AF13),DAY(AF13),MONTH(AF13)),DATE(RIGHT(AF13,4),LEFT(AF13,2),MID(AF13,4,2))) -> 45887 | AF13: 08/18/2025 | AG13: 14.99 | AJ13: Net P&L
A14: 1 | B14: BAC | C14: WFC | D14: 28839 | E14: 52.725 | F14: 85.125 | G14: 52.730272 | H14: 85.116488 | I14: -3.745894 | J14: 0.78585231 | K14: 0.18966335 | L14: -0.092317452 | M14: LONG | N14: 19 | O14: signal | P14: 28858 | Q14: 52.615 | R14: 84.855 | S14: -0.36520226 | T14: 0.0040627437 | U14: 0.00049561794 | V14: 0.0035717474 | W14: -0.0030761295 | X14: =WORKDAY(DATE(2025,8,2),INT(D14/390)) -> 45973 | Y14: =WORKDAY(DATE(2025,8,2),INT(P14/390)) -> 45973 | Z14: {=_xlfn.XLOOKUP(INT(X14),INT($AE$2:$AE$1000),$AG$2:$AG$1000,"")} -> 17.51 | AE14: =IF(ISNUMBER(AF14),DATE(YEAR(AF14),DAY(AF14),MONTH(AF14)),DATE(RIGHT(AF14,4),LEFT(AF14,2),MID(AF14,4,2))) -> 45888 | AF14: 08/19/2025 | AG14: 15.57 | AJ14: Avg gross P&L/trade
A15: 1 | B15: BAC | C15: WFC | D15: 29105 | E15: 52.09 | F15: 84.31 | G15: 52.095209 | H15: 84.301569 | I15: -4.0396526 | J15: 0.78585231 | K15: 0.19197543 | L15: -0.093209857 | M15: LONG | N15: 17 | O15: signal | P15: 29122 | Q15: 52.035 | R15: 84.14 | S15: -0.20841839 | T15: 0.0052870272 | U15: 0.0017179631 | V15: 0.0035717474 | W15: -0.0018537844 | X15: =WORKDAY(DATE(2025,8,2),INT(D15/390)) -> 45974 | Y15: =WORKDAY(DATE(2025,8,2),INT(P15/390)) -> 45974 | Z15: {=_xlfn.XLOOKUP(INT(X15),INT($AE$2:$AE$1000),$AG$2:$AG$1000,"")} -> 20 | AE15: =IF(ISNUMBER(AF15),DATE(YEAR(AF15),DAY(AF15),MONTH(AF15)),DATE(RIGHT(AF15,4),LEFT(AF15,2),MID(AF15,4,2))) -> 45889 | AF15: 08/20/2025 | AG15: 15.69 | AJ15: Avg net P&L/trade
A16: 1 | B16: BAC | C16: WFC | D16: 29668 | E16: 51.95 | F16: 84.105 | G16: 51.944805 | H16: 84.113411 | I16: 4.3006198 | J16: 0.78585231 | K16: -0.19249278 | L16: 0.09343705 | M16: SHORT | N16: 26 | O16: signal | P16: 29694 | Q16: 52.165 | R16: 84.43 | S16: 0.40318604 | T16: -0.011018907 | U16: -0.014597787 | V16: 0.0035716618 | W16: -0.018169449 | X16: =WORKDAY(DATE(2025,8,2),INT(D16/390)) -> 45978 | Y16: =WORKDAY(DATE(2025,8,2),INT(P16/390)) -> 45978 | Z16: {=_xlfn.XLOOKUP(INT(X16),INT($AE$2:$AE$1000),$AG$2:$AG$1000,"")} -> 22.38 | AE16: =IF(ISNUMBER(AF16),DATE(YEAR(AF16),DAY(AF16),MONTH(AF16)),DATE(RIGHT(AF16,4),LEFT(AF16,2),MID(AF16,4,2))) -> 45890 | AF16: 08/21/2025 | AG16: 16.6 | AJ16: Net PF
A17: 1 | B17: BAC | C17: WFC | D17: 31217 | E17: 51.96 | F17: 84.86 | G17: 51.965196 | H17: 84.851514 | I17: -3.5614788 | J17: 0.78585231 | K17: 0.19245574 | L17: -0.09260574 | M17: LONG | N17: 20 | O17: signal | P17: 31237 | Q17: 52.51 | R17: 85.14 | S17: 0.40215492 | T17: 0.079921047 | U17: 0.076336165 | V17: 0.0035717474 | W17: 0.072764417 | X17: =WORKDAY(DATE(2025,8,2),INT(D17/390)) -> 45982 | Y17: =WORKDAY(DATE(2025,8,2),INT(P17/390)) -> 45982 | Z17: {=_xlfn.XLOOKUP(INT(X17),INT($AE$2:$AE$1000),$AG$2:$AG$1000,"")} -> 23.43 | AE17: =IF(ISNUMBER(AF17),DATE(YEAR(AF17),DAY(AF17),MONTH(AF17)),DATE(RIGHT(AF17,4),LEFT(AF17,2),MID(AF17,4,2))) -> 45891 | AF17: 08/22/2025 | AG17: 14.22 | AJ17: Win rate
A18: 1 | B18: BAC | C18: WFC | D18: 31444 | E18: 52.65 | F18: 84.8 | G18: 52.655265 | H18: 84.79152 | I18: -3.5053921 | J18: 0.78585231 | K18: 0.18993352 | L18: -0.092671263 | M18: LONG | N18: 32 | O18: signal | P18: 31476 | Q18: 52.71 | R18: 85.025 | S18: -0.49317777 | T18: -0.0094550227 | U18: -0.013029952 | V18: 0.0035717474 | W18: -0.016601699 | X18: =WORKDAY(DATE(2025,8,2),INT(D18/390)) -> 45982 | Y18: =WORKDAY(DATE(2025,8,2),INT(P18/390)) -> 45982 | Z18: {=_xlfn.XLOOKUP(INT(X18),INT($AE$2:$AE$1000),$AG$2:$AG$1000,"")} -> 23.43 | AE18: =IF(ISNUMBER(AF18),DATE(YEAR(AF18),DAY(AF18),MONTH(AF18)),DATE(RIGHT(AF18,4),LEFT(AF18,2),MID(AF18,4,2))) -> 45894 | AF18: 08/25/2025 | AG18: 14.79 | AJ18: Avg winner
A19: 1 | B19: BAC | C19: WFC | D19: 31612 | E19: 52.505 | F19: 85.055 | G19: 52.510251 | H19: 85.046495 | I19: -3.5933745 | J19: 0.78585231 | K19: 0.19045805 | L19: -0.092393429 | M19: LONG | N19: 10 | O19: signal | P19: 31622 | Q19: 52.78 | R19: 85.49 | S19: -0.050359074 | T19: 0.012184823 | U19: 0.0086038615 | V19: 0.0035717474 | W19: 0.005032114 | X19: =WORKDAY(DATE(2025,8,2),INT(D19/390)) -> 45985 | Y19: =WORKDAY(DATE(2025,8,2),INT(P19/390)) -> 45985 | Z19: {=_xlfn.XLOOKUP(INT(X19),INT($AE$2:$AE$1000),$AG$2:$AG$1000,"")} -> 20.52 | AE19: =IF(ISNUMBER(AF19),DATE(YEAR(AF19),DAY(AF19),MONTH(AF19)),DATE(RIGHT(AF19,4),LEFT(AF19,2),MID(AF19,4,2))) -> 45895 | AF19: 08/26/2025 | AG19: 14.62 | AJ19: Avg loser
A20: 1 | B20: JPM | C20: GS | D20: 27901 | E20: 321.49 | F20: 832.19 | G20: 321.45785 | H20: 832.27322 | I20: 5.2946162 | J20: 0.65390315 | K20: -0.031105167 | L20: 0.0078576185 | M20: SHORT | N20: 23 | O20: signal | P20: 27924 | Q20: 321.12 | R20: 832.625 | S20: 0.48959011 | T20: 0.014926976 | U20: 0.011619978 | V20: 0.0033077371 | W20: 0.0083122414 | X20: =WORKDAY(DATE(2025,8,2),INT(D20/390)) -> 45971 | Y20: =WORKDAY(DATE(2025,8,2),INT(P20/390)) -> 45971 | Z20: {=_xlfn.XLOOKUP(INT(X20),INT($AE$2:$AE$1000),$AG$2:$AG$1000,"")} -> 17.6 | AE20: =IF(ISNUMBER(AF20),DATE(YEAR(AF20),DAY(AF20),MONTH(AF20)),DATE(RIGHT(AF20,4),LEFT(AF20,2),MID(AF20,4,2))) -> 45896 | AF20: 08/27/2025 | AG20: 14.85 | AJ20: Avg holding time
A21: 1 | B21: JPM | C21: GS | D21: 28497 | E21: 305.71 | F21: 787.29 | G21: 305.67943 | H21: 787.36873 | I21: 3.9612488 | J21: 0.65390315 | K21: -0.032710739 | L21: 0.0083057469 | M21: SHORT | N21: 7 | O21: signal | P21: 28504 | Q21: 304.365 | R21: 786.38 | S21: 0.030918091 | T21: 0.036437714 | U21: 0.033135063 | V21: 0.0033077371 | W21: 0.029827326 | X21: =WORKDAY(DATE(2025,8,2),INT(D21/390)) -> 45973 | Y21: =WORKDAY(DATE(2025,8,2),INT(P21/390)) -> 45973 | Z21: {=_xlfn.XLOOKUP(INT(X21),INT($AE$2:$AE$1000),$AG$2:$AG$1000,"")} -> 17.51 | AE21: =IF(ISNUMBER(AF21),DATE(YEAR(AF21),DAY(AF21),MONTH(AF21)),DATE(RIGHT(AF21,4),LEFT(AF21,2),MID(AF21,4,2))) -> 45897 | AF21: 08/28/2025 | AG21: 14.43 | AJ21: Avg |entry Z|
A22: 1 | B22: JPM | C22: GS | D22: 28630 | E22: 304.8 | F22: 797.315 | G22: 304.83048 | H22: 797.23527 | I22: -3.6261084 | J22: 0.65390315 | K22: 0.032808399 | L22: -0.0082013151 | M22: LONG | N22: 9 | O22: signal | P22: 28639 | Q22: 305.47 | R22: 796.03 | S22: 0.26313253 | T22: 0.032520317 | U22: 0.029211367 | V22: 0.0033078755 | W22: 0.025903491 | X22: =WORKDAY(DATE(2025,8,2),INT(D22/390)) -> 45973 | Y22: =WORKDAY(DATE(2025,8,2),INT(P22/390)) -> 45973 | Z22: {=_xlfn.XLOOKUP(INT(X22),INT($AE$2:$AE$1000),$AG$2:$AG$1000,"")} -> 17.51 | AE22: =IF(ISNUMBER(AF22),DATE(YEAR(AF22),DAY(AF22),MONTH(AF22)),DATE(RIGHT(AF22,4),LEFT(AF22,2),MID(AF22,4,2))) -> 45898 | AF22: 08/29/2025 | AG22: 15.36
A23: 1 | B23: JPM | C23: GS | D23: 28708 | E23: 304.81 | F23: 797.11 | G23: 304.84048 | H23: 797.03029 | I23: -3.55602 | J23: 0.65390315 | K23: 0.032807323 | L23: -0.0082034243 | M23: LONG | N23: 27 | O23: signal | P23: 28735 | Q23: 304.57 | R23: 796.62 | S23: 0.12160767 | T23: -0.0038540795 | U23: -0.0071606965 | V23: 0.0033078755 | W23: -0.010468572 | X23: =WORKDAY(DATE(2025,8,2),INT(D23/390)) -> 45973 | Y23: =WORKDAY(DATE(2025,8,2),INT(P23/390)) -> 45973 | Z23: {=_xlfn.XLOOKUP(INT(X23),INT($AE$2:$AE$1000),$AG$2:$AG$1000,"")} -> 17.51 | AE23: =IF(ISNUMBER(AF23),DATE(YEAR(AF23),DAY(AF23),MONTH(AF23)),DATE(RIGHT(AF23,4),LEFT(AF23,2),MID(AF23,4,2))) -> 45901 | AF23: 45666 | AG23: 16.12
A24: 1 | B24: JPM | C24: GS | D24: 29594 | E24: 301.3 | F24: 781.25 | G24: 301.26987 | H24: 781.32812 | I24: 3.5359515 | J24: 0.65390315 | K24: -0.033189512 | L24: 0.0083699603 | M24: SHORT | N24: 5 | O24: signal | P24: 29599 | Q24: 300.495 | R24: 781.25 | S24: -0.42317359 | T24: 0.026717557 | U24: 0.023412423 | V24: 0.0033077371 | W24: 0.020104686 | X24: =WORKDAY(DATE(2025,8,2),INT(D24/390)) -> 45975 | Y24: =WORKDAY(DATE(2025,8,2),INT(P24/390)) -> 45975 | Z24: {=_xlfn.XLOOKUP(INT(X24),INT($AE$2:$AE$1000),$AG$2:$AG$1000,"")} -> 19.83 | AE24: =IF(ISNUMBER(AF24),DATE(YEAR(AF24),DAY(AF24),MONTH(AF24)),DATE(RIGHT(AF24,4),LEFT(AF24,2),MID(AF24,4,2))) -> 45902 | AF24: 45697 | AG24: 17.17
A25: 1 | B25: JPM | C25: GS | D25: 29667 | E25: 300.82 | F25: 776.07 | G25: 300.78992 | H25: 776.14761 | I25: 4.3180527 | J25: 0.65390315 | K25: -0.033242471 | L25: 0.0084258269 | M25: SHORT | N25: 24 | O25: signal | P25: 29691 | Q25: 302.36 | R25: 779.065 | S25: 0.36508655 | T25: -0.025958053 | U25: -0.029273502 | V25: 0.0033077371 | W25: -0.032581239 | X25: =WORKDAY(DATE(2025,8,2),INT(D25/390)) -> 45978 | Y25: =WORKDAY(DATE(2025,8,2),INT(P25/390)) -> 45978 | Z25: {=_xlfn.XLOOKUP(INT(X25),INT($AE$2:$AE$1000),$AG$2:$AG$1000,"")} -> 22.38 | AE25: =IF(ISNUMBER(AF25),DATE(YEAR(AF25),DAY(AF25),MONTH(AF25)),DATE(RIGHT(AF25,4),LEFT(AF25,2),MID(AF25,4,2))) -> 45903 | AF25: 45725 | AG25: 16.35
A26: 1 | B26: JPM | C26: GS | D26: 30059 | E26: 307.04 | F26: 805.745 | G26: 307.0707 | H26: 805.66443 | I26: -3.8618259 | J26: 0.65390315 | K26: 0.032569046 | L26: -0.0081155099 | M26: LONG | N26: 6 | O26: signal | P26: 30065 | Q26: 308.48 | R26: 807.56 | S26: -0.319723 | T26: 0.032169776 | U26: 0.028855807 | V26: 0.0033078755 | W26: 0.025547932 | X26: =WORKDAY(DATE(2025,8,2),INT(D26/390)) -> 45979 | Y26: =WORKDAY(DATE(2025,8,2),INT(P26/390)) -> 45979 | Z26: {=_xlfn.XLOOKUP(INT(X26),INT($AE$2:$AE$1000),$AG$2:$AG$1000,"")} -> 24.69 | AE26: =IF(ISNUMBER(AF26),DATE(YEAR(AF26),DAY(AF26),MONTH(AF26)),DATE(RIGHT(AF26,4),LEFT(AF26,2),MID(AF26,4,2))) -> 45904 | AF26: 45756 | AG26: 15.3
A27: 1 | B27: JPM | C27: GS | D27: 31217 | E27: 297.97 | F27: 792.37 | G27: 297.9998 | H27: 792.29076 | I27: -3.574562 | J27: 0.65390315 | K27: 0.033560426 | L27: -0.0082524976 | M27: LONG | N27: 10 | O27: signal | P27: 31227 | Q27: 299.32 | R27: 795.235 | S27: -0.43617298 | T27: 0.021663169 | U27: 0.018348468 | V27: 0.0033078755 | W27: 0.015040592 | X27: =WORKDAY(DATE(2025,8,2),INT(D27/390)) -> 45982 | Y27: =WORKDAY(DATE(2025,8,2),INT(P27/390)) -> 45982 | Z27: {=_xlfn.XLOOKUP(INT(X27),INT($AE$2:$AE$1000),$AG$2:$AG$1000,"")} -> 23.43 | AE27: =IF(ISNUMBER(AF27),DATE(YEAR(AF27),DAY(AF27),MONTH(AF27)),DATE(RIGHT(AF27,4),LEFT(AF27,2),MID(AF27,4,2))) -> 45905 | AF27: 45786 | AG27: 15.18
A28: 2 | B28: BAC | C28: WFC | D28: 31801 | E28: 53.09 | F28: 85.965 | G28: 53.095309 | H28: 85.956404 | I28: -5.2946208 | J28: 0.73858207 | K28: 0.18835939 | L28: -0.085916602 | M28: LONG | N28: 23 | O28: signal | P28: 31824 | Q28: 53.09 | R28: 86 | S28: -0.49061199 | T28: -0.0030070811 | U28: -0.0064845459 | V28: 0.0034772164 | W28: -0.0099617624 | X28: =WORKDAY(DATE(2025,8,2),INT(D28/390)) -> 45985 | Y28: =WORKDAY(DATE(2025,8,2),INT(P28/390)) -> 45985 | Z28: {=_xlfn.XLOOKUP(INT(X28),INT($AE$2:$AE$1000),$AG$2:$AG$1000,"")} -> 20.52 | AE28: =IF(ISNUMBER(AF28),DATE(YEAR(AF28),DAY(AF28),MONTH(AF28)),DATE(RIGHT(AF28,4),LEFT(AF28,2),MID(AF28,4,2))) -> 45908 | AF28: 45878 | AG28: 15.11
A29: 2 | B29: BAC | C29: WFC | D29: 32007 | E29: 53.05 | F29: 85.48 | G29: 53.044695 | H29: 85.488548 | I29: 4.5358082 | J29: 0.73858207 | K29: -0.18850141 | L29: 0.08640408 | M29: SHORT | N29: 48 | O29: signal | P29: 32055 | Q29: 53.64 | R29: 85.89 | S29: 0.45483687 | T29: -0.075790161 | U29: -0.07928199 | V29: 0.0034771119 | W29: -0.082759102 | X29: =WORKDAY(DATE(2025,8,2),INT(D29/390)) -> 45986 | Y29: =WORKDAY(DATE(2025,8,2),INT(P29/390)) -> 45986 | Z29: {=_xlfn.XLOOKUP(INT(X29),INT($AE$2:$AE$1000),$AG$2:$AG$1000,"")} -> 18.56 | AE29: =IF(ISNUMBER(AF29),DATE(YEAR(AF29),DAY(AF29),MONTH(AF29)),DATE(RIGHT(AF29,4),LEFT(AF29,2),MID(AF29,4,2))) -> 45909 | AF29: 45909 | AG29: 15.04
A30: 2 | B30: BAC | C30: WFC | D30: 32217 | E30: 53.525 | F30: 85.885 | G30: 53.530352 | H30: 85.876412 | I30: -4.2270289 | J30: 0.73858207 | K30: 0.18682858 | L30: -0.085996632 | M30: LONG | N30: 1 | O30: signal | P30: 32218 | Q30: 53.54 | R30: 85.66 | S30: 0.16301468 | T30: 0.022151671 | U30: 0.018676161 | V30: 0.0034772164 | W30: 0.015198945 | X30: =WORKDAY(DATE(2025,8,2),INT(D30/390)) -> 45986 | Y30: =WORKDAY(DATE(2025,8,2),INT(P30/390)) -> 45986 | Z30: {=_xlfn.XLOOKUP(INT(X30),INT($AE$2:$AE$1000),$AG$2:$AG$1000,"")} -> 18.56 | AE30: =IF(ISNUMBER(AF30),DATE(YEAR(AF30),DAY(AF30),MONTH(AF30)),DATE(RIGHT(AF30,4),LEFT(AF30,2),MID(AF30,4,2))) -> 45910 | AF30: 45939 | AG30: 15.35
A31: 2 | B31: BAC | C31: WFC | D31: 32614 | E31: 53.25 | F31: 85.77 | G31: 53.255325 | H31: 85.761423 | I31: -3.6888174 | J31: 0.73858207 | K31: 0.18779343 | L31: -0.086111936 | M31: LONG | N31: 17 | O31: signal | P31: 32631 | Q31: 53.135 | R31: 85.39 | S31: -0.28159101 | T31: 0.011126291 | U31: 0.0076545592 | V31: 0.0034772164 | W31: 0.0041773427 | X31: =WORKDAY(DATE(2025,8,2),INT(D31/390)) -> 45987 | Y31: =WORKDAY(DATE(2025,8,2),INT(P31/390)) -> 45987 | Z31: {=_xlfn.XLOOKUP(INT(X31),INT($AE$2:$AE$1000),$AG$2:$AG$1000,"")} -> 17.19 | AE31: =IF(ISNUMBER(AF31),DATE(YEAR(AF31),DAY(AF31),MONTH(AF31)),DATE(RIGHT(AF31,4),LEFT(AF31,2),MID(AF31,4,2))) -> 45911 | AF31: 45970 | AG31: 14.71
A32: 2 | B32: BAC | C32: WFC | D32: 32998 | E32: 53.3 | F32: 86.31 | G32: 53.29467 | H32: 86.318631 | I32: 4.1634247 | J32: 0.73858207 | K32: -0.18761726 | L32: 0.085573175 | M32: SHORT | N32: 17 | O32: signal | P32: 33015 | Q32: 53.525 | R32: 86.83 | S32: 0.4746937 | T32: 0.0022841673 | U32: -0.0012016681 | V32: 0.0034771119 | W32: -0.0046787799 | X32: =WORKDAY(DATE(2025,8,2),INT(D32/390)) -> 45988 | Y32: =WORKDAY(DATE(2025,8,2),INT(P32/390)) -> 45988 | Z32: {=_xlfn.XLOOKUP(INT(X32),INT($AE$2:$AE$1000),$AG$2:$AG$1000,"")} -> 17.21 | AE32: =IF(ISNUMBER(AF32),DATE(YEAR(AF32),DAY(AF32),MONTH(AF32)),DATE(RIGHT(AF32,4),LEFT(AF32,2),MID(AF32,4,2))) -> 45912 | AF32: 46000 | AG32: 14.76
A33: 2 | B33: BAC | C33: WFC | D33: 34559 | E33: 54.005 | F33: 89.76 | G33: 53.9996 | H33: 89.768976 | I33: 3.5672352 | J33: 0.73858207 | K33: -0.18516804 | L33: 0.082284099 | M33: SHORT | N33: 5 | O33: signal | P33: 34564 | Q33: 53.83 | R33: 89.755 | S33: 0.11894705 | T33: 0.031992987 | U33: 0.028519104 | V33: 0.0034771119 | W33: 0.025041992 | X33: =WORKDAY(DATE(2025,8,2),INT(D33/390)) -> 45994 | Y33: =WORKDAY(DATE(2025,8,2),INT(P33/390)) -> 45994 | Z33: {=_xlfn.XLOOKUP(INT(X33),INT($AE$2:$AE$1000),$AG$2:$AG$1000,"")} -> 16.08 | AE33: =IF(ISNUMBER(AF33),DATE(YEAR(AF33),DAY(AF33),MONTH(AF33)),DATE(RIGHT(AF33,4),LEFT(AF33,2),MID(AF33,4,2))) -> 45915 | AF33: 09/15/2025 | AG33: 15.69
A34: 2 | B34: BAC | C34: WFC | D34: 35304 | E34: 53.915 | F34: 90.32 | G34: 53.920392 | H34: 90.310968 | I34: -3.5605368 | J34: 0.73858207 | K34: 0.18547714 | L34: -0.081773923 | M34: LONG | N34: 6 | O34: signal | P34: 35310 | Q34: 54.27 | R34: 90.385 | S34: 0.059936539 | T34: 0.06052908 | U34: 0.0570448 | V34: 0.0034772164 | W34: 0.053567583 | X34: =WORKDAY(DATE(2025,8,2),INT(D34/390)) -> 45996 | Y34: =WORKDAY(DATE(2025,8,2),INT(P34/390)) -> 45996 | Z34: {=_xlfn.XLOOKUP(INT(X34),INT($AE$2:$AE$1000),$AG$2:$AG$1000,"")} -> 15.41 | AE34: =IF(ISNUMBER(AF34),DATE(YEAR(AF34),DAY(AF34),MONTH(AF34)),DATE(RIGHT(AF34,4),LEFT(AF34,2),MID(AF34,4,2))) -> 45916 | AF34: 09/16/2025 | AG34: 16.36
A35: 2 | B35: MS | C35: WFC | D35: 31801 | E35: 168.27 | F35: 85.965 | G35: 168.25317 | H35: 85.973596 | I35: 5.2944766 | J35: 0.92309383 | K35: -0.0594283 | L35: 0.10738019 | M35: SHORT | N35: 23 | O35: signal | P35: 31824 | Q35: 168.29 | R35: 86 | S35: 0.49154454 | T35: 0.0025697408 | U35: -0.0012769416 | V35: 0.0038461723 | W35: -0.0051231139 | X35: =WORKDAY(DATE(2025,8,2),INT(D35/390)) -> 45985 | Y35: =WORKDAY(DATE(2025,8,2),INT(P35/390)) -> 45985 | Z35: {=_xlfn.XLOOKUP(INT(X35),INT($AE$2:$AE$1000),$AG$2:$AG$1000,"")} -> 20.52 | AE35: =IF(ISNUMBER(AF35),DATE(YEAR(AF35),DAY(AF35),MONTH(AF35)),DATE(RIGHT(AF35,4),LEFT(AF35,2),MID(AF35,4,2))) -> 45917 | AF35: 09/17/2025 | AG35: 15.72
A36: 2 | B36: MS | C36: WFC | D36: 32010 | E36: 168.395 | F36: 85.51 | G36: 168.37816 | H36: 85.518551 | I36: 4.2045657 | J36: 0.92309383 | K36: -0.059384186 | L36: 0.10795157 | M36: SHORT | N36: 8 | O36: signal | P36: 32018 | Q36: 168.17 | R36: 85.62 | S36: -0.44407293 | T36: 0.025236114 | U36: 0.021390075 | V36: 0.0038461723 | W36: 0.017543903 | X36: =WORKDAY(DATE(2025,8,2),INT(D36/390)) -> 45986 | Y36: =WORKDAY(DATE(2025,8,2),INT(P36/390)) -> 45986 | Z36: {=_xlfn.XLOOKUP(INT(X36),INT($AE$2:$AE$1000),$AG$2:$AG$1000,"")} -> 18.56 | AE36: =IF(ISNUMBER(AF36),DATE(YEAR(AF36),DAY(AF36),MONTH(AF36)),DATE(RIGHT(AF36,4),LEFT(AF36,2),MID(AF36,4,2))) -> 45918 | AF36: 09/18/2025 | AG36: 15.7
A37: 2 | B37: MS | C37: WFC | D37: 32218 | E37: 168.52 | F37: 85.66 | G37: 168.53685 | H37: 85.651434 | I37: -4.2728175 | J37: 0.92309383 | K37: 0.059340138 | L37: -0.10776253 | M37: LONG | N37: 26 | O37: signal | P37: 32244 | Q37: 169.74 | R37: 86.39 | S37: -0.37128894 | T37: -0.006271679 | U37: -0.010132973 | V37: 0.003846203 | W37: -0.013979176 | X37: =WORKDAY(DATE(2025,8,2),INT(D37/390)) -> 45986 | Y37: =WORKDAY(DATE(2025,8,2),INT(P37/390)) -> 45986 | Z37: {=_xlfn.XLOOKUP(INT(X37),INT($AE$2:$AE$1000),$AG$2:$AG$1000,"")} -> 18.56 | AE37: =IF(ISNUMBER(AF37),DATE(YEAR(AF37),DAY(AF37),MONTH(AF37)),DATE(RIGHT(AF37,4),LEFT(AF37,2),MID(AF37,4,2))) -> 45919 | AF37: 09/19/2025 | AG37: 15.45
A38: 2 | B38: MS | C38: WFC | D38: 33778 | E38: 174.92 | F38: 89.97 | G38: 174.90251 | H38: 89.978997 | I38: 3.639135 | J38: 0.92309383 | K38: -0.057168992 | L38: 0.10260018 | M38: SHORT | N38: 8 | O38: signal | P38: 33786 | Q38: 174.87 | R38: 90.22 | S38: 0.2567332 | T38: 0.028508495 | U38: 0.024660028 | V38: 0.0038461723 | W38: 0.020813856 | X38: =WORKDAY(DATE(2025,8,2),INT(D38/390)) -> 45992 | Y38: =WORKDAY(DATE(2025,8,2),INT(P38/390)) -> 45992 | Z38: {=_xlfn.XLOOKUP(INT(X38),INT($AE$2:$AE$1000),$AG$2:$AG$1000,"")} -> 17.24 | AE38: =IF(ISNUMBER(AF38),DATE(YEAR(AF38),DAY(AF38),MONTH(AF38)),DATE(RIGHT(AF38,4),LEFT(AF38,2),MID(AF38,4,2))) -> 45922 | AF38: 09/22/2025 | AG38: 16.1
A39: 2 | B39: MS | C39: WFC | D39: 34137 | E39: 176.815 | F39: 90.16 | G39: 176.79732 | H39: 90.169016 | I39: 3.7864965 | J39: 0.92309383 | K39: -0.056556288 | L39: 0.10238397 | M39: SHORT | N39: 21 | O39: signal | P39: 34158 | Q39: 176.23 | R39: 89.77 | S39: 0.31570697 | T39: -0.0068443183 | U39: -0.010683204 | V39: 0.0038461723 | W39: -0.014529377 | X39: =WORKDAY(DATE(2025,8,2),INT(D39/390)) -> 45993 | Y39: =WORKDAY(DATE(2025,8,2),INT(P39/390)) -> 45993 | Z39: {=_xlfn.XLOOKUP(INT(X39),INT($AE$2:$AE$1000),$AG$2:$AG$1000,"")} -> 16.59 | AE39: =IF(ISNUMBER(AF39),DATE(YEAR(AF39),DAY(AF39),MONTH(AF39)),DATE(RIGHT(AF39,4),LEFT(AF39,2),MID(AF39,4,2))) -> 45923 | AF39: 09/23/2025 | AG39: 16.64
A40: 2 | B40: MS | C40: WFC | D40: 34169 | E40: 176.88 | F40: 89.375 | G40: 176.86231 | H40: 89.383938 | I40: 4.0761167 | J40: 0.92309383 | K40: -0.056535504 | L40: 0.10328323 | M40: SHORT | N40: 9 | O40: signal | P40: 34178 | Q40: 177.68 | R40: 90.28 | S40: 0.25507736 | T40: 0.048242916 | U40: 0.044382859 | V40: 0.0038461723 | W40: 0.040536686 | X40: =WORKDAY(DATE(2025,8,2),INT(D40/390)) -> 45993 | Y40: =WORKDAY(DATE(2025,8,2),INT(P40/390)) -> 45993 | Z40: {=_xlfn.XLOOKUP(INT(X40),INT($AE$2:$AE$1000),$AG$2:$AG$1000,"")} -> 16.59 | AE40: =IF(ISNUMBER(AF40),DATE(YEAR(AF40),DAY(AF40),MONTH(AF40)),DATE(RIGHT(AF40,4),LEFT(AF40,2),MID(AF40,4,2))) -> 45924 | AF40: 09/24/2025 | AG40: 16.18
...

Sheet Analysis
L1: Exit timestamp | M1: Cumulative Gross PnL | N1: Cumulative Slipped PnL | O1: Cumulative Net PnL | Q1: min holding minutes | R1: max holding minutes | S1: Mean Net PnL | T1: Number of trades
B2: Rough Analysis of the baseline strategy | J2: Figures | L2: =Trades!P2 -> 24214 | M2: =Trades!T2 -> 0.024154984 | N2: =Trades!U2 -> 0.020822539 | O2: =Trades!W2 -> 0.017487745 | Q2: 0 | R2: 3 | S2: =AVERAGEIFS(Trades!W:W,Trades!N:N,">="&Q2,Trades!N:N,"<="&R2) -> 0.03153191 | T2: =COUNTIFS(Trades!N:N,">="&Q2,Trades!N:N,"<="&R2) -> 9
L3: =Trades!P3 -> 24606 | M3: =M2+Trades!T3 -> 0.067822224 | N3: =N2+Trades!U3 -> 0.061157159 | O3: =O2+Trades!W3 -> 0.054487572 | Q3: 4 | R3: 7 | S3: =AVERAGEIFS(Trades!W:W,Trades!N:N,">="&Q3,Trades!N:N,"<="&R3) -> 0.02589914 | T3: =COUNTIFS(Trades!N:N,">="&Q3,Trades!N:N,"<="&R3) -> 21
B4: Column1 | C4: Gross | D4: Slipped | E4: Net (Transaction costs) | L4: =Trades!P4 -> 24848 | M4: =M3+Trades!T4 -> 0.072054022 | N4: =N3+Trades!U4 -> 0.062055967 | O4: =O3+Trades!W4 -> 0.052051586 | Q4: 8 | R4: 11 | S4: =AVERAGEIFS(Trades!W:W,Trades!N:N,">="&Q4,Trades!N:N,"<="&R4) -> 0.023782929 | T4: =COUNTIFS(Trades!N:N,">="&Q4,Trades!N:N,"<="&R4) -> 19
B5: Overall PnL | C5: =SUM(Trades!T2:T9652) -> 1.3885918 | D5: =SUM(Trades!U2:U9652) -> 0.882144 | E5: =SUM(Trades!W2:W9652) -> 0.3758623 | L5: =Trades!P5 -> 24996 | M5: =M4+Trades!T5 -> 0.10989766 | N5: =N4+Trades!U5 -> 0.096564379 | O5: =O4+Trades!W5 -> 0.083225071 | Q5: 12 | R5: 15 | S5: =AVERAGEIFS(Trades!W:W,Trades!N:N,">="&Q5,Trades!N:N,"<="&R5) -> 0.014300093 | T5: =COUNTIFS(Trades!N:N,">="&Q5,Trades!N:N,"<="&R5) -> 19
B6: Mean PnL | C6: =AVERAGE(Trades!T:T) -> 0.010135706 | D6: =AVERAGE(Trades!U:U) -> 0.0064390073 | E6: =AVERAGE(Trades!W:W) -> 0.0027435204 | L6: =Trades!P6 -> 25392 | M6: =M5+Trades!T6 -> 0.14071719 | N6: =N5+Trades!U6 -> 0.12404061 | O6: =O5+Trades!W6 -> 0.10736638 | Q6: 16 | R6: 19 | S6: =AVERAGEIFS(Trades!W:W,Trades!N:N,">="&Q6,Trades!N:N,"<="&R6) -> -0.0045318448 | T6: =COUNTIFS(Trades!N:N,">="&Q6,Trades!N:N,"<="&R6) -> 16
B7: Median PnL | C7: =MEDIAN(Trades!T:T) -> 0.011783975 | D7: =MEDIAN(Trades!U:U) -> 0.0084181991 | E7: =MEDIAN(Trades!W:W) -> 0.0047335944 | L7: =Trades!P7 -> 25731 | M7: =M6+Trades!T7 -> 0.12499991 | N7: =N6+Trades!U7 -> 0.10498528 | O7: =O6+Trades!W7 -> 0.084976254 | Q7: 20 | R7: 23 | S7: =AVERAGEIFS(Trades!W:W,Trades!N:N,">="&Q7,Trades!N:N,"<="&R7) -> -0.012857903 | T7: =COUNTIFS(Trades!N:N,">="&Q7,Trades!N:N,"<="&R7) -> 24
B8: Max drawdown | C8: =MIN(Trades!T:T) -> -0.087068107 | D8: =MIN(Trades!U:U) -> -0.091191822 | E8: =MIN(Trades!W:W) -> -0.095289891 | L8: =Trades!P8 -> 25758 | M8: =M7+Trades!T8 -> 0.13581127 | N8: =N7+Trades!U8 -> 0.11246473 | O8: =O7+Trades!W8 -> 0.089120912 | Q8: 24 | R8: 27 | S8: =AVERAGEIFS(Trades!W:W,Trades!N:N,">="&Q8,Trades!N:N,"<="&R8) -> -0.024624317 | T8: =COUNTIFS(Trades!N:N,">="&Q8,Trades!N:N,"<="&R8) -> 15
B9: Biggest Winner | C9: =MAX(Trades!T:T) -> 0.09558224 | D9: =MAX(Trades!U:U) -> 0.091738669 | E9: =MAX(Trades!W:W) -> 0.087869742 | L9: =Trades!P9 -> 26942 | M9: =M8+Trades!T9 -> 0.16614087 | N9: =N8+Trades!U9 -> 0.13944671 | O9: =O8+Trades!W9 -> 0.11276796 | Q9: 28 | R9: 34 | S9: =AVERAGEIFS(Trades!W:W,Trades!N:N,">="&Q9,Trades!N:N,"<="&R9) -> -0.016174126 | T9: =COUNTIFS(Trades!N:N,">="&Q9,Trades!N:N,"<="&R9) -> 8
B10: Win rate | C10: =COUNTIF(Trades!T:T,">0")/(COUNTIF(Trades!T:T,">0")+COUNTIF(Trades!T:T,"<0")) -> 0.69343066 | D10: =COUNTIF(Trades!U:U,">0")/(COUNTIF(Trades!U:U,">0")+COUNTIF(Trades!U:U,"<0")) -> 0.6350365 | E10: =COUNTIF(Trades!W:W,">0")/(COUNTIF(Trades!W:W,">0")+COUNTIF(Trades!W:W,"<0")) -> 0.58394161 | L10: =Trades!P10 -> 27332 | M10: =M9+Trades!T10 -> 0.19014346 | N10: =N9+Trades!U10 -> 0.1601233 | O10: =O9+Trades!W10 -> 0.13010976 | Q10: 35 | R10: 40 | S10: =AVERAGEIFS(Trades!W:W,Trades!N:N,">="&Q10,Trades!N:N,"<="&R10) -> -0.045173001 | T10: =COUNTIFS(Trades!N:N,">="&Q10,Trades!N:N,"<="&R10) -> 4
B11: Profit Factor | C11: =SUMIF(Trades!T:T,">0",Trades!T:T)/ABS(SUMIF(Trades!T:T,"<0",Trades!T:T)) -> 2.2631106 | D11: =SUMIF(Trades!U:U,">0",Trades!U:U)/ABS(SUMIF(Trades!U:U,"<0",Trades!U:U)) -> 1.694162 | E11: =SUMIF(Trades!W:W,">0",Trades!W:W)/ABS(SUMIF(Trades!W:W,"<0",Trades!W:W)) -> 1.2550328 | L11: =Trades!P11 -> 27725 | M11: =M9+Trades!T11 -> 0.1839358 | N11: =N9+Trades!U11 -> 0.15388456 | O11: =O9+Trades!W11 -> 0.12387088
L12: =Trades!P12 -> 27924 | M12: =M11+Trades!T12 -> 0.19413267 | N12: =N11+Trades!U12 -> 0.16077521 | O12: =O11+Trades!W12 -> 0.1274538 | Q12: 41 | R12: 47 | S12: =AVERAGEIFS(Trades!W:W,Trades!N:N,">="&Q12,Trades!N:N,"<="&R12) -> -0.032076202 | T12: =COUNTIFS(Trades!N:N,">="&Q12,Trades!N:N,"<="&R12) -> 1
B13: Column1 | C13: Column2 | L13: =Trades!P20 -> 32055 | M13: =M12+Trades!T20 -> 0.1183425 | N13: =N12+Trades!U20 -> 0.081493219 | O13: =O12+Trades!W20 -> 0.044694694
B14: Number of Trades | C14: =COUNTA(Trades!A:A)-1 -> 137 | L14: =Trades!P13 -> 28504 | M14: =M13+Trades!T13 -> 0.15478022 | N14: =N13+Trades!U13 -> 0.11462828 | O14: =O13+Trades!W13 -> 0.07452202
B15: Mean holding time | C15: =AVERAGE(Trades!N:N) -> 16.321168 | L15: =Trades!P21 -> 32218 | M15: =M14+Trades!T21 -> 0.17693189 | N15: =N14+Trades!U21 -> 0.13330444 | O15: =O14+Trades!W21 -> 0.089720965
B16: Median holding time | C16: =MEDIAN(Trades!N:N) -> 16 | L16: =Trades!P22 -> 32631 | M16: =M15+Trades!T22 -> 0.18805818 | N16: =N15+Trades!U22 -> 0.140959 | O16: =O15+Trades!W22 -> 0.093898308
B17: Max holding time | C17: =MAX(Trades!N:N) -> 48 | L17: =Trades!P23 -> 33015 | M17: =M16+Trades!T23 -> 0.19034235 | N17: =N16+Trades!U23 -> 0.13975733 | O17: =O16+Trades!W23 -> 0.089219528
L18: =Trades!P14 -> 28639 | M18: =M17+Trades!T14 -> 0.22286266 | N18: =N17+Trades!U14 -> 0.1689687 | O18: =O17+Trades!W14 -> 0.11512302
B19: Column1 | C19: Positive | D19: Negative | L19: =Trades!P15 -> 28735 | M19: =M18+Trades!T15 -> 0.21900859 | N19: =N18+Trades!U15 -> 0.161808 | O19: =O18+Trades!W15 -> 0.10465445
B20: Mean entry z score | C20: =AVERAGEIF(Trades!I:I,">0",Trades!I:I) -> 4.1060707 | D20: =AVERAGEIF(Trades!I:I,"<0",Trades!I:I) -> -4.0699518 | L20: =Trades!P24 -> 34564 | M20: =M19+Trades!T24 -> 0.25100157 | N20: =N19+Trades!U24 -> 0.19032711 | O20: =O19+Trades!W24 -> 0.12969644
B21: Median entry z score | C21: {=MEDIAN(_xlfn._xlws.FILTER(Trades!I:I,Trades!I:I>0))} -> 3.9061094 | D21: {=MEDIAN(_xlfn._xlws.FILTER(Trades!I:I,Trades!I:I<0))} -> -3.8781857 | L21: =Trades!P25 -> 35310 | M21: =M20+Trades!T25 -> 0.31153065 | N21: =N20+Trades!U25 -> 0.24737191 | O21: =O20+Trades!W25 -> 0.18326402
B22: max entry z score | C22: =_xlfn.MAXIFS(Trades!I:I,Trades!I:I,">0") -> 5.2946422 | D22: =_xlfn.MINIFS(Trades!I:I,Trades!I:I,"<0") -> -5.29465 | L22: =Trades!P16 -> 29691 | M22: =M21+Trades!T16 -> 0.2855726 | N22: =N21+Trades!U16 -> 0.21809841 | O22: =O21+Trades!W16 -> 0.15068278
B23: Mean exit z score | C23: =AVERAGEIF(Trades!S:S,">0",Trades!S:S) -> 0.28568269 | D23: =AVERAGEIF(Trades!S:S,"<0",Trades!S:S) -> -0.31373434 | L23: =Trades!P26 -> 35725 | M23: =M22+Trades!T26 -> 0.25803359 | N23: =N22+Trades!U26 -> 0.18721437 | O23: =O22+Trades!W26 -> 0.11644792
B24: Median exit z score | C24: {=MEDIAN(_xlfn._xlws.FILTER(Trades!S:S,Trades!S:S>0))} -> 0.28678401 | D24: {=MEDIAN(_xlfn._xlws.FILTER(Trades!S:S,Trades!S:S<0))} -> -0.32318646 | L24: =Trades!P27 -> 36516 | M24: =M23+Trades!T27 -> 0.33351918 | N24: =N23+Trades!U27 -> 0.2593426 | O24: =O23+Trades!W27 -> 0.18522519
B25: max exit z score | C25: =_xlfn.MAXIFS(Trades!S:S,Trades!S:S,">0") -> 0.49471769 | D25: =_xlfn.MINIFS(Trades!S:S,Trades!S:S,"<0") -> -0.49528239 | L25: =Trades!P17 -> 30065 | M25: =M24+Trades!T17 -> 0.36568895 | N25: =N24+Trades!U17 -> 0.28819841 | O25: =O24+Trades!W17 -> 0.21077312
G26: 1 | H26: Edge is there, but wiped out by costs | L26: =Trades!P18 -> 31227 | M26: =M25+Trades!T18 -> 0.38735212 | N26: =N25+Trades!U18 -> 0.30654688 | O26: =O25+Trades!W18 -> 0.22581371
B27: Column1 | C27: Long | D27: Short | E27: Signal | F27: Forced | L27: =Trades!P19 -> 31824 | M27: =M26+Trades!T19 -> 0.38434504 | N27: =N26+Trades!U19 -> 0.30006233 | O27: =O26+Trades!W19 -> 0.21585195
B28: PnL (gross) | C28: =SUMIF(Trades!M:M,"LONG",Trades!T:T) -> 0.83313468 | D28: =SUMIF(Trades!M:M,"SHORT",Trades!T:T) -> 0.5554571 | E28: =SUMIF(Trades!O:O,"Signal",Trades!T:T) -> 1.3885918 | F28: =SUMIF(Trades!O:O,"Forced",Trades!T:T) -> 0 | L28: =Trades!P28 -> 37315 | M28: =M27+Trades!T28 -> 0.43368133 | N28: =N27+Trades!U28 -> 0.34603416 | O28: =O27+Trades!W28 -> 0.25847282
B29: Number | C29: =COUNTIF(Trades!M:M,"LONG") -> 60 | D29: =COUNTIF(Trades!M:M,"SHORT") -> 77 | E29: =COUNTIF(Trades!O:O,"Signal") -> 137 | F29: =COUNTIF(Trades!O:O,"Forced") -> 0 | L29: =Trades!P35 -> 39624 | M29: =M28+Trades!T35 -> 0.43411723 | N29: =N28+Trades!U35 -> 0.34316461 | O29: =O28+Trades!W35 -> 0.25229668
L30: =Trades!P44 -> 44024 | M30: =M29+Trades!T44 -> 0.415339 | N30: =N29+Trades!U44 -> 0.32116928 | O30: =O29+Trades!W44 -> 0.22708743
B31: min Holding time | C31: Max Holding time | D31: Win rate | L31: =Trades!P52 -> 47424 | M31: =M30+Trades!T52 -> 0.42008468 | N31: =N30+Trades!U52 -> 0.32181636 | O31: =O30+Trades!W52 -> 0.22363644
B32: 0 | C32: 3 | D32: =COUNTIFS(Trades!N:N,">="&B32,Trades!N:N,"<="&C32,Trades!T:T,">0")/(COUNTIFS(Trades!N:N,">="&B32,Trades!N:N,"<="&C32,Trades!T:T,">0")+COUNTIFS(Trades!N:N,">="&B32,Trades!N:N,"<="&C32,Trades!T:T,"<0")) -> 1 | L32: =Trades!P36 -> 39854 | M32: =M31+Trades!T36 -> 0.43647186 | N32: =N31+Trades!U36 -> 0.33490512 | O32: =O31+Trades!W36 -> 0.2334186
B33: 4 | C33: 7 | D33: =COUNTIFS(Trades!N:N,">="&B33,Trades!N:N,"<="&C33,Trades!T:T,">0")/(COUNTIFS(Trades!N:N,">="&B33,Trades!N:N,"<="&C33,Trades!T:T,">0")+COUNTIFS(Trades!N:N,">="&B33,Trades!N:N,"<="&C33,Trades!T:T,"<0")) -> 1 | L33: =Trades!P45 -> 44544 | M33: =M32+Trades!T45 -> 0.47445826 | N33: =N32+Trades!U45 -> 0.36968772 | O33: =O32+Trades!W45 -> 0.26498728
B34: 8 | C34: 11 | D34: =COUNTIFS(Trades!N:N,">="&B34,Trades!N:N,"<="&C34,Trades!T:T,">0")/(COUNTIFS(Trades!N:N,">="&B34,Trades!N:N,"<="&C34,Trades!T:T,">0")+COUNTIFS(Trades!N:N,">="&B34,Trades!N:N,"<="&C34,Trades!T:T,"<0")) -> 1 | L34: =Trades!P29 -> 37701 | M34: =M33+Trades!T29 -> 0.46909498 | N34: =N33+Trades!U29 -> 0.36096748 | O34: =O33+Trades!W29 -> 0.25291621
B35: 12 | C35: 15 | D35: =COUNTIFS(Trades!N:N,">="&B35,Trades!N:N,"<="&C35,Trades!T:T,">0")/(COUNTIFS(Trades!N:N,">="&B35,Trades!N:N,"<="&C35,Trades!T:T,">0")+COUNTIFS(Trades!N:N,">="&B35,Trades!N:N,"<="&C35,Trades!T:T,"<0")) -> 0.94736842 | L35: =Trades!P30 -> 38206 | M35: =M34+Trades!T30 -> 0.46858465 | N35: =N34+Trades!U30 -> 0.3571047 | O35: =O34+Trades!W30 -> 0.2457026
B36: 16 | C36: 1000000 | D36: =COUNTIFS(Trades!N:N,">="&B36,Trades!N:N,"<="&C36,Trades!T:T,">0")/(COUNTIFS(Trades!N:N,">="&B36,Trades!N:N,"<="&C36,Trades!T:T,">0")+COUNTIFS(Trades!N:N,">="&B36,Trades!N:N,"<="&C36,Trades!T:T,"<0")) -> 0.4057971 | L36: =Trades!P37 -> 41036 | M36: =M35+Trades!T37 -> 0.39856519 | N36: =N35+Trades!U37 -> 0.28375323 | O36: =O35+Trades!W37 -> 0.16904454
L37: =Trades!P53 -> 47667 | M37: =M36+Trades!T53 -> 0.38252126 | N37: =N36+Trades!U53 -> 0.26358278 | O37: =O36+Trades!W53 -> 0.14477603
L38: =Trades!P54 -> 47973 | M38: =M37+Trades!T54 -> 0.40939771 | N38: =N37+Trades!U54 -> 0.28635789 | O38: =O37+Trades!W54 -> 0.16345309
B39: Conclusion: | L39: =Trades!P31 -> 38333 | M39: =M38+Trades!T31 -> 0.40708774 | N39: =N38+Trades!U31 -> 0.28069769 | O39: =O38+Trades!W31 -> 0.15444193
B40: does the multiple pairs strategy improve diversification and risk adjusted returns instead of just gross exposure? | L40: =Trades!P32 -> 38674 | M40: =M39+Trades!T32 -> 0.41547439 | N40: =N39+Trades!U32 -> 0.2857316 | O40: =O39+Trades!W32 -> 0.15612489
...

Sheet comparison with single pair
B2: Metric | C2: Value | J2: Daily PnL table
B3: Net P&L | C3: =SUM(Trades!W2:W9652) -> 0.3758623
B4: Number of trades | C4: =COUNTA(Trades!A:A)-1 -> 137 | J4: {=_xlfn.LET( _xlpm.dates,_xlfn.SEQUENCE(DATE(2026,8,2)-DATE(2025,8,2)+1,,DATE(2025,8,2)), _xlfn._xlws.FILTER(_xlpm.dates,WEEKDAY(_xlpm.dates,2)<=5) )} -> 45873 | K4: {=SUMIFS('trades edited'!$W$2:$W$100000,'trades edited'!$Y$2:$Y$100000,_xlfn.ANCHORARRAY(J4))} -> 0
B5: P&L/trade | C5: =AVERAGE(Trades!W:W) -> 0.0027435204 | J5: 45874 | K5: 0
B6: Daily P&L volatility | C6: =_xlfn.STDEV.S(_xlfn.ANCHORARRAY(K4)) -> 0.1838488 | J6: 45875 | K6: 0
B7: Sharpe-like measure | C7: =AVERAGE(_xlfn.ANCHORARRAY(K4))/_xlfn.STDEV.S(_xlfn.ANCHORARRAY(K4))*SQRT(252) -> 2.5235284 | J7: 45876 | K7: 0
B8: Max drawdown | C8: =MIN(Trades!W:W) -> -0.095289891 | J8: 45877 | K8: 0
B9: Max drawdown / total P&L | C9: =C8/C3 -> -0.25352341 | J9: 45880 | K9: 0
B10: Worst day | J10: 45881 | K10: 0
B11: Max concurrent positions | J11: 45882 | K11: 0
B12: Max gross exposure | J12: 45883 | K12: 0
J13: 45884 | K13: 0
J14: 45887 | K14: 0
J15: 45888 | K15: 0
B16: it seems like this strat might actually be WORSE for risk *potentially* than the single pair version. The main question now is how much capital we need to keep in reserves to avoid margin calling and liquidation. portfolio total P&L = cumulative realised P&L up to minute + total unrealised P&L at minute | J16: 45889 | K16: 0
J17: 45890 | K17: 0
J18: 45891 | K18: 0
J19: 45894 | K19: 0
J20: 45895 | K20: 0
J21: 45896 | K21: 0
J22: 45897 | K22: 0
J23: 45898 | K23: 0
J24: 45901 | K24: 0
J25: 45902 | K25: 0
J26: 45903 | K26: 0
J27: 45904 | K27: 0
J28: 45905 | K28: 0
... J263: 46234 | K263: 0
