Workbook

Sheet Trades
A1: window_id | B1: stock1 | C1: stock2 | D1: entry_timestamp | E1: entry_price_1 | F1: entry_price_2 | G1: entry_price_1_slipped | H1: entry_price_2_slipped | I1: entry_zscore | J1: hedge_ratio_entry | K1: position_size_1 | L1: position_size_2 | M1: direction | N1: holding_minutes | O1: exit_reason | P1: exit_timestamp | Q1: exit_price_1 | R1: exit_price_2 | S1: exit_zscore | T1: gross_pnl | U1: gross_pnl_slipped | V1: transaction_costs | W1: net_pnl
A2: 0 | B2: JPM | C2: USB | D2: 24032 | E2: 123.99 | F2: 42.295 | G2: 124.0024 | H2: 42.290771 | I2: -1.829777 | J2: 0.44350025 | K2: 0.080651665 | L2: -0.10485879 | M2: LONG | N2: 13 | O2: signal | P2: 24045 | Q2: 123.985 | R2: 42.325 | S2: -0.39352704 | T2: -0.003549022 | U2: -0.0064362968 | V2: 0.0028871118 | W2: -0.0093234086
A3: 0 | B3: JPM | C3: USB | D3: 24072 | E3: 123.785 | F3: 42.3 | G3: 123.79738 | H3: 42.29577 | I3: -1.5626489 | J3: 0.44350025 | K3: 0.080785232 | L3: -0.1048464 | M3: LONG | N3: 10 | O3: signal | P3: 24082 | Q3: 124 | R3: 42.45 | S3: -0.32782764 | T3: 0.0016418656 | U3: -0.0012484445 | V3: 0.0028871118 | W3: -0.0041355563
A4: 0 | B4: JPM | C4: USB | D4: 24087 | E4: 123.84 | F4: 42.445 | G4: 123.85238 | H4: 42.440755 | I4: -1.8136979 | J4: 0.44350025 | K4: 0.080749354 | L4: -0.10448822 | M4: LONG | N4: 6 | O4: signal | P4: 24093 | Q4: 124.02 | R4: 42.5 | S4: 0.058790867 | T4: 0.0087880316 | U4: 0.0058990029 | V4: 0.0028871118 | W4: 0.0030118911
A5: 0 | B5: JPM | C5: USB | D5: 24105 | E5: 124.14 | F5: 42.5 | G5: 124.12759 | H5: 42.50425 | I5: 2.3071722 | J5: 0.44350025 | K5: -0.080554213 | L5: 0.104353 | M5: SHORT | N5: 11 | O5: signal | P5: 24116 | Q5: 124.1 | R5: 42.53 | S5: 0.28307231 | T5: 0.0063527585 | U5: 0.0034657672 | V5: 0.0028868892 | W5: 0.00057887799
A6: 0 | B6: JPM | C6: USB | D6: 24131 | E6: 123.9 | F6: 42.45 | G6: 123.91239 | H6: 42.445755 | I6: -2.1886252 | J6: 0.44350025 | K6: 0.08071025 | L6: -0.10447591 | M6: LONG | N6: 2 | O6: signal | P6: 24133 | Q6: 123.97 | R6: 42.435 | S6: -0.26054265 | T6: 0.0072168562 | U6: 0.0043294475 | V6: 0.0028871118 | W6: 0.0014423356
A7: 0 | B7: JPM | C7: USB | D7: 24135 | E7: 123.91 | F7: 42.44 | G7: 123.92239 | H7: 42.435756 | I7: -1.5368203 | J7: 0.44350025 | K7: 0.080703737 | L7: -0.10450053 | M7: LONG | N7: 11 | O7: signal | P7: 24146 | Q7: 123.97 | R7: 42.425 | S7: 0.47338936 | T7: 0.0064097322 | U7: 0.0035224042 | V7: 0.0028871118 | W7: 0.00063529237
A8: 0 | B8: JPM | C8: USB | D8: 24157 | E8: 123.75 | F8: 42.355 | G8: 123.76238 | H8: 42.350764 | I8: -1.5773892 | J8: 0.44350025 | K8: 0.080808081 | L8: -0.10471025 | M8: LONG | N8: 20 | O8: signal | P8: 24177 | Q8: 123.69 | R8: 42.355 | S8: -0.21399894 | T8: -0.0048484848 | U8: -0.0077350005 | V8: 0.0028871118 | W8: -0.010622112
A9: 0 | B9: JPM | C9: USB | D9: 24183 | E9: 123.85 | F9: 42.365 | G9: 123.83761 | H9: 42.369237 | I9: 1.5049563 | J9: 0.44350025 | K9: -0.080742834 | L9: 0.10468553 | M9: SHORT | N9: 28 | O9: signal | P9: 24211 | Q9: 123.98 | R9: 42.39 | S9: 0.11754797 | T9: -0.0078794301 | U9: -0.010767742 | V9: 0.0028868892 | W9: -0.013654631
A10: 0 | B10: JPM | C10: USB | D10: 24221 | E10: 125.96 | F10: 42.885 | G10: 125.9474 | H10: 42.889288 | I10: 5.0954302 | J10: 0.44350025 | K10: -0.079390283 | L10: 0.10341617 | M10: SHORT | N10: 17 | O10: signal | P10: 24238 | Q10: 125.16 | R10: 42.48 | S10: 0.3822661 | T10: 0.021628676 | U10: 0.018752215 | V10: 0.0028868892 | W10: 0.015865326
A11: 0 | B11: JPM | C11: USB | D11: 24253 | E11: 125.38 | F11: 42.64 | G11: 125.39254 | H11: 42.635736 | I11: -1.5669398 | J11: 0.44350025 | K11: 0.079757537 | L11: -0.10401038 | M11: LONG | N11: 4 | O11: signal | P11: 24257 | Q11: 125.75 | R11: 42.75 | S11: 0.262983 | T11: 0.018069147 | U11: 0.015178051 | V11: 0.0028871118 | W11: 0.01229094
A12: 0 | B12: JPM | C12: USB | D12: 24261 | E12: 125.19 | F12: 42.63 | G12: 125.20252 | H12: 42.625737 | I12: -2.4807127 | J12: 0.44350025 | K12: 0.079878585 | L12: -0.10403478 | M12: LONG | N12: 3 | O12: signal | P12: 24264 | Q12: 125.63 | R12: 42.75 | S12: -0.070223915 | T12: 0.022662404 | U12: 0.01977064 | V12: 0.0028871118 | W12: 0.016883529
A13: 0 | B13: JPM | C13: USB | D13: 24268 | E13: 125.39 | F13: 42.75 | G13: 125.40254 | H13: 42.745725 | I13: -1.7779612 | J13: 0.44350025 | K13: 0.079751176 | L13: -0.10374275 | M13: LONG | N13: 4 | O13: signal | P13: 24272 | Q13: 125.7 | R13: 42.825 | S13: -0.026130971 | T13: 0.016942158 | U13: 0.014051908 | V13: 0.0028871118 | W13: 0.011164796
... A694: 3 | B694: PNC | C694: COF | D694: 39549 | E694: 151.82 | F694: 88.4 | G694: 151.80482 | H694: 88.40884 | I694: 1.7098916 | J694: 0.53007103 | K694: -0.065867475 | L694: 0.059962787 | M694: SHORT | N694: 14 | O694: signal | P694: 39563 | Q694: 152.01 | R694: 88.67 | S694: 0.4348704 | T694: 0.0036751322 | U694: 0.00061211968 | V694: 0.0030600481 | W694: -0.0024479284
A695: 3 | B695: PNC | C695: COF | D695: 39570 | E695: 152.055 | F695: 88.46 | G695: 152.03979 | H695: 88.468846 | I695: 1.9460864 | J695: 0.53007103 | K695: -0.065765677 | L695: 0.059922116 | M695: SHORT | N695: 30 | O695: forced | P695: 39600 | Q695: 152.57 | R695: 88.39 | T695: -0.038063872 | U695: -0.041126981 | V695: 0.0030600481 | W695: -0.044187029
A696: 4 | B696: WFC | C696: PNC | D696: 39601 | E696: 40.36 | F696: 152.675 | G696: 40.364036 | H696: 152.65973 | I696: -5.2946487 | J696: 1.3273183 | K696: 0.24777007 | L696: -0.0869375 | M696: LONG | N696: 23 | O696: signal | P696: 39624 | Q696: 40.47 | R696: 152.94 | S696: -0.49144633 | T696: 0.0042162702 | U696: -0.00044339562 | V696: 0.0046545711 | W696: -0.0050979667
A697: 4 | B697: WFC | C697: PNC | D697: 39630 | E697: 40.58 | F697: 153.54 | G697: 40.584058 | H697: 153.52465 | I697: -2.5002994 | J697: 1.3273183 | K697: 0.24642681 | L697: -0.086447719 | M697: LONG | N697: 40 | O697: signal | P697: 39670 | Q697: 40.71 | R697: 154.32 | S697: -0.42867277 | T697: -0.035393735 | U697: -0.040058318 | V697: 0.0046545711 | W697: -0.044712889
A698: 4 | B698: WFC | C698: PNC | D698: 39671 | E698: 40.85 | F698: 155.19 | G698: 40.854085 | H698: 155.17448 | I698: -2.6610347 | J698: 1.3273183 | K698: 0.24479804 | L698: -0.085528596 | M698: LONG | N698: 16 | O698: signal | P698: 39687 | Q698: 40.63 | R698: 154.83 | S698: -0.48597015 | T698: -0.023065275 | U698: -0.027711447 | V698: 0.0046545711 | W698: -0.032366018
A699: 4 | B699: WFC | C699: PNC | D699: 39733 | E699: 40.8 | F699: 155.815 | G699: 40.80408 | H699: 155.79942 | I699: -1.7417201 | J699: 1.3273183 | K699: 0.24509804 | L699: -0.085185526 | M699: LONG | N699: 14 | O699: signal | P699: 39747 | Q699: 40.79 | R699: 155.76 | S699: -0.35094534 | T699: 0.0022342235 | U699: -0.0024196994 | V699: 0.0046545711 | W699: -0.0070742705
A700: 4 | B700: WFC | C700: PNC | D700: 39757 | E700: 40.675 | F700: 155.65 | G700: 40.679068 | H700: 155.63443 | I700: -1.8549727 | J700: 1.3273183 | K700: 0.24585126 | L700: -0.085275829 | M700: LONG | N700: 6 | O700: signal | P700: 39763 | Q700: 40.655 | R700: 155.41 | S700: 0.31581444 | T700: 0.015549174 | U700: 0.010897075 | V700: 0.0046545711 | W700: 0.0062425044
A701: 4 | B701: WFC | C701: PNC | D701: 39772 | E701: 40.73 | F701: 155.49 | G701: 40.725927 | H701: 155.50555 | I701: 1.6180546 | J701: 1.3273183 | K701: -0.24551927 | L701: 0.085363578 | M701: SHORT | N701: 26 | O701: signal | P701: 39798 | Q701: 40.805 | R701: 155.295 | S701: 0.46433641 | T701: -0.035059843 | U701: -0.039714657 | V701: 0.004654702 | W701: -0.044369359
A702: 4 | B702: WFC | C702: PNC | D702: 39817 | E702: 40.9 | F702: 155.18 | G702: 40.89591 | H702: 155.19552 | I702: 2.4589266 | J702: 1.3273183 | K702: -0.24449878 | L702: 0.085534107 | M702: SHORT | N702: 26 | O702: signal | P702: 39843 | Q702: 40.965 | R702: 155.43 | S702: -0.10221628 | T702: 0.0054911063 | U702: 0.00083274211 | V702: 0.004654702 | W702: -0.0038219599
A703: 4 | B703: WFC | C703: PNC | D703: 39845 | E703: 40.97 | F703: 155.26 | G703: 40.965903 | H703: 155.27553 | I703: 2.3058079 | J703: 1.3273183 | K703: -0.24408103 | L703: 0.085490034 | M703: SHORT | N703: 5 | O703: signal | P703: 39850 | Q703: 40.94 | R703: 155.33 | S703: -0.23796388 | T703: 0.013306733 | U703: 0.0086522307 | V703: 0.004654702 | W703: 0.0039975287
A704: 4 | B704: WFC | C704: PNC | D704: 39860 | E704: 40.97 | F704: 155.255 | G704: 40.965903 | H704: 155.27053 | I704: 1.6346286 | J704: 1.3273183 | K704: -0.24408103 | L704: 0.085492788 | M704: SHORT | N704: 2 | O704: signal | P704: 39862 | Q704: 40.94 | R704: 155.255 | S704: 0.42726095 | T704: 0.007322431 | U704: 0.0026685267 | V704: 0.004654702 | W704: -0.0019861753
A705: 4 | B705: WFC | C705: PNC | D705: 39866 | E705: 40.92 | F705: 154.895 | G705: 40.915908 | H705: 154.91049 | I705: 3.512169 | J705: 1.3273183 | K705: -0.24437928 | L705: 0.085691486 | M705: SHORT | N705: 24 | O705: signal | P705: 39890 | Q705: 40.95 | R705: 154.99 | S705: 0.25517233 | T705: 0.00080931289 | U705: -0.0038468709 | V705: 0.004654702 | W705: -0.0085015729
A706: 4 | B706: WFC | C706: PNC | D706: 39904 | E706: 40.92 | F706: 154.97 | G706: 40.924092 | H706: 154.9545 | I706: -2.0330445 | J706: 1.3273183 | K706: 0.24437928 | L706: -0.085650015 | M706: LONG | N706: 2 | O706: signal | P706: 39906 | Q706: 40.91 | R706: 154.86 | S706: 0.063197208 | T706: 0.0069777088 | U706: 0.0023242588 | V706: 0.0046545711 | W706: -0.0023303123
A707: 4 | B707: WFC | C707: PNC | D707: 39910 | E707: 40.92 | F707: 154.96 | G707: 40.924092 | H707: 154.9445 | I707: -1.6607745 | J707: 1.3273183 | K707: 0.24437928 | L707: -0.085655542 | M707: LONG | N707: 7 | O707: signal | P707: 39917 | Q707: 40.92 | R707: 154.93 | S707: -0.21801585 | T707: 0.0025696663 | U707: -0.0020847133 | V707: 0.0046545711 | W707: -0.0067392844
... A1213: 6 | B1213: JPM | C1213: C | D1213: 51240 | E1213: 143.12 | F1213: 51.185 | G1213: 143.13431 | H1213: 51.179882 | I1213: -2.0187201 | J1213: 0.45865237 | K1213: 0.069871437 | L1213: -0.089606793 | M1213: LONG | N1213: 25 | O1213: signal | P1213: 51265 | Q1213: 142.6 | R1213: 50.92 | S1213: -0.45329725 | T1213: -0.012587347 | U1213: -0.015498644 | V1213: 0.002917413 | W1213: -0.018416057
A1214: 6 | B1214: JPM | C1214: C | D1214: 51290 | E1214: 142.985 | F1214: 51.21 | G1214: 142.9707 | H1214: 51.215121 | I1214: 2.0193441 | J1214: 0.45865237 | K1214: -0.069937406 | L1214: 0.089563048 | M1214: SHORT | N1214: 10 | O1214: forced | P1214: 51300 | Q1214: 143.1 | R1214: 51.17 | T1214: -0.011625324 | U1214: -0.014543074 | V1214: 0.0029171965 | W1214: -0.017460271
A1215: 9 | B1215: BAC | C1215: USB | D1215: 59101 | E1215: 32.495 | F1215: 45.325 | G1215: 32.49825 | H1215: 45.320468 | I1215: -5.2946393 | J1215: 0.71217967 | K1215: 0.30773965 | L1215: -0.15712734 | M1215: LONG | N1215: 23 | O1215: signal | P1215: 59124 | Q1215: 32.535 | R1215: 45.31 | S1215: -0.49156319 | T1215: 0.014666496 | U1215: 0.011241142 | V1215: 0.0034244169 | W1215: 0.0078167247
A1216: 9 | B1216: BAC | C1216: USB | D1216: 59135 | E1216: 32.555 | F1216: 45.295 | G1216: 32.551745 | H1216: 45.299529 | I1216: 2.1493212 | J1216: 0.71217967 | K1216: -0.30717248 | L1216: 0.15723141 | M1216: SHORT | N1216: 3 | O1216: signal | P1216: 59138 | Q1216: 32.54 | R1216: 45.295 | S1216: 0.43093402 | T1216: 0.0046075872 | U1216: 0.0011836886 | V1216: 0.0034243018 | W1216: -0.0022406132
A1217: 9 | B1217: BAC | C1217: USB | D1217: 59139 | E1217: 32.52 | F1217: 45.295 | G1217: 32.523252 | H1217: 45.29047 | I1217: -1.5552672 | J1217: 0.71217967 | K1217: 0.30750308 | L1217: -0.15723141 | M1217: LONG | N1217: 2 | O1217: signal | P1217: 59141 | Q1217: 32.53 | R1217: 45.285 | S1217: -0.10547729 | T1217: 0.0046473448 | U1217: 0.0012228352 | V1217: 0.0034244169 | W1217: -0.0022015817
A1218: 9 | B1218: BAC | C1218: USB | D1218: 59147 | E1218: 32.52 | F1218: 45.305 | G1218: 32.523252 | H1218: 45.30047 | I1218: -1.7251409 | J1218: 0.71217967 | K1218: 0.30750308 | L1218: -0.1571967 | M1218: LONG | N1218: 33 | O1218: signal | P1218: 59180 | Q1218: 32.48 | R1218: 45.315 | S1218: -0.043245876 | T1218: -0.01387209 | U1218: -0.017295377 | V1218: 0.0034244169 | W1218: -0.020719793
A1219: 9 | B1219: BAC | C1219: USB | D1219: 59181 | E1219: 32.46 | F1219: 45.35 | G1219: 32.463246 | H1219: 45.345465 | I1219: -2.0412286 | J1219: 0.71217967 | K1219: 0.30807147 | L1219: -0.15704072 | M1219: LONG | N1219: 4 | O1219: signal | P1219: 59185 | Q1219: 32.5 | R1219: 45.355 | S1219: 0.27961433 | T1219: 0.011537655 | U1219: 0.0081119852 | V1219: 0.0034244169 | W1219: 0.0046875683
A1220: 9 | B1220: BAC | C1220: USB | D1220: 59192 | E1220: 32.525 | F1220: 45.37 | G1220: 32.521747 | H1220: 45.374537 | I1220: 1.6280145 | J1220: 0.71217967 | K1220: -0.3074558 | L1220: 0.15697149 | M1220: SHORT | N1220: 6 | O1220: signal | P1220: 59198 | Q1220: 32.55 | R1220: 45.455 | S1220: 0.092532096 | T1220: 0.0056561819 | U1220: 0.0022297197 | V1220: 0.0034243018 | W1220: -0.0011945821
A1221: 9 | B1221: BAC | C1221: USB | D1221: 59210 | E1221: 32.28 | F1221: 45.09 | G1221: 32.283228 | H1221: 45.085491 | I1221: -3.3704246 | J1221: 0.71217967 | K1221: 0.30978934 | L1221: -0.15794626 | M1221: LONG | N1221: 8 | O1221: signal | P1221: 59218 | Q1221: 32.35 | R1221: 45.06 | S1221: 0.29789108 | T1221: 0.026423642 | U1221: 0.022997588 | V1221: 0.0034244169 | W1221: 0.019573171
A1222: 9 | B1222: BAC | C1222: USB | D1222: 59224 | E1222: 32.11 | F1222: 44.785 | G1222: 32.113211 | H1222: 44.780522 | I1222: -2.5615801 | J1222: 0.71217967 | K1222: 0.31142946 | L1222: -0.15902192 | M1222: LONG | N1222: 14 | O1222: signal | P1222: 59238 | Q1222: 31.975 | R1222: 44.5 | S1222: -0.26322598 | T1222: 0.0032782699 | U1222: -0.00013735304 | V1222: 0.0034244169 | W1222: -0.0035617699
A1223: 9 | B1223: BAC | C1223: USB | D1223: 59241 | E1223: 31.885 | F1223: 44.57 | G1223: 31.888188 | H1223: 44.565543 | I1223: -1.9888139 | J1223: 0.71217967 | K1223: 0.3136271 | L1223: -0.15978902 | M1223: LONG | N1223: 2 | O1223: signal | P1223: 59243 | Q1223: 31.975 | R1223: 44.545 | S1223: -0.28225455 | T1223: 0.032221164 | U1223: 0.028794382 | V1223: 0.0034244169 | W1223: 0.025369965
A1224: 9 | B1224: BAC | C1224: USB | D1224: 59254 | E1224: 31.765 | F1224: 44.385 | G1224: 31.768176 | H1224: 44.380561 | I1224: -2.2048682 | J1224: 0.71217967 | K1224: 0.3148119 | L1224: -0.16045503 | M1224: LONG | N1224: 4 | O1224: signal | P1224: 59258 | Q1224: 31.76 | R1224: 44.245 | S1224: -0.28881098 | T1224: 0.020889645 | U1224: 0.01746769 | V1224: 0.0034244169 | W1224: 0.014043273
A1225: 9 | B1225: BAC | C1225: USB | D1225: 59261 | E1225: 31.825 | F1225: 44.21 | G1225: 31.821818 | H1225: 44.214421 | I1225: 1.8945684 | J1225: 0.71217967 | K1225: -0.31421838 | L1225: 0.16109018 | M1225: SHORT | N1225: 11 | O1225: signal | P1225: 59272 | Q1225: 31.925 | R1225: 44.49 | S1225: 0.076906469 | T1225: 0.013683411 | U1225: 0.010251399 | V1225: 0.0034243018 | W1225: 0.0068270973
...

Sheet Analysis
L1: Exit timestamp | M1: Cumulative Gross PnL | N1: Cumulative Slipped PnL | O1: Cumulative Net PnL | Q1: min holding minutes | R1: max holding minutes | S1: Mean Net PnL | T1: Number of trades
B2: Rough Analysis of the baseline strategy | J2: Figures | L2: =Trades!P2 -> 24045 | M2: =Trades!T2 -> -0.003549022 | N2: =Trades!U2 -> -0.0064362968 | O2: =Trades!W2 -> -0.0093234086 | Q2: 0 | R2: 3 | S2: =AVERAGEIFS(Trades!W:W,Trades!N:N,">="&Q2,Trades!N:N,"<="&R2) -> 0.0052277562 | T2: =COUNTIFS(Trades!N:N,">="&Q2,Trades!N:N,"<="&R2) -> 2171
L3: =Trades!P3 -> 24082 | M3: =M2+Trades!T3 -> -0.0019071564 | N3: =N2+Trades!U3 -> -0.0076847413 | O3: =O2+Trades!W3 -> -0.013458965 | Q3: 4 | R3: 7 | S3: =AVERAGEIFS(Trades!W:W,Trades!N:N,">="&Q3,Trades!N:N,"<="&R3) -> 0.0052270235 | T3: =COUNTIFS(Trades!N:N,">="&Q3,Trades!N:N,"<="&R3) -> 2304
B4: Column1 | C4: Gross | D4: Slipped | E4: Net (Transaction costs) | L4: =Trades!P4 -> 24093 | M4: =M3+Trades!T4 -> 0.0068808751 | N4: =N3+Trades!U4 -> -0.0017857384 | O4: =O3+Trades!W4 -> -0.010447074 | Q4: 8 | R4: 11 | S4: =AVERAGEIFS(Trades!W:W,Trades!N:N,">="&Q4,Trades!N:N,"<="&R4) -> 0.0023024376 | T4: =COUNTIFS(Trades!N:N,">="&Q4,Trades!N:N,"<="&R4) -> 1512
B5: Overall PnL | C5: =SUM(Trades!T2:T9652) -> 46.618463 | D5: =SUM(Trades!U2:U9652) -> 11.60472 | E5: =SUM(Trades!W2:W9652) -> -23.408147 | L5: =Trades!P5 -> 24116 | M5: =M4+Trades!T5 -> 0.013233634 | N5: =N4+Trades!U5 -> 0.0016800288 | O5: =O4+Trades!W5 -> -0.0098681958 | Q5: 12 | R5: 15 | S5: =AVERAGEIFS(Trades!W:W,Trades!N:N,">="&Q5,Trades!N:N,"<="&R5) -> -0.0021627422 | T5: =COUNTIFS(Trades!N:N,">="&Q5,Trades!N:N,"<="&R5) -> 1084
B6: Mean PnL | C6: =AVERAGE(Trades!T:T) -> 0.0048304283 | D6: =AVERAGE(Trades!U:U) -> 0.001202437 | E6: =AVERAGE(Trades!W:W) -> -0.0024254634 | L6: =Trades!P6 -> 24133 | M6: =M5+Trades!T6 -> 0.02045049 | N6: =N5+Trades!U6 -> 0.0060094763 | O6: =O5+Trades!W6 -> -0.0084258602 | Q6: 16 | R6: 19 | S6: =AVERAGEIFS(Trades!W:W,Trades!N:N,">="&Q6,Trades!N:N,"<="&R6) -> -0.0080257974 | T6: =COUNTIFS(Trades!N:N,">="&Q6,Trades!N:N,"<="&R6) -> 796
B7: Median PnL | C7: =MEDIAN(Trades!T:T) -> 0.0069323281 | D7: =MEDIAN(Trades!U:U) -> 0.0033873557 | E7: =MEDIAN(Trades!W:W) -> -0.00014851146 | L7: =Trades!P7 -> 24146 | M7: =M6+Trades!T7 -> 0.026860222 | N7: =N6+Trades!U7 -> 0.0095318804 | O7: =O6+Trades!W7 -> -0.0077905678 | Q7: 20 | R7: 23 | S7: =AVERAGEIFS(Trades!W:W,Trades!N:N,">="&Q7,Trades!N:N,"<="&R7) -> -0.011769587 | T7: =COUNTIFS(Trades!N:N,">="&Q7,Trades!N:N,"<="&R7) -> 592
B8: Max drawdown | C8: =MIN(Trades!T:T) -> -1.0062256 | D8: =MIN(Trades!U:U) -> -1.0123855 | E8: =MIN(Trades!W:W) -> -1.0184582 | L8: =Trades!P8 -> 24177 | M8: =M7+Trades!T8 -> 0.022011737 | N8: =N7+Trades!U8 -> 0.0017968799 | O8: =O7+Trades!W8 -> -0.01841268 | Q8: 24 | R8: 27 | S8: =AVERAGEIFS(Trades!W:W,Trades!N:N,">="&Q8,Trades!N:N,"<="&R8) -> -0.020527564 | T8: =COUNTIFS(Trades!N:N,">="&Q8,Trades!N:N,"<="&R8) -> 410
B9: Biggest Winner | C9: =MAX(Trades!T:T) -> 0.51144834 | D9: =MAX(Trades!U:U) -> 0.50927349 | E9: =MAX(Trades!W:W) -> 0.50704771 | L9: =Trades!P9 -> 24211 | M9: =M8+Trades!T9 -> 0.014132307 | N9: =N8+Trades!U9 -> -0.0089708621 | O9: =O8+Trades!W9 -> -0.032067311 | Q9: 28 | R9: 34 | S9: =AVERAGEIFS(Trades!W:W,Trades!N:N,">="&Q9,Trades!N:N,"<="&R9) -> -0.025358155 | T9: =COUNTIFS(Trades!N:N,">="&Q9,Trades!N:N,"<="&R9) -> 399
B10: Win rate | C10: =COUNTIF(Trades!T:T,">0")/(COUNTIF(Trades!T:T,">0")+COUNTIF(Trades!T:T,"<0")) -> 0.77246812 | D10: =COUNTIF(Trades!U:U,">0")/(COUNTIF(Trades!U:U,">0")+COUNTIF(Trades!U:U,"<0")) -> 0.68365972 | E10: =COUNTIF(Trades!W:W,">0")/(COUNTIF(Trades!W:W,">0")+COUNTIF(Trades!W:W,"<0")) -> 0.49114081 | L10: =Trades!P10 -> 24238 | M10: =M9+Trades!T10 -> 0.035760983 | N10: =N9+Trades!U10 -> 0.0097813534 | O10: =O9+Trades!W10 -> -0.016201985 | Q10: 35 | R10: 40 | S10: =AVERAGEIFS(Trades!W:W,Trades!N:N,">="&Q10,Trades!N:N,"<="&R10) -> -0.034268153 | T10: =COUNTIFS(Trades!N:N,">="&Q10,Trades!N:N,"<="&R10) -> 162
B11: Profit Factor | C11: =SUMIF(Trades!T:T,">0",Trades!T:T)/ABS(SUMIF(Trades!T:T,"<0",Trades!T:T)) -> 1.981138 | D11: =SUMIF(Trades!U:U,">0",Trades!U:U)/ABS(SUMIF(Trades!U:U,"<0",Trades!U:U)) -> 1.2046779 | E11: =SUMIF(Trades!W:W,">0",Trades!W:W)/ABS(SUMIF(Trades!W:W,"<0",Trades!W:W)) -> 0.66988477
L12: =Trades!P11 -> 24257 | M12: =M10+Trades!T11 -> 0.053830131 | N12: =N10+Trades!U11 -> 0.024959405 | O12: =O10+Trades!W11 -> -0.0039110455 | Q12: 41 | R12: 47 | S12: =AVERAGEIFS(Trades!W:W,Trades!N:N,">="&Q12,Trades!N:N,"<="&R12) -> -0.036948969 | T12: =COUNTIFS(Trades!N:N,">="&Q12,Trades!N:N,"<="&R12) -> 111
B13: Column1 | C13: Column2 | L13: =Trades!P12 -> 24264 | M13: =M12+Trades!T12 -> 0.076492535 | N13: =N12+Trades!U12 -> 0.044730045 | O13: =O12+Trades!W12 -> 0.012972483
B14: Number of Trades | C14: =ROWS(Table1[]) -> 9651 | L14: =Trades!P13 -> 24272 | M14: =M13+Trades!T13 -> 0.093434693 | N14: =N13+Trades!U13 -> 0.058781953 | O14: =O13+Trades!W13 -> 0.024137279
B15: Mean holding time | C15: =AVERAGE(Trades!N:N) -> 11.613926 | L15: =Trades!P14 -> 24280 | M15: =M14+Trades!T14 -> 0.11044756 | N15: =N14+Trades!U14 -> 0.072907049 | O15: =O14+Trades!W14 -> 0.035375263
B16: Median holding time | C16: =MEDIAN(Trades!N:N) -> 8 | L16: =Trades!P15 -> 24286 | M16: =M15+Trades!T15 -> 0.13155826 | N16: =N15+Trades!U15 -> 0.091133483 | O16: =O15+Trades!W15 -> 0.050714808
B17: Max holding time | C17: =MAX(Trades!N:N) -> 104 | L17: =Trades!P16 -> 24316 | M17: =M16+Trades!T16 -> 0.14587165 | N17: =N16+Trades!U16 -> 0.10256265 | O17: =O16+Trades!W16 -> 0.059257089
L18: =Trades!P17 -> 24343 | M18: =M17+Trades!T17 -> 0.15174594 | N18: =N17+Trades!U17 -> 0.10555165 | O18: =O17+Trades!W17 -> 0.059358969
B19: Column1 | C19: Positive | D19: Negative | L19: =Trades!P18 -> 24366 | M19: =M18+Trades!T18 -> 0.15999309 | N19: =N18+Trades!U18 -> 0.11091241 | O19: =O18+Trades!W18 -> 0.061832847
B20: Mean entry z score | C20: =AVERAGEIF(Trades!I:I,">0",Trades!I:I) -> 1.978442 | D20: =AVERAGEIF(Trades!I:I,"<0",Trades!I:I) -> -1.9717978 | L20: =Trades!P19 -> 24402 | M20: =M19+Trades!T19 -> 0.15214409 | N20: =N19+Trades!U19 -> 0.10017751 | O20: =O19+Trades!W19 -> 0.048211057
B21: Median entry z score | C21: {=MEDIAN(_xlfn._xlws.FILTER(Trades!I:I,Trades!I:I>0))} -> 1.8199965 | D21: {=MEDIAN(_xlfn._xlws.FILTER(Trades!I:I,Trades!I:I<0))} -> -1.8140198 | L21: =Trades!P20 -> 24420 | M21: =M20+Trades!T20 -> 0.16881915 | N21: =N20+Trades!U20 -> 0.11396412 | O21: =O20+Trades!W20 -> 0.059110553
B22: max entry z score | C22: =_xlfn.MAXIFS(Trades!I:I,Trades!I:I,">0") -> 5.2946498 | D22: =_xlfn.MINIFS(Trades!I:I,Trades!I:I,"<0") -> -5.2946498 | L22: =Trades!P21 -> 24444 | M22: =M21+Trades!T21 -> 0.16776922 | N22: =N21+Trades!U21 -> 0.11002298 | O22: =O21+Trades!W21 -> 0.052282527
B23: Mean exit z score | C23: =AVERAGEIF(Trades!S:S,">0",Trades!S:S) -> 0.28014079 | D23: =AVERAGEIF(Trades!S:S,"<0",Trades!S:S) -> -0.27577936 | L23: =Trades!P22 -> 24480 | M23: =M22+Trades!T22 -> 0.15825068 | N23: =N22+Trades!U22 -> 0.097621117 | O23: =O22+Trades!W22 -> 0.036993549
B24: Median exit z score | C24: {=MEDIAN(_xlfn._xlws.FILTER(Trades!S:S,Trades!S:S>0))} -> 0.29698808 | D24: {=MEDIAN(_xlfn._xlws.FILTER(Trades!S:S,Trades!S:S<0))} -> -0.28780656 | L24: =Trades!P23 -> 24499 | M24: =M23+Trades!T23 -> 0.16312894 | N24: =N23+Trades!U23 -> 0.099612629 | O24: =O23+Trades!W23 -> 0.03609795
B25: max exit z score | C25: =_xlfn.MAXIFS(Trades!S:S,Trades!S:S,">0") -> 0.49995858 | D25: =_xlfn.MINIFS(Trades!S:S,Trades!S:S,"<0") -> -0.49996787 | L25: =Trades!P24 -> 24502 | M25: =M24+Trades!T24 -> 0.17351829 | N25: =N24+Trades!U24 -> 0.10711425 | O25: =O24+Trades!W24 -> 0.040712455
G26: 1 | H26: Edge is there, but wiped out by costs | L26: =Trades!P25 -> 24526 | M26: =M25+Trades!T25 -> 0.17048883 | N26: =N25+Trades!U25 -> 0.10119801 | O26: =O25+Trades!W25 -> 0.031909332
B27: Column1 | C27: Long | D27: Short | E27: Signal | F27: Forced | L27: =Trades!P26 -> 24552 | M27: =M26+Trades!T26 -> 0.16378556 | N27: =N26+Trades!U26 -> 0.091608831 | O27: =O26+Trades!W26 -> 0.019433039
B28: PnL (gross) | C28: =SUMIF(Trades!M:M,"LONG",Trades!T:T) -> 23.003665 | D28: =SUMIF(Trades!M:M,"SHORT",Trades!T:T) -> 23.614799 | E28: =SUMIF(Trades!O:O,"Signal",Trades!T:T) -> 46.716086 | F28: =SUMIF(Trades!O:O,"Forced",Trades!T:T) -> -0.09762246 | L28: =Trades!P27 -> 24564 | M28: =M27+Trades!T27 -> 0.17352355 | N28: =N27+Trades!U27 -> 0.098459273 | O28: =O27+Trades!W27 -> 0.02339637
B29: Number | C29: =COUNTIF(Trades!M:M,"LONG") -> 4816 | D29: =COUNTIF(Trades!M:M,"SHORT") -> 4835 | E29: =COUNTIF(Trades!O:O,"Signal") -> 9635 | F29: =COUNTIF(Trades!O:O,"Forced") -> 16 | L29: =Trades!P28 -> 24583 | M29: =M28+Trades!T28 -> 0.17329913 | N29: =N28+Trades!U28 -> 0.09534735 | O29: =O28+Trades!W28 -> 0.017397335
L30: =Trades!P29 -> 24594 | M30: =M29+Trades!T29 -> 0.18101305 | N30: =N29+Trades!U29 -> 0.10017255 | O30: =O29+Trades!W29 -> 0.019335425
B31: min Holding time | C31: Max Holding time | D31: Win rate | L31: =Trades!P30 -> 24608 | M31: =M30+Trades!T30 -> 0.18722598 | N31: =N30+Trades!U30 -> 0.10350006 | O31: =O30+Trades!W30 -> 0.01977582
B32: 0 | C32: 3 | D32: =COUNTIFS(Trades!N:N,">="&B32,Trades!N:N,"<="&C32,Trades!T:T,">0")/(COUNTIFS(Trades!N:N,">="&B32,Trades!N:N,"<="&C32,Trades!T:T,">0")+COUNTIFS(Trades!N:N,">="&B32,Trades!N:N,"<="&C32,Trades!T:T,"<0")) -> 0.99815753 | L32: =Trades!P31 -> 24620 | M32: =M31+Trades!T31 -> 0.19197307 | N32: =N31+Trades!U31 -> 0.10535631 | O32: =O31+Trades!W31 -> 0.01874518
B33: 4 | C33: 7 | D33: =COUNTIFS(Trades!N:N,">="&B33,Trades!N:N,"<="&C33,Trades!T:T,">0")/(COUNTIFS(Trades!N:N,">="&B33,Trades!N:N,"<="&C33,Trades!T:T,">0")+COUNTIFS(Trades!N:N,">="&B33,Trades!N:N,"<="&C33,Trades!T:T,"<0")) -> 0.99609375 | L33: =Trades!P32 -> 24655 | M33: =M32+Trades!T32 -> 0.18816685 | N33: =N32+Trades!U32 -> 0.098667438 | O33: =O32+Trades!W32 -> 0.0091691976
B34: 8 | C34: 11 | D34: =COUNTIFS(Trades!N:N,">="&B34,Trades!N:N,"<="&C34,Trades!T:T,">0")/(COUNTIFS(Trades!N:N,">="&B34,Trades!N:N,"<="&C34,Trades!T:T,">0")+COUNTIFS(Trades!N:N,">="&B34,Trades!N:N,"<="&C34,Trades!T:T,"<0")) -> 0.95701058 | L34: =Trades!P33 -> 24684 | M34: =M33+Trades!T33 -> 0.20216125 | N34: =N33+Trades!U33 -> 0.10977624 | O34: =O33+Trades!W33 -> 0.01739111
B35: 12 | C35: 15 | D35: =COUNTIFS(Trades!N:N,">="&B35,Trades!N:N,"<="&C35,Trades!T:T,">0")/(COUNTIFS(Trades!N:N,">="&B35,Trades!N:N,"<="&C35,Trades!T:T,">0")+COUNTIFS(Trades!N:N,">="&B35,Trades!N:N,"<="&C35,Trades!T:T,"<0")) -> 0.76638966 | L35: =Trades!P34 -> 24726 | M35: =M34+Trades!T34 -> 0.18755977 | N35: =N34+Trades!U34 -> 0.092290465 | O35: =O34+Trades!W34 -> -0.0029817759
B36: 16 | C36: 1000000 | D36: =COUNTIFS(Trades!N:N,">="&B36,Trades!N:N,"<="&C36,Trades!T:T,">0")/(COUNTIFS(Trades!N:N,">="&B36,Trades!N:N,"<="&C36,Trades!T:T,">0")+COUNTIFS(Trades!N:N,">="&B36,Trades!N:N,"<="&C36,Trades!T:T,"<0")) -> 0.27667831 | L36: =Trades!P35 -> 24739 | M36: =M35+Trades!T35 -> 0.20161598 | N36: =N35+Trades!U35 -> 0.10346315 | O36: =O35+Trades!W35 -> 0.0053040247
L37: =Trades!P36 -> 24761 | M37: =M36+Trades!T36 -> 0.1948286 | N37: =N36+Trades!U36 -> 0.093785279 | O37: =O36+Trades!W36 -> -0.0072607405
L38: =Trades!P37 -> 24774 | M38: =M37+Trades!T37 -> 0.21662206 | N38: =N37+Trades!U37 -> 0.11268789 | O38: =O37+Trades!W37 -> 0.008754761
B39: Conclusion: | L39: =Trades!P38 -> 24800 | M39: =M38+Trades!T38 -> 0.21030372 | N39: =N38+Trades!U38 -> 0.10348047 | O39: =O38+Trades!W38 -> -0.0033395523
B40: "The baseline strategy exhibits a positive gross trading edge, but this edge is insufficient to overcome the assumed transaction costs and slippage. Under the baseline execution assumptions, implementation frictions are the primary driver of the strategy's negative net performance." | L40: =Trades!P39 -> 24819 | M40: =M39+Trades!T39 -> 0.20633064 | N40: =N39+Trades!U39 -> 0.096617906 | O40: =O39+Trades!W39 -> -0.013089004
...
