Workbook

Sheet Trades
A1: window_id | B1: stock1 | C1: stock2 | D1: entry_timestamp | E1: entry_price_1 | F1: entry_price_2 | G1: entry_price_1_slipped | H1: entry_price_2_slipped | I1: entry_zscore | J1: hedge_ratio_entry | K1: position_size_1 | L1: position_size_2 | M1: direction | N1: holding_minutes | O1: exit_reason | P1: exit_timestamp | Q1: exit_price_1 | R1: exit_price_2 | S1: exit_zscore | T1: gross_pnl | U1: gross_pnl_slipped | V1: transaction_costs | W1: net_pnl | X1: exit_price_age_1 | Y1: exit_price_age_2
A2: 0 | B2: JPM | C2: GS | D2: 24207 | E2: 306.355 | F2: 782.975 | G2: 306.32436 | H2: 783.0533 | I2: 3.594531 | J2: 0.66743015 | K2: -0.03264187 | L2: 0.0085242843 | M2: SHORT | N2: 7 | O2: signal | P2: 24214 | Q2: 305.615 | R2: 782.975 | S2: 0.36824447 | T2: 0.024154984 | U2: 0.020822539 | V2: 0.0033347938 | W2: 0.017487745 | X2: 305.615 | Y2: 782.975
A3: 0 | B3: JPM | C3: GS | D3: 24601 | E3: 310.255 | F3: 784.85 | G3: 310.22397 | H3: 784.92849 | I3: 3.7200374 | J3: 0.66743015 | K3: -0.032231551 | L3: 0.0085039198 | M3: SHORT | N3: 5 | O3: signal | P3: 24606 | Q3: 309.23 | R3: 786.1 | S3: 0.45860297 | T3: 0.04366724 | U3: 0.04033462 | V3: 0.0033347938 | W3: 0.036999827 | X3: 309.23 | Y3: 786.1
A4: 0 | B4: JPM | C4: GS | D4: 24832 | E4: 309.67 | F4: 784.45 | G4: 309.63903 | H4: 784.52845 | I4: 3.979432 | J4: 0.66743015 | K4: -0.03229244 | L4: 0.0085082561 | M4: SHORT | N4: 16 | O4: signal | P4: 24848 | Q4: 309.315 | R4: 783.6 | S4: 0.38578157 | T4: 0.0042317987 | U4: 0.00089880794 | V4: 0.0033347938 | W4: -0.0024359858 | X4: 309.315 | Y4: 783.6
A5: 0 | B5: JPM | C5: GS | D5: 24987 | E5: 310.945 | F5: 792.31 | G5: 310.97609 | H5: 792.23077 | I5: -4.4660855 | J5: 0.66743015 | K5: 0.032160028 | L5: -0.0084238511 | M5: LONG | N5: 9 | O5: signal | P5: 24996 | Q5: 311.59 | R5: 790.28 | S5: 0.2672345 | T5: 0.037843636 | U5: 0.034508411 | V5: 0.0033349268 | W5: 0.031173485 | X5: 311.59 | Y5: 790.28
A6: 0 | B6: JPM | C6: GS | D6: 25380 | E6: 305.665 | F6: 775.68 | G6: 305.69557 | H6: 775.60243 | I6: -3.6905639 | J6: 0.66743015 | K6: 0.032715555 | L6: -0.0086044522 | M6: LONG | N6: 12 | O6: signal | P6: 25392 | Q6: 307.425 | R6: 778.79 | S6: 0.21702582 | T6: 0.03081953 | U6: 0.027476236 | V6: 0.0033349268 | W6: 0.024141309 | X6: 307.425 | Y6: 778.79
A7: 0 | B7: JPM | C7: GS | D7: 25694 | E7: 308.605 | F7: 791.07 | G7: 308.57414 | H7: 791.14911 | I7: 3.6289486 | J7: 0.66743015 | K7: -0.032403882 | L7: 0.0084370555 | M7: SHORT | N7: 37 | O7: signal | P7: 25731 | Q7: 309.34 | R7: 792.03 | S7: 0.21396878 | T7: -0.01571728 | U7: -0.019055332 | V7: 0.0033347938 | W7: -0.022390126 | X7: 309.34 | Y7: 792.03
A8: 0 | B8: JPM | C8: GS | D8: 25752 | E8: 310.22 | F8: 793.57 | G8: 310.18898 | H8: 793.64936 | I8: 3.587045 | J8: 0.66743015 | K8: -0.032235188 | L8: 0.0084104761 | M8: SHORT | N8: 6 | O8: signal | P8: 25758 | Q8: 309.595 | R8: 792.46 | S8: 0.10046321 | T8: 0.010811364 | U8: 0.007479452 | V8: 0.0033347938 | W8: 0.0041446582 | X8: 309.595 | Y8: 792.46
A9: 0 | B9: JPM | C9: GS | D9: 26937 | E9: 316.57 | F9: 798.58 | G9: 316.60166 | H9: 798.50014 | I9: -3.6665215 | J9: 0.66743015 | K9: 0.03158859 | L9: -0.0083577118 | M9: LONG | N9: 5 | O9: signal | P9: 26942 | Q9: 319.07 | R9: 804.4 | S9: -0.22070535 | T9: 0.030329593 | U9: 0.026981971 | V9: 0.0033349268 | W9: 0.023647044 | X9: 319.07 | Y9: 804.4
A10: 0 | B10: JPM | C10: GS | D10: 27327 | E10: 318.785 | F10: 801.62 | G10: 318.75312 | H10: 801.70016 | I10: 3.8655947 | J10: 0.66743015 | K10: -0.031369105 | L10: 0.0083260167 | M10: SHORT | N10: 5 | O10: signal | P10: 27332 | Q10: 316.99 | R10: 797.74 | S10: 0.091473395 | T10: 0.024002598 | U10: 0.020676599 | V10: 0.0033347938 | W10: 0.017341805 | X10: 316.99 | Y10: 797.74
A11: 0 | B11: JPM | C11: GS | D11: 27717 | E11: 316.63 | F11: 816.83 | G11: 316.66166 | H11: 816.74832 | I11: -4.1191154 | J11: 0.66743015 | K11: 0.031582604 | L11: -0.0081709799 | M11: LONG | N11: 8 | O11: signal | P11: 27725 | Q11: 320.43 | R11: 829.34 | S11: -0.091250949 | T11: 0.017794938 | U11: 0.014437855 | V11: 0.0033349268 | W11: 0.011102928 | X11: 320.43 | Y11: 829.34
A12: 1 | B12: JPM | C12: GS | D12: 28497 | E12: 305.71 | F12: 787.29 | G12: 305.67943 | H12: 787.36873 | I12: 3.9612488 | J12: 0.65390315 | K12: -0.032710739 | L12: 0.0083057469 | M12: SHORT | N12: 7 | O12: signal | P12: 28504 | Q12: 304.365 | R12: 786.38 | S12: 0.030918091 | T12: 0.036437714 | U12: 0.033135063 | V12: 0.0033077371 | W12: 0.029827326 | X12: 304.365 | Y12: 786.38
A13: 1 | B13: JPM | C13: GS | D13: 28630 | E13: 304.8 | F13: 797.315 | G13: 304.83048 | H13: 797.23527 | I13: -3.6261084 | J13: 0.65390315 | K13: 0.032808399 | L13: -0.0082013151 | M13: LONG | N13: 9 | O13: signal | P13: 28639 | Q13: 305.47 | R13: 796.03 | S13: 0.26313253 | T13: 0.032520317 | U13: 0.029211367 | V13: 0.0033078755 | W13: 0.025903491 | X13: 305.47 | Y13: 796.03
... A133: 16 | B133: BAC | C133: USB | D133: 90259 | E133: 59.24 | F133: 62.225 | G133: 59.234076 | H133: 62.231223 | I133: 3.938376 | J133: 1.2019117 | K133: -0.16880486 | L133: 0.19315576 | M133: SHORT | N133: 31 | O133: signal | P133: 90290 | Q133: 59.23 | R133: 61.88 | S133: 0.19335895 | T133: -0.06495069 | U133: -0.06934768 | V133: 0.0044038639 | W133: -0.073751544 | X133: 59.23 | Y133: 61.88

Sheet trades edited
A1: window_id | B1: stock1 | C1: stock2 | D1: entry_timestamp | E1: entry_price_1 | F1: entry_price_2 | G1: entry_price_1_slipped | H1: entry_price_2_slipped | I1: entry_zscore | J1: hedge_ratio_entry | K1: position_size_1 | L1: position_size_2 | M1: direction | N1: holding_minutes | O1: exit_reason | P1: exit_timestamp | Q1: exit_price_1 | R1: exit_price_2 | S1: exit_zscore | T1: gross_pnl | U1: gross_pnl_slipped | V1: transaction_costs | W1: net_pnl | X1: Entry day | Y1: Exit day | AB1: timestamp | AC1: minute | AE1: UK Date | AF1: US DATE | AG1: VIX ON ENTRY
A2: 0 | B2: JPM | C2: GS | D2: 24207 | E2: 306.355 | F2: 782.975 | G2: 306.32436 | H2: 783.0533 | I2: 3.594531 | J2: 0.66743015 | K2: -0.03264187 | L2: 0.0085242843 | M2: SHORT | N2: 7 | O2: signal | P2: 24214 | Q2: 305.615 | R2: 782.975 | S2: 0.36824447 | T2: 0.024154984 | U2: 0.020822539 | V2: 0.0033347938 | W2: 0.017487745 | X2: =WORKDAY(DATE(2025,8,2),INT(D2/390)) -> 45958 | Y2: =WORKDAY(DATE(2025,8,2),INT(P2/390)) -> 45958 | AB2: 45873.562 | AC2: 0 | AE2: =IF(ISNUMBER(AF2),DATE(YEAR(AF2),DAY(AF2),MONTH(AF2)),DATE(RIGHT(AF2,4),LEFT(AF2,2),MID(AF2,4,2))) -> 45870 | AF2: 45665 | AG2: 20.38 | AJ2: VIX at entry | AK2: Net PnL | AL2: Trades | AM2: Avg Net P&L | AN2: Win rate
A3: 0 | B3: JPM | C3: GS | D3: 24601 | E3: 310.255 | F3: 784.85 | G3: 310.22397 | H3: 784.92849 | I3: 3.7200374 | J3: 0.66743015 | K3: -0.032231551 | L3: 0.0085039198 | M3: SHORT | N3: 5 | O3: signal | P3: 24606 | Q3: 309.23 | R3: 786.1 | S3: 0.45860297 | T3: 0.04366724 | U3: 0.04033462 | V3: 0.0033347938 | W3: 0.036999827 | X3: =WORKDAY(DATE(2025,8,2),INT(D3/390)) -> 45959 | Y3: =WORKDAY(DATE(2025,8,2),INT(P3/390)) -> 45959 | AB3: 45873.563 | AC3: 1 | AE3: =IF(ISNUMBER(AF3),DATE(YEAR(AF3),DAY(AF3),MONTH(AF3)),DATE(RIGHT(AF3,4),LEFT(AF3,2),MID(AF3,4,2))) -> 45873 | AF3: 45755 | AG3: 17.52 | AJ3: <15 | AK3: =AL3*AM3 -> #DIV/0! | AL3: =COUNTIF(Z:Z,"<15") -> 0 | AM3: =AVERAGEIF(Z:Z,"<15",W:W) -> #DIV/0! | AN3: =COUNTIFS(Z:Z,"<15",T:T,">0")/COUNTIFS(Z:Z,"<15") -> #DIV/0!
A4: 0 | B4: JPM | C4: GS | D4: 24832 | E4: 309.67 | F4: 784.45 | G4: 309.63903 | H4: 784.52845 | I4: 3.979432 | J4: 0.66743015 | K4: -0.03229244 | L4: 0.0085082561 | M4: SHORT | N4: 16 | O4: signal | P4: 24848 | Q4: 309.315 | R4: 783.6 | S4: 0.38578157 | T4: 0.0042317987 | U4: 0.00089880794 | V4: 0.0033347938 | W4: -0.0024359858 | X4: =WORKDAY(DATE(2025,8,2),INT(D4/390)) -> 45959 | Y4: =WORKDAY(DATE(2025,8,2),INT(P4/390)) -> 45959 | AB4: 45873.564 | AC4: 2 | AE4: =IF(ISNUMBER(AF4),DATE(YEAR(AF4),DAY(AF4),MONTH(AF4)),DATE(RIGHT(AF4,4),LEFT(AF4,2),MID(AF4,4,2))) -> 45874 | AF4: 45785 | AG4: 17.85 | AJ4: 15–20 | AK4: =AL4*AM4 -> #DIV/0! | AL4: =COUNTIFS(Z:Z,">=15",Z:Z,"<20") -> 0 | AM4: =AVERAGEIFS(W:W,Z:Z,">=15",Z:Z,"<20") -> #DIV/0! | AN4: =COUNTIFS(Z:Z,">=15",Z:Z,"<20",T:T,">0")/COUNTIFS(Z:Z,">=15",Z:Z,"<20") -> #DIV/0!
A5: 0 | B5: JPM | C5: GS | D5: 24987 | E5: 310.945 | F5: 792.31 | G5: 310.97609 | H5: 792.23077 | I5: -4.4660855 | J5: 0.66743015 | K5: 0.032160028 | L5: -0.0084238511 | M5: LONG | N5: 9 | O5: signal | P5: 24996 | Q5: 311.59 | R5: 790.28 | S5: 0.2672345 | T5: 0.037843636 | U5: 0.034508411 | V5: 0.0033349268 | W5: 0.031173485 | X5: =WORKDAY(DATE(2025,8,2),INT(D5/390)) -> 45960 | Y5: =WORKDAY(DATE(2025,8,2),INT(P5/390)) -> 45960 | AB5: 45873.565 | AC5: 3 | AE5: =IF(ISNUMBER(AF5),DATE(YEAR(AF5),DAY(AF5),MONTH(AF5)),DATE(RIGHT(AF5,4),LEFT(AF5,2),MID(AF5,4,2))) -> 45875 | AF5: 45816 | AG5: 16.77 | AJ5: >=20 | AK5: =AL5*AM5 -> #DIV/0! | AL5: =COUNTIFS(Z:Z,">=20") -> 0 | AM5: =AVERAGEIFS(W:W,Z:Z,">=20") -> #DIV/0! | AN5: =COUNTIFS(Z:Z,">=20",T:T,">0")/COUNTIFS(Z:Z,">=20") -> #DIV/0!
A6: 0 | B6: JPM | C6: GS | D6: 25380 | E6: 305.665 | F6: 775.68 | G6: 305.69557 | H6: 775.60243 | I6: -3.6905639 | J6: 0.66743015 | K6: 0.032715555 | L6: -0.0086044522 | M6: LONG | N6: 12 | O6: signal | P6: 25392 | Q6: 307.425 | R6: 778.79 | S6: 0.21702582 | T6: 0.03081953 | U6: 0.027476236 | V6: 0.0033349268 | W6: 0.024141309 | X6: =WORKDAY(DATE(2025,8,2),INT(D6/390)) -> 45961 | Y6: =WORKDAY(DATE(2025,8,2),INT(P6/390)) -> 45961 | AB6: 45873.565 | AC6: 4 | AE6: =IF(ISNUMBER(AF6),DATE(YEAR(AF6),DAY(AF6),MONTH(AF6)),DATE(RIGHT(AF6,4),LEFT(AF6,2),MID(AF6,4,2))) -> 45876 | AF6: 45846 | AG6: 16.57
A7: 0 | B7: JPM | C7: GS | D7: 25694 | E7: 308.605 | F7: 791.07 | G7: 308.57414 | H7: 791.14911 | I7: 3.6289486 | J7: 0.66743015 | K7: -0.032403882 | L7: 0.0084370555 | M7: SHORT | N7: 37 | O7: signal | P7: 25731 | Q7: 309.34 | R7: 792.03 | S7: 0.21396878 | T7: -0.01571728 | U7: -0.019055332 | V7: 0.0033347938 | W7: -0.022390126 | X7: =WORKDAY(DATE(2025,8,2),INT(D7/390)) -> 45961 | Y7: =WORKDAY(DATE(2025,8,2),INT(P7/390)) -> 45961 | AB7: 45873.566 | AC7: 5 | AE7: =IF(ISNUMBER(AF7),DATE(YEAR(AF7),DAY(AF7),MONTH(AF7)),DATE(RIGHT(AF7,4),LEFT(AF7,2),MID(AF7,4,2))) -> 45877 | AF7: 45877 | AG7: 15.15
A8: 0 | B8: JPM | C8: GS | D8: 25752 | E8: 310.22 | F8: 793.57 | G8: 310.18898 | H8: 793.64936 | I8: 3.587045 | J8: 0.66743015 | K8: -0.032235188 | L8: 0.0084104761 | M8: SHORT | N8: 6 | O8: signal | P8: 25758 | Q8: 309.595 | R8: 792.46 | S8: 0.10046321 | T8: 0.010811364 | U8: 0.007479452 | V8: 0.0033347938 | W8: 0.0041446582 | X8: =WORKDAY(DATE(2025,8,2),INT(D8/390)) -> 45964 | Y8: =WORKDAY(DATE(2025,8,2),INT(P8/390)) -> 45964 | AB8: 45873.567 | AC8: 6 | AE8: =IF(ISNUMBER(AF8),DATE(YEAR(AF8),DAY(AF8),MONTH(AF8)),DATE(RIGHT(AF8,4),LEFT(AF8,2),MID(AF8,4,2))) -> 45880 | AF8: 45969 | AG8: 16.25
A9: 0 | B9: JPM | C9: GS | D9: 26937 | E9: 316.57 | F9: 798.58 | G9: 316.60166 | H9: 798.50014 | I9: -3.6665215 | J9: 0.66743015 | K9: 0.03158859 | L9: -0.0083577118 | M9: LONG | N9: 5 | O9: signal | P9: 26942 | Q9: 319.07 | R9: 804.4 | S9: -0.22070535 | T9: 0.030329593 | U9: 0.026981971 | V9: 0.0033349268 | W9: 0.023647044 | X9: =WORKDAY(DATE(2025,8,2),INT(D9/390)) -> 45967 | Y9: =WORKDAY(DATE(2025,8,2),INT(P9/390)) -> 45967 | AB9: 45873.567 | AC9: 7 | AE9: =IF(ISNUMBER(AF9),DATE(YEAR(AF9),DAY(AF9),MONTH(AF9)),DATE(RIGHT(AF9,4),LEFT(AF9,2),MID(AF9,4,2))) -> 45881 | AF9: 45999 | AG9: 14.73
A10: 0 | B10: JPM | C10: GS | D10: 27327 | E10: 318.785 | F10: 801.62 | G10: 318.75312 | H10: 801.70016 | I10: 3.8655947 | J10: 0.66743015 | K10: -0.031369105 | L10: 0.0083260167 | M10: SHORT | N10: 5 | O10: signal | P10: 27332 | Q10: 316.99 | R10: 797.74 | S10: 0.091473395 | T10: 0.024002598 | U10: 0.020676599 | V10: 0.0033347938 | W10: 0.017341805 | X10: =WORKDAY(DATE(2025,8,2),INT(D10/390)) -> 45968 | Y10: =WORKDAY(DATE(2025,8,2),INT(P10/390)) -> 45968 | AB10: 45873.568 | AC10: 8 | AE10: =IF(ISNUMBER(AF10),DATE(YEAR(AF10),DAY(AF10),MONTH(AF10)),DATE(RIGHT(AF10,4),LEFT(AF10,2),MID(AF10,4,2))) -> 45882 | AF10: 08/13/2025 | AG10: 14.49 | AJ10: Metric | AK10: OOS H1 | AL10: OOS H2
A11: 0 | B11: JPM | C11: GS | D11: 27717 | E11: 316.63 | F11: 816.83 | G11: 316.66166 | H11: 816.74832 | I11: -4.1191154 | J11: 0.66743015 | K11: 0.031582604 | L11: -0.0081709799 | M11: LONG | N11: 8 | O11: signal | P11: 27725 | Q11: 320.43 | R11: 829.34 | S11: -0.091250949 | T11: 0.017794938 | U11: 0.014437855 | V11: 0.0033349268 | W11: 0.011102928 | X11: =WORKDAY(DATE(2025,8,2),INT(D11/390)) -> 45971 | Y11: =WORKDAY(DATE(2025,8,2),INT(P11/390)) -> 45971 | AB11: 45873.569 | AC11: 9 | AE11: =IF(ISNUMBER(AF11),DATE(YEAR(AF11),DAY(AF11),MONTH(AF11)),DATE(RIGHT(AF11,4),LEFT(AF11,2),MID(AF11,4,2))) -> 45883 | AF11: 08/14/2025 | AG11: 14.83 | AJ11: Trades
A12: 1 | B12: JPM | C12: GS | D12: 28497 | E12: 305.71 | F12: 787.29 | G12: 305.67943 | H12: 787.36873 | I12: 3.9612488 | J12: 0.65390315 | K12: -0.032710739 | L12: 0.0083057469 | M12: SHORT | N12: 7 | O12: signal | P12: 28504 | Q12: 304.365 | R12: 786.38 | S12: 0.030918091 | T12: 0.036437714 | U12: 0.033135063 | V12: 0.0033077371 | W12: 0.029827326 | X12: =WORKDAY(DATE(2025,8,2),INT(D12/390)) -> 45973 | Y12: =WORKDAY(DATE(2025,8,2),INT(P12/390)) -> 45973 | AB12: 45873.569 | AC12: 10 | AE12: =IF(ISNUMBER(AF12),DATE(YEAR(AF12),DAY(AF12),MONTH(AF12)),DATE(RIGHT(AF12,4),LEFT(AF12,2),MID(AF12,4,2))) -> 45884 | AF12: 08/15/2025 | AG12: 15.09 | AJ12: Gross P&L
A13: 1 | B13: JPM | C13: GS | D13: 28630 | E13: 304.8 | F13: 797.315 | G13: 304.83048 | H13: 797.23527 | I13: -3.6261084 | J13: 0.65390315 | K13: 0.032808399 | L13: -0.0082013151 | M13: LONG | N13: 9 | O13: signal | P13: 28639 | Q13: 305.47 | R13: 796.03 | S13: 0.26313253 | T13: 0.032520317 | U13: 0.029211367 | V13: 0.0033078755 | W13: 0.025903491 | X13: =WORKDAY(DATE(2025,8,2),INT(D13/390)) -> 45973 | Y13: =WORKDAY(DATE(2025,8,2),INT(P13/390)) -> 45973 | AB13: 45873.57 | AC13: 11 | AE13: =IF(ISNUMBER(AF13),DATE(YEAR(AF13),DAY(AF13),MONTH(AF13)),DATE(RIGHT(AF13,4),LEFT(AF13,2),MID(AF13,4,2))) -> 45887 | AF13: 08/18/2025 | AG13: 14.99 | AJ13: Net P&L
A14: 1 | B14: JPM | C14: GS | D14: 28708 | E14: 304.81 | F14: 797.11 | G14: 304.84048 | H14: 797.03029 | I14: -3.55602 | J14: 0.65390315 | K14: 0.032807323 | L14: -0.0082034243 | M14: LONG | N14: 27 | O14: signal | P14: 28735 | Q14: 304.57 | R14: 796.62 | S14: 0.12160767 | T14: -0.0038540795 | U14: -0.0071606965 | V14: 0.0033078755 | W14: -0.010468572 | X14: =WORKDAY(DATE(2025,8,2),INT(D14/390)) -> 45973 | Y14: =WORKDAY(DATE(2025,8,2),INT(P14/390)) -> 45973 | AB14: 45873.571 | AC14: 12 | AE14: =IF(ISNUMBER(AF14),DATE(YEAR(AF14),DAY(AF14),MONTH(AF14)),DATE(RIGHT(AF14,4),LEFT(AF14,2),MID(AF14,4,2))) -> 45888 | AF14: 08/19/2025 | AG14: 15.57 | AJ14: Avg gross P&L/trade
A15: 1 | B15: JPM | C15: GS | D15: 29594 | E15: 301.3 | F15: 781.25 | G15: 301.26987 | H15: 781.32812 | I15: 3.5359515 | J15: 0.65390315 | K15: -0.033189512 | L15: 0.0083699603 | M15: SHORT | N15: 5 | O15: signal | P15: 29599 | Q15: 300.495 | R15: 781.25 | S15: -0.42317359 | T15: 0.026717557 | U15: 0.023412423 | V15: 0.0033077371 | W15: 0.020104686 | X15: =WORKDAY(DATE(2025,8,2),INT(D15/390)) -> 45975 | Y15: =WORKDAY(DATE(2025,8,2),INT(P15/390)) -> 45975 | AB15: 45873.572 | AC15: 13 | AE15: =IF(ISNUMBER(AF15),DATE(YEAR(AF15),DAY(AF15),MONTH(AF15)),DATE(RIGHT(AF15,4),LEFT(AF15,2),MID(AF15,4,2))) -> 45889 | AF15: 08/20/2025 | AG15: 15.69 | AJ15: Avg net P&L/trade
A16: 1 | B16: JPM | C16: GS | D16: 29667 | E16: 300.82 | F16: 776.07 | G16: 300.78992 | H16: 776.14761 | I16: 4.3180527 | J16: 0.65390315 | K16: -0.033242471 | L16: 0.0084258269 | M16: SHORT | N16: 24 | O16: signal | P16: 29691 | Q16: 302.36 | R16: 779.065 | S16: 0.36508655 | T16: -0.025958053 | U16: -0.029273502 | V16: 0.0033077371 | W16: -0.032581239 | X16: =WORKDAY(DATE(2025,8,2),INT(D16/390)) -> 45978 | Y16: =WORKDAY(DATE(2025,8,2),INT(P16/390)) -> 45978 | AB16: 45873.572 | AC16: 14 | AE16: =IF(ISNUMBER(AF16),DATE(YEAR(AF16),DAY(AF16),MONTH(AF16)),DATE(RIGHT(AF16,4),LEFT(AF16,2),MID(AF16,4,2))) -> 45890 | AF16: 08/21/2025 | AG16: 16.6 | AJ16: Net PF
A17: 1 | B17: JPM | C17: GS | D17: 30059 | E17: 307.04 | F17: 805.745 | G17: 307.0707 | H17: 805.66443 | I17: -3.8618259 | J17: 0.65390315 | K17: 0.032569046 | L17: -0.0081155099 | M17: LONG | N17: 6 | O17: signal | P17: 30065 | Q17: 308.48 | R17: 807.56 | S17: -0.319723 | T17: 0.032169776 | U17: 0.028855807 | V17: 0.0033078755 | W17: 0.025547932 | X17: =WORKDAY(DATE(2025,8,2),INT(D17/390)) -> 45979 | Y17: =WORKDAY(DATE(2025,8,2),INT(P17/390)) -> 45979 | AB17: 45873.573 | AC17: 15 | AE17: =IF(ISNUMBER(AF17),DATE(YEAR(AF17),DAY(AF17),MONTH(AF17)),DATE(RIGHT(AF17,4),LEFT(AF17,2),MID(AF17,4,2))) -> 45891 | AF17: 08/22/2025 | AG17: 14.22 | AJ17: Win rate
A18: 1 | B18: JPM | C18: GS | D18: 31217 | E18: 297.97 | F18: 792.37 | G18: 297.9998 | H18: 792.29076 | I18: -3.574562 | J18: 0.65390315 | K18: 0.033560426 | L18: -0.0082524976 | M18: LONG | N18: 10 | O18: signal | P18: 31227 | Q18: 299.32 | R18: 795.235 | S18: -0.43617298 | T18: 0.021663169 | U18: 0.018348468 | V18: 0.0033078755 | W18: 0.015040592 | X18: =WORKDAY(DATE(2025,8,2),INT(D18/390)) -> 45982 | Y18: =WORKDAY(DATE(2025,8,2),INT(P18/390)) -> 45982 | AB18: 45873.574 | AC18: 16 | AE18: =IF(ISNUMBER(AF18),DATE(YEAR(AF18),DAY(AF18),MONTH(AF18)),DATE(RIGHT(AF18,4),LEFT(AF18,2),MID(AF18,4,2))) -> 45894 | AF18: 08/25/2025 | AG18: 14.79 | AJ18: Avg winner
A19: 2 | B19: BAC | C19: WFC | D19: 32007 | E19: 53.05 | F19: 85.48 | G19: 53.044695 | H19: 85.488548 | I19: 4.5358082 | J19: 0.73858207 | K19: -0.18850141 | L19: 0.08640408 | M19: SHORT | N19: 48 | O19: signal | P19: 32055 | Q19: 53.64 | R19: 85.89 | S19: 0.45483687 | T19: -0.075790161 | U19: -0.07928199 | V19: 0.0034771119 | W19: -0.082759102 | X19: =WORKDAY(DATE(2025,8,2),INT(D19/390)) -> 45986 | Y19: =WORKDAY(DATE(2025,8,2),INT(P19/390)) -> 45986 | AB19: 45873.574 | AC19: 17 | AE19: =IF(ISNUMBER(AF19),DATE(YEAR(AF19),DAY(AF19),MONTH(AF19)),DATE(RIGHT(AF19,4),LEFT(AF19,2),MID(AF19,4,2))) -> 45895 | AF19: 08/26/2025 | AG19: 14.62 | AJ19: Avg loser
A20: 2 | B20: BAC | C20: WFC | D20: 32217 | E20: 53.525 | F20: 85.885 | G20: 53.530352 | H20: 85.876412 | I20: -4.2270289 | J20: 0.73858207 | K20: 0.18682858 | L20: -0.085996632 | M20: LONG | N20: 1 | O20: signal | P20: 32218 | Q20: 53.54 | R20: 85.66 | S20: 0.16301468 | T20: 0.022151671 | U20: 0.018676161 | V20: 0.0034772164 | W20: 0.015198945 | X20: =WORKDAY(DATE(2025,8,2),INT(D20/390)) -> 45986 | Y20: =WORKDAY(DATE(2025,8,2),INT(P20/390)) -> 45986 | AB20: 45873.575 | AC20: 18 | AE20: =IF(ISNUMBER(AF20),DATE(YEAR(AF20),DAY(AF20),MONTH(AF20)),DATE(RIGHT(AF20,4),LEFT(AF20,2),MID(AF20,4,2))) -> 45896 | AF20: 08/27/2025 | AG20: 14.85 | AJ20: Avg holding time
A21: 2 | B21: BAC | C21: WFC | D21: 32614 | E21: 53.25 | F21: 85.77 | G21: 53.255325 | H21: 85.761423 | I21: -3.6888174 | J21: 0.73858207 | K21: 0.18779343 | L21: -0.086111936 | M21: LONG | N21: 17 | O21: signal | P21: 32631 | Q21: 53.135 | R21: 85.39 | S21: -0.28159101 | T21: 0.011126291 | U21: 0.0076545592 | V21: 0.0034772164 | W21: 0.0041773427 | X21: =WORKDAY(DATE(2025,8,2),INT(D21/390)) -> 45987 | Y21: =WORKDAY(DATE(2025,8,2),INT(P21/390)) -> 45987 | AB21: 45873.576 | AC21: 19 | AE21: =IF(ISNUMBER(AF21),DATE(YEAR(AF21),DAY(AF21),MONTH(AF21)),DATE(RIGHT(AF21,4),LEFT(AF21,2),MID(AF21,4,2))) -> 45897 | AF21: 08/28/2025 | AG21: 14.43 | AJ21: Avg |entry Z|
A22: 2 | B22: BAC | C22: WFC | D22: 32998 | E22: 53.3 | F22: 86.31 | G22: 53.29467 | H22: 86.318631 | I22: 4.1634247 | J22: 0.73858207 | K22: -0.18761726 | L22: 0.085573175 | M22: SHORT | N22: 17 | O22: signal | P22: 33015 | Q22: 53.525 | R22: 86.83 | S22: 0.4746937 | T22: 0.0022841673 | U22: -0.0012016681 | V22: 0.0034771119 | W22: -0.0046787799 | X22: =WORKDAY(DATE(2025,8,2),INT(D22/390)) -> 45988 | Y22: =WORKDAY(DATE(2025,8,2),INT(P22/390)) -> 45988 | AB22: 45873.576 | AC22: 20 | AE22: =IF(ISNUMBER(AF22),DATE(YEAR(AF22),DAY(AF22),MONTH(AF22)),DATE(RIGHT(AF22,4),LEFT(AF22,2),MID(AF22,4,2))) -> 45898 | AF22: 08/29/2025 | AG22: 15.36
A23: 2 | B23: BAC | C23: WFC | D23: 34559 | E23: 54.005 | F23: 89.76 | G23: 53.9996 | H23: 89.768976 | I23: 3.5672352 | J23: 0.73858207 | K23: -0.18516804 | L23: 0.082284099 | M23: SHORT | N23: 5 | O23: signal | P23: 34564 | Q23: 53.83 | R23: 89.755 | S23: 0.11894705 | T23: 0.031992987 | U23: 0.028519104 | V23: 0.0034771119 | W23: 0.025041992 | X23: =WORKDAY(DATE(2025,8,2),INT(D23/390)) -> 45994 | Y23: =WORKDAY(DATE(2025,8,2),INT(P23/390)) -> 45994 | AB23: 45873.577 | AC23: 21 | AE23: =IF(ISNUMBER(AF23),DATE(YEAR(AF23),DAY(AF23),MONTH(AF23)),DATE(RIGHT(AF23,4),LEFT(AF23,2),MID(AF23,4,2))) -> 45901 | AF23: 45666 | AG23: 16.12
A24: 2 | B24: BAC | C24: WFC | D24: 35304 | E24: 53.915 | F24: 90.32 | G24: 53.920392 | H24: 90.310968 | I24: -3.5605368 | J24: 0.73858207 | K24: 0.18547714 | L24: -0.081773923 | M24: LONG | N24: 6 | O24: signal | P24: 35310 | Q24: 54.27 | R24: 90.385 | S24: 0.059936539 | T24: 0.06052908 | U24: 0.0570448 | V24: 0.0034772164 | W24: 0.053567583 | X24: =WORKDAY(DATE(2025,8,2),INT(D24/390)) -> 45996 | Y24: =WORKDAY(DATE(2025,8,2),INT(P24/390)) -> 45996 | AB24: 45873.578 | AC24: 22 | AE24: =IF(ISNUMBER(AF24),DATE(YEAR(AF24),DAY(AF24),MONTH(AF24)),DATE(RIGHT(AF24,4),LEFT(AF24,2),MID(AF24,4,2))) -> 45902 | AF24: 45697 | AG24: 17.17
A25: 3 | B25: BAC | C25: WFC | D25: 36509 | E25: 54.965 | F25: 93.105 | G25: 54.970497 | H25: 93.09569 | I25: -4.8712868 | J25: 0.67544695 | K25: 0.18193396 | L25: -0.072546796 | M25: LONG | N25: 7 | O25: signal | P25: 36516 | Q25: 55.35 | R25: 93.03 | S25: -0.41313051 | T25: 0.075485584 | U25: 0.072128229 | V25: 0.0033509588 | W25: 0.06877727 | X25: =WORKDAY(DATE(2025,8,2),INT(D25/390)) -> 46001 | Y25: =WORKDAY(DATE(2025,8,2),INT(P25/390)) -> 46001 | AB25: 45873.578 | AC25: 23 | AE25: =IF(ISNUMBER(AF25),DATE(YEAR(AF25),DAY(AF25),MONTH(AF25)),DATE(RIGHT(AF25,4),LEFT(AF25,2),MID(AF25,4,2))) -> 45903 | AF25: 45725 | AG25: 16.35
A26: 3 | B26: BAC | C26: WFC | D26: 37290 | E26: 54.595 | F26: 93.11 | G26: 54.600459 | H26: 93.100689 | I26: -3.9272584 | J26: 0.67544695 | K26: 0.18316696 | L26: -0.0725429 | M26: LONG | N26: 25 | O26: signal | P26: 37315 | Q26: 55.1 | R26: 93.705 | S26: 0.14678068 | T26: 0.049336287 | U26: 0.045971827 | V26: 0.0033509588 | W26: 0.042620868 | X26: =WORKDAY(DATE(2025,8,2),INT(D26/390)) -> 46003 | Y26: =WORKDAY(DATE(2025,8,2),INT(P26/390)) -> 46003 | AB26: 45873.579 | AC26: 24 | AE26: =IF(ISNUMBER(AF26),DATE(YEAR(AF26),DAY(AF26),MONTH(AF26)),DATE(RIGHT(AF26,4),LEFT(AF26,2),MID(AF26,4,2))) -> 45904 | AF26: 45756 | AG26: 15.3
A27: 3 | B27: BAC | C27: WFC | D27: 37679 | E27: 54.57 | F27: 91.7 | G27: 54.564543 | H27: 91.70917 | I27: 4.6807257 | J27: 0.67544695 | K27: -0.18325087 | L27: 0.073658336 | M27: SHORT | N27: 22 | O27: signal | P27: 37701 | Q27: 54.75 | R27: 92.075 | S27: 0.41292147 | T27: -0.0053632805 | U27: -0.0087202351 | V27: 0.003350829 | W27: -0.012071064 | X27: =WORKDAY(DATE(2025,8,2),INT(D27/390)) -> 46006 | Y27: =WORKDAY(DATE(2025,8,2),INT(P27/390)) -> 46006 | AB27: 45873.58 | AC27: 25 | AE27: =IF(ISNUMBER(AF27),DATE(YEAR(AF27),DAY(AF27),MONTH(AF27)),DATE(RIGHT(AF27,4),LEFT(AF27,2),MID(AF27,4,2))) -> 45905 | AF27: 45786 | AG27: 15.18
A28: 3 | B28: BAC | C28: WFC | D28: 38190 | E28: 55.87 | F28: 94.01 | G28: 55.864413 | H28: 94.019401 | I28: 3.6342178 | J28: 0.67544695 | K28: -0.17898693 | L28: 0.071848415 | M28: SHORT | N28: 16 | O28: signal | P28: 38206 | Q28: 55.915 | R28: 94.115 | S28: 0.48719907 | T28: -0.0005103285 | U28: -0.0038627822 | V28: 0.003350829 | W28: -0.0072136112 | X28: =WORKDAY(DATE(2025,8,2),INT(D28/390)) -> 46007 | Y28: =WORKDAY(DATE(2025,8,2),INT(P28/390)) -> 46007 | AB28: 45873.581 | AC28: 26 | AE28: =IF(ISNUMBER(AF28),DATE(YEAR(AF28),DAY(AF28),MONTH(AF28)),DATE(RIGHT(AF28,4),LEFT(AF28,2),MID(AF28,4,2))) -> 45908 | AF28: 45878 | AG28: 15.11
A29: 3 | B29: BAC | C29: WFC | D29: 38306 | E29: 55.98 | F29: 93.99 | G29: 55.985598 | H29: 93.980601 | I29: -4.0638487 | J29: 0.67544695 | K29: 0.17863523 | L29: -0.071863703 | M29: LONG | N29: 27 | O29: signal | P29: 38333 | Q29: 55.955 | R29: 93.96 | S29: 0.017472686 | T29: -0.0023099696 | U29: -0.0056602013 | V29: 0.0033509588 | W29: -0.0090111601 | X29: =WORKDAY(DATE(2025,8,2),INT(D29/390)) -> 46008 | Y29: =WORKDAY(DATE(2025,8,2),INT(P29/390)) -> 46008 | AB29: 45873.581 | AC29: 27 | AE29: =IF(ISNUMBER(AF29),DATE(YEAR(AF29),DAY(AF29),MONTH(AF29)),DATE(RIGHT(AF29,4),LEFT(AF29,2),MID(AF29,4,2))) -> 45909 | AF29: 45909 | AG29: 15.04
A30: 3 | B30: BAC | C30: WFC | D30: 38659 | E30: 55.95 | F30: 94.22 | G30: 55.955595 | H30: 94.210578 | I30: -3.6283825 | J30: 0.67544695 | K30: 0.17873101 | L30: -0.071688277 | M30: LONG | N30: 15 | O30: signal | P30: 38674 | Q30: 56.025 | R30: 94.29 | S30: 0.17646003 | T30: 0.0083866464 | U30: 0.0050339102 | V30: 0.0033509588 | W30: 0.0016829514 | X30: =WORKDAY(DATE(2025,8,2),INT(D30/390)) -> 46009 | Y30: =WORKDAY(DATE(2025,8,2),INT(P30/390)) -> 46009 | AB30: 45873.582 | AC30: 28 | AE30: =IF(ISNUMBER(AF30),DATE(YEAR(AF30),DAY(AF30),MONTH(AF30)),DATE(RIGHT(AF30,4),LEFT(AF30,2),MID(AF30,4,2))) -> 45910 | AF30: 45939 | AG30: 15.35
A31: 3 | B31: BAC | C31: WFC | D31: 39059 | E31: 56.42 | F31: 95.27 | G31: 56.414358 | H31: 95.279527 | I31: 3.7111055 | J31: 0.67544695 | K31: -0.17724211 | L31: 0.070898178 | M31: SHORT | N31: 9 | O31: signal | P31: 39068 | Q31: 56.34 | R31: 95.295 | S31: 0.16521923 | T31: 0.015951823 | U31: 0.01260217 | V31: 0.003350829 | W31: 0.0092513413 | X31: =WORKDAY(DATE(2025,8,2),INT(D31/390)) -> 46010 | Y31: =WORKDAY(DATE(2025,8,2),INT(P31/390)) -> 46010 | AB31: 45873.583 | AC31: 29 | AE31: =IF(ISNUMBER(AF31),DATE(YEAR(AF31),DAY(AF31),MONTH(AF31)),DATE(RIGHT(AF31,4),LEFT(AF31,2),MID(AF31,4,2))) -> 45911 | AF31: 45970 | AG31: 14.71
A32: 3 | B32: BAC | C32: WFC | D32: 39449 | E32: 56.095 | F32: 95.37 | G32: 56.100609 | H32: 95.360463 | I32: -3.6509999 | J32: 0.67544695 | K32: 0.17826901 | L32: -0.070823838 | M32: LONG | N32: 23 | O32: signal | P32: 39472 | Q32: 55.91 | R32: 94.92 | S32: -0.48824636 | T32: -0.0011090393 | U32: -0.0044534481 | V32: 0.0033509588 | W32: -0.0078044069 | X32: =WORKDAY(DATE(2025,8,2),INT(D32/390)) -> 46013 | Y32: =WORKDAY(DATE(2025,8,2),INT(P32/390)) -> 46013 | AB32: 45873.583 | AC32: 30 | AE32: =IF(ISNUMBER(AF32),DATE(YEAR(AF32),DAY(AF32),MONTH(AF32)),DATE(RIGHT(AF32,4),LEFT(AF32,2),MID(AF32,4,2))) -> 45912 | AF32: 46000 | AG32: 14.76
A33: 4 | B33: BAC | C33: WFC | D33: 39839 | E33: 55.6 | F33: 94.82 | G33: 55.59444 | H33: 94.829482 | I33: 5.0316061 | J33: 0.65333461 | K33: -0.17985612 | L33: 0.068902616 | M33: SHORT | N33: 15 | O33: signal | P33: 39854 | Q33: 55.325 | R33: 94.34 | S33: -0.086236821 | T33: 0.016387176 | U33: 0.01308876 | V33: 0.0033065999 | W33: 0.0097821602 | X33: =WORKDAY(DATE(2025,8,2),INT(D33/390)) -> 46014 | Y33: =WORKDAY(DATE(2025,8,2),INT(P33/390)) -> 46014 | AB33: 45873.584 | AC33: 31 | AE33: =IF(ISNUMBER(AF33),DATE(YEAR(AF33),DAY(AF33),MONTH(AF33)),DATE(RIGHT(AF33,4),LEFT(AF33,2),MID(AF33,4,2))) -> 45915 | AF33: 09/15/2025 | AG33: 15.69
A34: 4 | B34: BAC | C34: WFC | D34: 41009 | E34: 56.28 | F34: 95.5 | G34: 56.274372 | H34: 95.50955 | I34: 5.0228281 | J34: 0.65333461 | K34: -0.17768301 | L34: 0.068412001 | M34: SHORT | N34: 27 | O34: signal | P34: 41036 | Q34: 57.19 | R34: 96.84 | S34: 0.39209777 | T34: -0.070019462 | U34: -0.073351467 | V34: 0.0033065999 | W34: -0.076658067 | X34: =WORKDAY(DATE(2025,8,2),INT(D34/390)) -> 46017 | Y34: =WORKDAY(DATE(2025,8,2),INT(P34/390)) -> 46017 | AB34: 45873.585 | AC34: 32 | AE34: =IF(ISNUMBER(AF34),DATE(YEAR(AF34),DAY(AF34),MONTH(AF34)),DATE(RIGHT(AF34,4),LEFT(AF34,2),MID(AF34,4,2))) -> 45916 | AF34: 09/16/2025 | AG34: 16.36
A35: 4 | B35: BAC | C35: WFC | D35: 41201 | E35: 57.27 | F35: 97.02 | G35: 57.264273 | H35: 97.029702 | I35: 3.6553078 | J35: 0.65333461 | K35: -0.17461149 | L35: 0.067340198 | M35: SHORT | N35: 8 | O35: signal | P35: 41209 | Q35: 57.21 | R35: 97.1 | S35: 0.10476352 | T35: 0.015863905 | U35: 0.012557745 | V35: 0.0033065999 | W35: 0.0092511451 | X35: =WORKDAY(DATE(2025,8,2),INT(D35/390)) -> 46017 | Y35: =WORKDAY(DATE(2025,8,2),INT(P35/390)) -> 46017 | AB35: 45873.585 | AC35: 33 | AE35: =IF(ISNUMBER(AF35),DATE(YEAR(AF35),DAY(AF35),MONTH(AF35)),DATE(RIGHT(AF35,4),LEFT(AF35,2),MID(AF35,4,2))) -> 45917 | AF35: 09/17/2025 | AG35: 15.72
A36: 4 | B36: BAC | C36: WFC | D36: 41399 | E36: 57.19 | F36: 95.59 | G36: 57.184281 | H36: 95.599559 | I36: 5.0111564 | J36: 0.65333461 | K36: -0.17485574 | L36: 0.068347589 | M36: SHORT | N36: 15 | O36: signal | P36: 41414 | Q36: 56.91 | R36: 95.525 | S36: 0.46103593 | T36: 0.044517015 | U36: 0.041215686 | V36: 0.0033065999 | W36: 0.037909086 | X36: =WORKDAY(DATE(2025,8,2),INT(D36/390)) -> 46020 | Y36: =WORKDAY(DATE(2025,8,2),INT(P36/390)) -> 46020 | AB36: 45873.586 | AC36: 34 | AE36: =IF(ISNUMBER(AF36),DATE(YEAR(AF36),DAY(AF36),MONTH(AF36)),DATE(RIGHT(AF36,4),LEFT(AF36,2),MID(AF36,4,2))) -> 45918 | AF36: 09/18/2025 | AG36: 15.7
A37: 4 | B37: BAC | C37: WFC | D37: 41790 | E37: 56.665 | F37: 95.725 | G37: 56.670667 | H37: 95.715427 | I37: -4.5347559 | J37: 0.65333461 | K37: 0.17647578 | L37: -0.068251199 | M37: LONG | N37: 35 | O37: signal | P37: 41825 | Q37: 56.145 | R37: 94.71 | S37: -0.064708702 | T37: -0.022492438 | U37: -0.025783003 | V37: 0.0033067385 | W37: -0.029089741 | X37: =WORKDAY(DATE(2025,8,2),INT(D37/390)) -> 46021 | Y37: =WORKDAY(DATE(2025,8,2),INT(P37/390)) -> 46021 | AB37: 45873.587 | AC37: 35 | AE37: =IF(ISNUMBER(AF37),DATE(YEAR(AF37),DAY(AF37),MONTH(AF37)),DATE(RIGHT(AF37,4),LEFT(AF37,2),MID(AF37,4,2))) -> 45919 | AF37: 09/19/2025 | AG37: 15.45
A38: 4 | B38: BAC | C38: WFC | D38: 42180 | E38: 55.58 | F38: 94.41 | G38: 55.585558 | H38: 94.400559 | I38: -4.0714174 | J38: 0.65333461 | K38: 0.17992083 | L38: -0.069201844 | M38: LONG | N38: 1 | O38: signal | P38: 42181 | Q38: 55.77 | R38: 94.43 | S38: 0.11846267 | T38: 0.032800922 | U38: 0.029490696 | V38: 0.0033067385 | W38: 0.026183957 | X38: =WORKDAY(DATE(2025,8,2),INT(D38/390)) -> 46022 | Y38: =WORKDAY(DATE(2025,8,2),INT(P38/390)) -> 46022 | AB38: 45873.588 | AC38: 36 | AE38: =IF(ISNUMBER(AF38),DATE(YEAR(AF38),DAY(AF38),MONTH(AF38)),DATE(RIGHT(AF38,4),LEFT(AF38,2),MID(AF38,4,2))) -> 45922 | AF38: 09/22/2025 | AG38: 16.1
A39: 4 | B39: BAC | C39: WFC | D39: 43332 | E39: 55.17 | F39: 94.905 | G39: 55.164483 | H39: 94.91449 | I39: 3.7294972 | J39: 0.65333461 | K39: -0.18125793 | L39: 0.068840905 | M39: SHORT | N39: 6 | O39: signal | P39: 43338 | Q39: 55.115 | R39: 94.925 | S39: 0.19387848 | T39: 0.011346004 | U39: 0.0080401943 | V39: 0.0033065999 | W39: 0.0047335944 | X39: =WORKDAY(DATE(2025,8,2),INT(D39/390)) -> 46027 | Y39: =WORKDAY(DATE(2025,8,2),INT(P39/390)) -> 46027 | AB39: 45873.588 | AC39: 37 | AE39: =IF(ISNUMBER(AF39),DATE(YEAR(AF39),DAY(AF39),MONTH(AF39)),DATE(RIGHT(AF39,4),LEFT(AF39,2),MID(AF39,4,2))) -> 45923 | AF39: 09/23/2025 | AG39: 16.64
A40: 5 | B40: BAC | C40: WFC | D40: 44003 | E40: 52.16 | F40: 88.9 | G40: 52.154784 | H40: 88.90889 | I40: 3.5004358 | J40: 0.60699764 | K40: -0.19171779 | L40: 0.068278699 | M40: SHORT | N40: 21 | O40: signal | P40: 44024 | Q40: 52.29 | R40: 88.99 | S40: 0.49471769 | T40: -0.01877823 | U40: -0.021995332 | V40: 0.0032139167 | W40: -0.025209249 | X40: =WORKDAY(DATE(2025,8,2),INT(D40/390)) -> 46028 | Y40: =WORKDAY(DATE(2025,8,2),INT(P40/390)) -> 46028 | AB40: 45873.589 | AC40: 38 | AE40: =IF(ISNUMBER(AF40),DATE(YEAR(AF40),DAY(AF40),MONTH(AF40)),DATE(RIGHT(AF40,4),LEFT(AF40,2),MID(AF40,4,2))) -> 45924 | AF40: 09/24/2025 | AG40: 16.18
...

Sheet capital utilisation
B2: only 2% of time are we holding any position

Sheet Analysis
L1: Exit timestamp | M1: Cumulative Gross PnL | N1: Cumulative Slipped PnL | O1: Cumulative Net PnL | Q1: min holding minutes | R1: max holding minutes | S1: Mean Net PnL | T1: Number of trades
B2: Rough Analysis of the baseline strategy | J2: Figures | L2: =Trades!P2 -> 24214 | M2: =Trades!T2 -> 0.024154984 | N2: =Trades!U2 -> 0.020822539 | O2: =Trades!W2 -> 0.017487745 | Q2: 0 | R2: 3 | S2: =AVERAGEIFS(Trades!W:W,Trades!N:N,">="&Q2,Trades!N:N,"<="&R2) -> 0.028497814 | T2: =COUNTIFS(Trades!N:N,">="&Q2,Trades!N:N,"<="&R2) -> 11
L3: =Trades!P3 -> 24606 | M3: =M2+Trades!T3 -> 0.067822224 | N3: =N2+Trades!U3 -> 0.061157159 | O3: =O2+Trades!W3 -> 0.054487572 | Q3: 4 | R3: 7 | S3: =AVERAGEIFS(Trades!W:W,Trades!N:N,">="&Q3,Trades!N:N,"<="&R3) -> 0.024845937 | T3: =COUNTIFS(Trades!N:N,">="&Q3,Trades!N:N,"<="&R3) -> 25
B4: Column1 | C4: Gross | D4: Slipped | E4: Net (Transaction costs) | L4: =Trades!P4 -> 24848 | M4: =M3+Trades!T4 -> 0.072054022 | N4: =N3+Trades!U4 -> 0.062055967 | O4: =O3+Trades!W4 -> 0.052051586 | Q4: 8 | R4: 11 | S4: =AVERAGEIFS(Trades!W:W,Trades!N:N,">="&Q4,Trades!N:N,"<="&R4) -> 0.022591354 | T4: =COUNTIFS(Trades!N:N,">="&Q4,Trades!N:N,"<="&R4) -> 21
B5: Overall PnL | C5: =SUM(Trades!T2:T9652) -> 1.6777784 | D5: =SUM(Trades!U2:U9652) -> 1.1888885 | E5: =SUM(Trades!W2:W9652) -> 0.70017553 | L5: =Trades!P5 -> 24996 | M5: =M4+Trades!T5 -> 0.10989766 | N5: =N4+Trades!U5 -> 0.096564379 | O5: =O4+Trades!W5 -> 0.083225071 | Q5: 12 | R5: 15 | S5: =AVERAGEIFS(Trades!W:W,Trades!N:N,">="&Q5,Trades!N:N,"<="&R5) -> 0.014078891 | T5: =COUNTIFS(Trades!N:N,">="&Q5,Trades!N:N,"<="&R5) -> 20
B6: Mean PnL | C6: =AVERAGE(Trades!T:T) -> 0.012710442 | D6: =AVERAGE(Trades!U:U) -> 0.0090067312 | E6: =AVERAGE(Trades!W:W) -> 0.0053043601 | L6: =Trades!P6 -> 25392 | M6: =M5+Trades!T6 -> 0.14071719 | N6: =N5+Trades!U6 -> 0.12404061 | O6: =O5+Trades!W6 -> 0.10736638 | Q6: 16 | R6: 19 | S6: =AVERAGEIFS(Trades!W:W,Trades!N:N,">="&Q6,Trades!N:N,"<="&R6) -> -0.0045318448 | T6: =COUNTIFS(Trades!N:N,">="&Q6,Trades!N:N,"<="&R6) -> 16
B7: Median PnL | C7: =MEDIAN(Trades!T:T) -> 0.0161695 | D7: =MEDIAN(Trades!U:U) -> 0.012618928 | E7: =MEDIAN(Trades!W:W) -> 0.0091126223 | L7: =Trades!P7 -> 25731 | M7: =M6+Trades!T7 -> 0.12499991 | N7: =N6+Trades!U7 -> 0.10498528 | O7: =O6+Trades!W7 -> 0.084976254 | Q7: 20 | R7: 23 | S7: =AVERAGEIFS(Trades!W:W,Trades!N:N,">="&Q7,Trades!N:N,"<="&R7) -> -0.014353217 | T7: =COUNTIFS(Trades!N:N,">="&Q7,Trades!N:N,"<="&R7) -> 11
B8: Max drawdown | C8: =MIN(Trades!T:T) -> -0.087068107 | D8: =MIN(Trades!U:U) -> -0.091191822 | E8: =MIN(Trades!W:W) -> -0.095289891 | L8: =Trades!P8 -> 25758 | M8: =M7+Trades!T8 -> 0.13581127 | N8: =N7+Trades!U8 -> 0.11246473 | O8: =O7+Trades!W8 -> 0.089120912 | Q8: 24 | R8: 27 | S8: =AVERAGEIFS(Trades!W:W,Trades!N:N,">="&Q8,Trades!N:N,"<="&R8) -> -0.023937849 | T8: =COUNTIFS(Trades!N:N,">="&Q8,Trades!N:N,"<="&R8) -> 14
B9: Biggest Winner | C9: =MAX(Trades!T:T) -> 0.09558224 | D9: =MAX(Trades!U:U) -> 0.091738669 | E9: =MAX(Trades!W:W) -> 0.087869742 | L9: =Trades!P9 -> 26942 | M9: =M8+Trades!T9 -> 0.16614087 | N9: =N8+Trades!U9 -> 0.13944671 | O9: =O8+Trades!W9 -> 0.11276796 | Q9: 28 | R9: 34 | S9: =AVERAGEIFS(Trades!W:W,Trades!N:N,">="&Q9,Trades!N:N,"<="&R9) -> -0.016174126 | T9: =COUNTIFS(Trades!N:N,">="&Q9,Trades!N:N,"<="&R9) -> 8
B10: Win rate | C10: =COUNTIF(Trades!T:T,">0")/(COUNTIF(Trades!T:T,">0")+COUNTIF(Trades!T:T,"<0")) -> 0.74242424 | D10: =COUNTIF(Trades!U:U,">0")/(COUNTIF(Trades!U:U,">0")+COUNTIF(Trades!U:U,"<0")) -> 0.68939394 | E10: =COUNTIF(Trades!W:W,">0")/(COUNTIF(Trades!W:W,">0")+COUNTIF(Trades!W:W,"<0")) -> 0.65151515 | L10: =Trades!P10 -> 27332 | M10: =M9+Trades!T10 -> 0.19014346 | N10: =N9+Trades!U10 -> 0.1601233 | O10: =O9+Trades!W10 -> 0.13010976 | Q10: 35 | R10: 40 | S10: =AVERAGEIFS(Trades!W:W,Trades!N:N,">="&Q10,Trades!N:N,"<="&R10) -> -0.045173001 | T10: =COUNTIFS(Trades!N:N,">="&Q10,Trades!N:N,"<="&R10) -> 4
B11: Profit Factor | C11: =SUMIF(Trades!T:T,">0",Trades!T:T)/ABS(SUMIF(Trades!T:T,"<0",Trades!T:T)) -> 2.7198882 | D11: =SUMIF(Trades!U:U,">0",Trades!U:U)/ABS(SUMIF(Trades!U:U,"<0",Trades!U:U)) -> 2.0670501 | E11: =SUMIF(Trades!W:W,">0",Trades!W:W)/ABS(SUMIF(Trades!W:W,"<0",Trades!W:W)) -> 1.5483743 | L11: =Trades!P11 -> 27725 | M11: =M9+Trades!T11 -> 0.1839358 | N11: =N9+Trades!U11 -> 0.15388456 | O11: =O9+Trades!W11 -> 0.12387088
L12: =Trades!P12 -> 28504 | M12: =M11+Trades!T12 -> 0.22037352 | N12: =N11+Trades!U12 -> 0.18701962 | O12: =O11+Trades!W12 -> 0.15369821 | Q12: 41 | R12: 47 | S12: =AVERAGEIFS(Trades!W:W,Trades!N:N,">="&Q12,Trades!N:N,"<="&R12) -> -0.032076202 | T12: =COUNTIFS(Trades!N:N,">="&Q12,Trades!N:N,"<="&R12) -> 1
B13: Column1 | C13: Column2 | L13: =Trades!P20 -> 32218 | M13: =M12+Trades!T20 -> 0.24252519 | N13: =N12+Trades!U20 -> 0.20569578 | O13: =O12+Trades!W20 -> 0.16889716
B14: Number of Trades | C14: =COUNTA(Trades!A:A)-1 -> 132 | L14: =Trades!P13 -> 28639 | M14: =M13+Trades!T13 -> 0.27504551 | N14: =N13+Trades!U13 -> 0.23490715 | O14: =O13+Trades!W13 -> 0.19480065
B15: Mean holding time | C15: =AVERAGE(Trades!N:N) -> 14.909091 | L15: =Trades!P21 -> 32631 | M15: =M14+Trades!T21 -> 0.2861718 | N15: =N14+Trades!U21 -> 0.24256171 | O15: =O14+Trades!W21 -> 0.19897799
B16: Median holding time | C16: =MEDIAN(Trades!N:N) -> 13 | L16: =Trades!P22 -> 33015 | M16: =M15+Trades!T22 -> 0.28845596 | N16: =N15+Trades!U22 -> 0.24136004 | O16: =O15+Trades!W22 -> 0.19429921
B17: Max holding time | C17: =MAX(Trades!N:N) -> 48 | L17: =Trades!P23 -> 34564 | M17: =M16+Trades!T23 -> 0.32044895 | N17: =N16+Trades!U23 -> 0.26987915 | O17: =O16+Trades!W23 -> 0.2193412
L18: =Trades!P14 -> 28735 | M18: =M17+Trades!T14 -> 0.31659487 | N18: =N17+Trades!U14 -> 0.26271845 | O18: =O17+Trades!W14 -> 0.20887263
B19: Column1 | C19: Positive | D19: Negative | L19: =Trades!P15 -> 29599 | M19: =M18+Trades!T15 -> 0.34331243 | N19: =N18+Trades!U15 -> 0.28613087 | O19: =O18+Trades!W15 -> 0.22897731
B20: Mean entry z score | C20: =AVERAGEIF(Trades!I:I,">0",Trades!I:I) -> 3.9561553 | D20: =AVERAGEIF(Trades!I:I,"<0",Trades!I:I) -> -3.9684066 | L20: =Trades!P24 -> 35310 | M20: =M19+Trades!T24 -> 0.40384151 | N20: =N19+Trades!U24 -> 0.34317567 | O20: =O19+Trades!W24 -> 0.2825449
B21: Median entry z score | C21: {=MEDIAN(_xlfn._xlws.FILTER(Trades!I:I,Trades!I:I>0))} -> 3.8036455 | D21: {=MEDIAN(_xlfn._xlws.FILTER(Trades!I:I,Trades!I:I<0))} -> -3.842663 | L21: =Trades!P25 -> 36516 | M21: =M20+Trades!T25 -> 0.47932709 | N21: =N20+Trades!U25 -> 0.4153039 | O21: =O20+Trades!W25 -> 0.35132217
B22: max entry z score | C22: =_xlfn.MAXIFS(Trades!I:I,Trades!I:I,">0") -> 5.0316061 | D22: =_xlfn.MINIFS(Trades!I:I,Trades!I:I,"<0") -> -4.9584327 | L22: =Trades!P16 -> 29691 | M22: =M21+Trades!T16 -> 0.45336904 | N22: =N21+Trades!U16 -> 0.3860304 | O22: =O21+Trades!W16 -> 0.31874093
B23: Mean exit z score | C23: =AVERAGEIF(Trades!S:S,">0",Trades!S:S) -> 0.25490692 | D23: =AVERAGEIF(Trades!S:S,"<0",Trades!S:S) -> -0.29230905 | L23: =Trades!P26 -> 37315 | M23: =M22+Trades!T26 -> 0.50270533 | N23: =N22+Trades!U26 -> 0.43200223 | O23: =O22+Trades!W26 -> 0.3613618
B24: Median exit z score | C24: {=MEDIAN(_xlfn._xlws.FILTER(Trades!S:S,Trades!S:S>0))} -> 0.26064238 | D24: {=MEDIAN(_xlfn._xlws.FILTER(Trades!S:S,Trades!S:S<0))} -> -0.30297441 | L24: =Trades!P27 -> 37701 | M24: =M23+Trades!T27 -> 0.49734205 | N24: =N23+Trades!U27 -> 0.42328199 | O24: =O23+Trades!W27 -> 0.34929073
B25: max exit z score | C25: =_xlfn.MAXIFS(Trades!S:S,Trades!S:S,">0") -> 0.49471769 | D25: =_xlfn.MINIFS(Trades!S:S,Trades!S:S,"<0") -> -0.49528239 | L25: =Trades!P17 -> 30065 | M25: =M24+Trades!T17 -> 0.52951182 | N25: =N24+Trades!U17 -> 0.4521378 | O25: =O24+Trades!W17 -> 0.37483867
G26: 1 | H26: Edge is there, but wiped out by costs | L26: =Trades!P18 -> 31227 | M26: =M25+Trades!T18 -> 0.55117499 | N26: =N25+Trades!U18 -> 0.47048627 | O26: =O25+Trades!W18 -> 0.38987926
B27: Column1 | C27: Long | D27: Short | E27: Signal | F27: Forced | L27: =Trades!P19 -> 32055 | M27: =M26+Trades!T19 -> 0.47538483 | N27: =N26+Trades!U19 -> 0.39120428 | O27: =O26+Trades!W19 -> 0.30712016
B28: PnL (gross) | C28: =SUMIF(Trades!M:M,"LONG",Trades!T:T) -> 0.97162033 | D28: =SUMIF(Trades!M:M,"SHORT",Trades!T:T) -> 0.70615807 | E28: =SUMIF(Trades!O:O,"Signal",Trades!T:T) -> 1.6777784 | F28: =SUMIF(Trades!O:O,"Forced",Trades!T:T) -> 0 | L28: =Trades!P28 -> 38206 | M28: =M27+Trades!T28 -> 0.4748745 | N28: =N27+Trades!U28 -> 0.38734149 | O28: =O27+Trades!W28 -> 0.29990654
B29: Number | C29: =COUNTIF(Trades!M:M,"LONG") -> 59 | D29: =COUNTIF(Trades!M:M,"SHORT") -> 73 | E29: =COUNTIF(Trades!O:O,"Signal") -> 132 | F29: =COUNTIF(Trades!O:O,"Forced") -> 0 | L29: =Trades!P35 -> 41209 | M29: =M28+Trades!T35 -> 0.49073841 | N29: =N28+Trades!U35 -> 0.39989924 | O29: =O28+Trades!W35 -> 0.30915769
L30: =Trades!P44 -> 45725 | M30: =M29+Trades!T44 -> 0.52559472 | N30: =N29+Trades!U44 -> 0.43153142 | O30: =O29+Trades!W44 -> 0.33757596
B31: min Holding time | C31: Max Holding time | D31: Win rate | L31: =Trades!P52 -> 49254 | M31: =M30+Trades!T52 -> 0.46916174 | N31: =N30+Trades!U52 -> 0.37099936 | O31: =O30+Trades!W52 -> 0.27294585
B32: 0 | C32: 3 | D32: =COUNTIFS(Trades!N:N,">="&B32,Trades!N:N,"<="&C32,Trades!T:T,">0")/(COUNTIFS(Trades!N:N,">="&B32,Trades!N:N,"<="&C32,Trades!T:T,">0")+COUNTIFS(Trades!N:N,">="&B32,Trades!N:N,"<="&C32,Trades!T:T,"<0")) -> 1 | L32: =Trades!P36 -> 41414 | M32: =M31+Trades!T36 -> 0.51367876 | N32: =N31+Trades!U36 -> 0.41221505 | O32: =O31+Trades!W36 -> 0.31085493
B33: 4 | C33: 7 | D33: =COUNTIFS(Trades!N:N,">="&B33,Trades!N:N,"<="&C33,Trades!T:T,">0")/(COUNTIFS(Trades!N:N,">="&B33,Trades!N:N,"<="&C33,Trades!T:T,">0")+COUNTIFS(Trades!N:N,">="&B33,Trades!N:N,"<="&C33,Trades!T:T,"<0")) -> 1 | L33: =Trades!P45 -> 45815 | M33: =M32+Trades!T45 -> 0.52546273 | N33: =N32+Trades!U45 -> 0.42078442 | O33: =O32+Trades!W45 -> 0.31621039
B34: 8 | C34: 11 | D34: =COUNTIFS(Trades!N:N,">="&B34,Trades!N:N,"<="&C34,Trades!T:T,">0")/(COUNTIFS(Trades!N:N,">="&B34,Trades!N:N,"<="&C34,Trades!T:T,">0")+COUNTIFS(Trades!N:N,">="&B34,Trades!N:N,"<="&C34,Trades!T:T,"<0")) -> 1 | L34: =Trades!P29 -> 38333 | M34: =M33+Trades!T29 -> 0.52315276 | N34: =N33+Trades!U29 -> 0.41512422 | O34: =O33+Trades!W29 -> 0.30719923
B35: 12 | C35: 15 | D35: =COUNTIFS(Trades!N:N,">="&B35,Trades!N:N,"<="&C35,Trades!T:T,">0")/(COUNTIFS(Trades!N:N,">="&B35,Trades!N:N,"<="&C35,Trades!T:T,">0")+COUNTIFS(Trades!N:N,">="&B35,Trades!N:N,"<="&C35,Trades!T:T,"<0")) -> 0.95 | L35: =Trades!P30 -> 38674 | M35: =M34+Trades!T30 -> 0.53153941 | N35: =N34+Trades!U30 -> 0.42015813 | O35: =O34+Trades!W30 -> 0.30888218
B36: 16 | C36: 1000000 | D36: =COUNTIFS(Trades!N:N,">="&B36,Trades!N:N,"<="&C36,Trades!T:T,">0")/(COUNTIFS(Trades!N:N,">="&B36,Trades!N:N,"<="&C36,Trades!T:T,">0")+COUNTIFS(Trades!N:N,">="&B36,Trades!N:N,"<="&C36,Trades!T:T,"<0")) -> 0.4 | L36: =Trades!P37 -> 41825 | M36: =M35+Trades!T37 -> 0.50904697 | N36: =N35+Trades!U37 -> 0.39437512 | O36: =O35+Trades!W37 -> 0.27979244
L37: =Trades!P53 -> 49618 | M37: =M36+Trades!T53 -> 0.54804889 | N37: =N36+Trades!U53 -> 0.42928753 | O37: =O36+Trades!W53 -> 0.31060679
L38: =Trades!P54 -> 50031 | M38: =M37+Trades!T54 -> 0.46098078 | N38: =N37+Trades!U54 -> 0.33809571 | O38: =O37+Trades!W54 -> 0.2153169
B39: Conclusion: | L39: =Trades!P31 -> 39068 | M39: =M38+Trades!T31 -> 0.47693261 | N39: =N38+Trades!U31 -> 0.35069788 | O39: =O38+Trades!W31 -> 0.22456824
B40: does the multiple pairs strategy improve diversification and risk adjusted returns instead of just gross exposure? | L40: =Trades!P32 -> 39472 | M40: =M39+Trades!T32 -> 0.47582357 | N40: =N39+Trades!U32 -> 0.34624443 | O40: =O39+Trades!W32 -> 0.21676384
...

Sheet comparison with single pair
B2: Metric | C2: Value | J2: Daily PnL table
B3: Net P&L | C3: =SUM(Trades!W2:W9652) -> 0.70017553
B4: Number of trades | C4: =COUNTA(Trades!A:A)-1 -> 132 | J4: {=_xlfn.LET( _xlpm.dates,_xlfn.SEQUENCE(DATE(2026,8,2)-DATE(2025,8,2)+1,,DATE(2025,8,2)), _xlfn._xlws.FILTER(_xlpm.dates,WEEKDAY(_xlpm.dates,2)<=5) )} -> 45873 | K4: {=SUMIFS('trades edited'!$W$2:$W$100000,'trades edited'!$Y$2:$Y$100000,_xlfn.ANCHORARRAY(J4))} -> 0
B5: P&L/trade | C5: =AVERAGE(Trades!W:W) -> 0.0053043601 | J5: 45874 | K5: 0
B6: Daily P&L volatility | C6: =_xlfn.STDEV.S(_xlfn.ANCHORARRAY(K4)) -> 0.02256984 | J6: 45875 | K6: 0
B7: Sharpe-like measure | C7: =AVERAGE(_xlfn.ANCHORARRAY(K4))/_xlfn.STDEV.S(_xlfn.ANCHORARRAY(K4))*SQRT(252) -> 1.8941108 | J7: 45876 | K7: 0
B8: Max drawdown | C8: =MIN(Trades!W:W) -> -0.095289891 | J8: 45877 | K8: 0
B9: Max drawdown / total P&L | C9: =C8/C3 -> -0.13609429 | J9: 45880 | K9: 0
B10: Worst day | J10: 45881 | K10: 0
B11: Max concurrent positions | J11: 45882 | K11: 0
B12: Max gross exposure | J12: 45883 | K12: 0
J13: 45884 | K13: 0
J14: 45887 | K14: 0
J15: 45888 | K15: 0
B16: it seems like this strat might actually be WORSE for risk *potentially* than the single pair version. The main question now is how much capital we need to keep in reserves to avoid margin calling and liquidation. portfolio total P&L = cumulative realised P&L up to minute + total unrealised P&L at minute | J16: 45889 | K16: 0
J17: 45890 | K17: 0
J18: 45891 | K18: 0
J19: 45894 | K19: 0
J20: 45895 | K20: 0
J21: 45896 | K21: 0
J22: 45897 | K22: 0
J23: 45898 | K23: 0
J24: 45901 | K24: 0
J25: 45902 | K25: 0
J26: 45903 | K26: 0
J27: 45904 | K27: 0
J28: 45905 | K28: 0
... J263: 46234 | K263: 0
