Workbook

Sheet Trades
A1: window_id | B1: stock1 | C1: stock2 | D1: entry_timestamp | E1: entry_price_1 | F1: entry_price_2 | G1: entry_price_1_slipped | H1: entry_price_2_slipped | I1: entry_zscore | J1: hedge_ratio_entry | K1: position_size_1 | L1: position_size_2 | M1: direction | N1: holding_minutes | O1: exit_reason | P1: exit_timestamp | Q1: exit_price_1 | R1: exit_price_2 | S1: exit_zscore | T1: gross_pnl | U1: gross_pnl_slipped | V1: transaction_costs | W1: net_pnl
A2: 0 | B2: JPM | C2: GS | D2: 24207 | E2: 306.355 | F2: 782.975 | G2: 306.32436 | H2: 783.0533 | I2: 3.594531 | J2: 0.66743015 | K2: -0.03264187 | L2: 0.0085242843 | M2: SHORT | N2: 7 | O2: signal | P2: 24214 | Q2: 305.615 | R2: 782.975 | S2: 0.36824447 | T2: 0.024154984 | U2: 0.020822539 | V2: 0.0033347938 | W2: 0.017487745
A3: 0 | B3: JPM | C3: GS | D3: 24601 | E3: 310.255 | F3: 784.85 | G3: 310.22397 | H3: 784.92849 | I3: 3.7200374 | J3: 0.66743015 | K3: -0.032231551 | L3: 0.0085039198 | M3: SHORT | N3: 5 | O3: signal | P3: 24606 | Q3: 309.23 | R3: 786.1 | S3: 0.45860297 | T3: 0.04366724 | U3: 0.04033462 | V3: 0.0033347938 | W3: 0.036999827
A4: 0 | B4: JPM | C4: GS | D4: 24832 | E4: 309.67 | F4: 784.45 | G4: 309.63903 | H4: 784.52845 | I4: 3.979432 | J4: 0.66743015 | K4: -0.03229244 | L4: 0.0085082561 | M4: SHORT | N4: 16 | O4: signal | P4: 24848 | Q4: 309.315 | R4: 783.6 | S4: 0.38578157 | T4: 0.0042317987 | U4: 0.00089880794 | V4: 0.0033347938 | W4: -0.0024359858
A5: 0 | B5: JPM | C5: GS | D5: 24987 | E5: 310.945 | F5: 792.31 | G5: 310.97609 | H5: 792.23077 | I5: -4.4660855 | J5: 0.66743015 | K5: 0.032160028 | L5: -0.0084238511 | M5: LONG | N5: 9 | O5: signal | P5: 24996 | Q5: 311.59 | R5: 790.28 | S5: 0.2672345 | T5: 0.037843636 | U5: 0.034508411 | V5: 0.0033349268 | W5: 0.031173485
A6: 0 | B6: JPM | C6: GS | D6: 25380 | E6: 305.665 | F6: 775.68 | G6: 305.69557 | H6: 775.60243 | I6: -3.6905639 | J6: 0.66743015 | K6: 0.032715555 | L6: -0.0086044522 | M6: LONG | N6: 12 | O6: signal | P6: 25392 | Q6: 307.425 | R6: 778.79 | S6: 0.21702582 | T6: 0.03081953 | U6: 0.027476236 | V6: 0.0033349268 | W6: 0.024141309
A7: 0 | B7: JPM | C7: GS | D7: 25694 | E7: 308.605 | F7: 791.07 | G7: 308.57414 | H7: 791.14911 | I7: 3.6289486 | J7: 0.66743015 | K7: -0.032403882 | L7: 0.0084370555 | M7: SHORT | N7: 37 | O7: signal | P7: 25731 | Q7: 309.34 | R7: 792.03 | S7: 0.21396878 | T7: -0.01571728 | U7: -0.019055332 | V7: 0.0033347938 | W7: -0.022390126
A8: 0 | B8: JPM | C8: GS | D8: 25752 | E8: 310.22 | F8: 793.57 | G8: 310.18898 | H8: 793.64936 | I8: 3.587045 | J8: 0.66743015 | K8: -0.032235188 | L8: 0.0084104761 | M8: SHORT | N8: 6 | O8: signal | P8: 25758 | Q8: 309.595 | R8: 792.46 | S8: 0.10046321 | T8: 0.010811364 | U8: 0.007479452 | V8: 0.0033347938 | W8: 0.0041446582
A9: 0 | B9: JPM | C9: GS | D9: 26937 | E9: 316.57 | F9: 798.58 | G9: 316.60166 | H9: 798.50014 | I9: -3.6665215 | J9: 0.66743015 | K9: 0.03158859 | L9: -0.0083577118 | M9: LONG | N9: 5 | O9: signal | P9: 26942 | Q9: 319.07 | R9: 804.4 | S9: -0.22070535 | T9: 0.030329593 | U9: 0.026981971 | V9: 0.0033349268 | W9: 0.023647044
A10: 0 | B10: JPM | C10: GS | D10: 27327 | E10: 318.785 | F10: 801.62 | G10: 318.75312 | H10: 801.70016 | I10: 3.8655947 | J10: 0.66743015 | K10: -0.031369105 | L10: 0.0083260167 | M10: SHORT | N10: 5 | O10: signal | P10: 27332 | Q10: 316.99 | R10: 797.74 | S10: 0.091473395 | T10: 0.024002598 | U10: 0.020676599 | V10: 0.0033347938 | W10: 0.017341805
A11: 0 | B11: JPM | C11: GS | D11: 27717 | E11: 316.63 | F11: 816.83 | G11: 316.66166 | H11: 816.74832 | I11: -4.1191154 | J11: 0.66743015 | K11: 0.031582604 | L11: -0.0081709799 | M11: LONG | N11: 8 | O11: signal | P11: 27725 | Q11: 320.43 | R11: 829.34 | S11: -0.091250949 | T11: 0.017794938 | U11: 0.014437855 | V11: 0.0033349268 | W11: 0.011102928
A12: 1 | B12: JPM | C12: GS | D12: 27901 | E12: 321.49 | F12: 832.19 | G12: 321.45785 | H12: 832.27322 | I12: 5.2836493 | J12: 0.65390315 | K12: -0.031105167 | L12: 0.0078576185 | M12: SHORT | N12: 23 | O12: signal | P12: 27924 | Q12: 321.12 | R12: 832.625 | S12: 0.47150671 | T12: 0.014926976 | U12: 0.011619978 | V12: 0.0033077371 | W12: 0.0083122414
A13: 1 | B13: JPM | C13: GS | D13: 28497 | E13: 305.71 | F13: 787.29 | G13: 305.67943 | H13: 787.36873 | I13: 3.9612488 | J13: 0.65390315 | K13: -0.032710739 | L13: 0.0083057469 | M13: SHORT | N13: 7 | O13: signal | P13: 28504 | Q13: 304.365 | R13: 786.38 | S13: 0.030918091 | T13: 0.036437714 | U13: 0.033135063 | V13: 0.0033077371 | W13: 0.029827326
... A173: 16 | B173: BAC | C173: USB | D173: 90259 | E173: 59.24 | F173: 62.225 | G173: 59.234076 | H173: 62.231223 | I173: 3.938376 | J173: 1.2019117 | K173: -0.16880486 | L173: 0.19315576 | M173: SHORT | N173: 31 | O173: signal | P173: 90290 | Q173: 59.23 | R173: 61.88 | S173: 0.19335895 | T173: -0.06495069 | U173: -0.06934768 | V173: 0.0044038639 | W173: -0.073751544

Sheet trades edited
A1: window_id | B1: stock1 | C1: stock2 | D1: entry_timestamp | E1: entry_price_1 | F1: entry_price_2 | G1: entry_price_1_slipped | H1: entry_price_2_slipped | I1: entry_zscore | J1: hedge_ratio_entry | K1: position_size_1 | L1: position_size_2 | M1: direction | N1: holding_minutes | O1: exit_reason | P1: exit_timestamp | Q1: exit_price_1 | R1: exit_price_2 | S1: exit_zscore | T1: gross_pnl | U1: gross_pnl_slipped | V1: transaction_costs | W1: net_pnl | X1: Entry day | Y1: Exit Day | Z1: VIX on entry | AE1: UK Date | AF1: US DATE | AG1: VIX ON ENTRY
A2: 0 | B2: JPM | C2: GS | D2: 24207 | E2: 306.355 | F2: 782.975 | G2: 306.32436 | H2: 783.0533 | I2: 3.594531 | J2: 0.66743015 | K2: -0.03264187 | L2: 0.0085242843 | M2: SHORT | N2: 7 | O2: signal | P2: 24214 | Q2: 305.615 | R2: 782.975 | S2: 0.36824447 | T2: 0.024154984 | U2: 0.020822539 | V2: 0.0033347938 | W2: 0.017487745 | X2: =WORKDAY(DATE(2025,8,2),INT(D2/390)) -> 45958 | Y2: =WORKDAY(DATE(2025,8,2),INT(P2/390)) -> 45958 | Z2: {=_xlfn.XLOOKUP(INT(X2),INT($AE$2:$AE$1000),$AG$2:$AG$1000,"")} -> 16.42 | AE2: =IF(ISNUMBER(AF2),DATE(YEAR(AF2),DAY(AF2),MONTH(AF2)),DATE(RIGHT(AF2,4),LEFT(AF2,2),MID(AF2,4,2))) -> 45870 | AF2: 45665 | AG2: 20.38 | AJ2: VIX at entry | AK2: Net PnL | AL2: Trades | AM2: Avg Net P&L | AN2: Win rate
A3: 0 | B3: JPM | C3: GS | D3: 24601 | E3: 310.255 | F3: 784.85 | G3: 310.22397 | H3: 784.92849 | I3: 3.7200374 | J3: 0.66743015 | K3: -0.032231551 | L3: 0.0085039198 | M3: SHORT | N3: 5 | O3: signal | P3: 24606 | Q3: 309.23 | R3: 786.1 | S3: 0.45860297 | T3: 0.04366724 | U3: 0.04033462 | V3: 0.0033347938 | W3: 0.036999827 | X3: =WORKDAY(DATE(2025,8,2),INT(D3/390)) -> 45959 | Y3: =WORKDAY(DATE(2025,8,2),INT(P3/390)) -> 45959 | Z3: {=_xlfn.XLOOKUP(INT(X3),INT($AE$2:$AE$1000),$AG$2:$AG$1000,"")} -> 16.92 | AE3: =IF(ISNUMBER(AF3),DATE(YEAR(AF3),DAY(AF3),MONTH(AF3)),DATE(RIGHT(AF3,4),LEFT(AF3,2),MID(AF3,4,2))) -> 45873 | AF3: 45755 | AG3: 17.52 | AJ3: <15 | AK3: =AL3*AM3 -> 0.034883676 | AL3: =COUNTIF(Z:Z,"<15") -> 15 | AM3: =AVERAGEIF(Z:Z,"<15",W:W) -> 0.0023255784 | AN3: =COUNTIFS(Z:Z,"<15",T:T,">0")/COUNTIFS(Z:Z,"<15") -> 0.66666667
A4: 0 | B4: JPM | C4: GS | D4: 24832 | E4: 309.67 | F4: 784.45 | G4: 309.63903 | H4: 784.52845 | I4: 3.979432 | J4: 0.66743015 | K4: -0.03229244 | L4: 0.0085082561 | M4: SHORT | N4: 16 | O4: signal | P4: 24848 | Q4: 309.315 | R4: 783.6 | S4: 0.38578157 | T4: 0.0042317987 | U4: 0.00089880794 | V4: 0.0033347938 | W4: -0.0024359858 | X4: =WORKDAY(DATE(2025,8,2),INT(D4/390)) -> 45959 | Y4: =WORKDAY(DATE(2025,8,2),INT(P4/390)) -> 45959 | Z4: {=_xlfn.XLOOKUP(INT(X4),INT($AE$2:$AE$1000),$AG$2:$AG$1000,"")} -> 16.92 | AE4: =IF(ISNUMBER(AF4),DATE(YEAR(AF4),DAY(AF4),MONTH(AF4)),DATE(RIGHT(AF4,4),LEFT(AF4,2),MID(AF4,4,2))) -> 45874 | AF4: 45785 | AG4: 17.85 | AJ4: 15–20 | AK4: =AL4*AM4 -> 1.5033115 | AL4: =COUNTIFS(Z:Z,">=15",Z:Z,"<20") -> 108 | AM4: =AVERAGEIFS(W:W,Z:Z,">=15",Z:Z,"<20") -> 0.013919551 | AN4: =COUNTIFS(Z:Z,">=15",Z:Z,"<20",T:T,">0")/COUNTIFS(Z:Z,">=15",Z:Z,"<20") -> 0.75925926
A5: 0 | B5: JPM | C5: GS | D5: 24987 | E5: 310.945 | F5: 792.31 | G5: 310.97609 | H5: 792.23077 | I5: -4.4660855 | J5: 0.66743015 | K5: 0.032160028 | L5: -0.0084238511 | M5: LONG | N5: 9 | O5: signal | P5: 24996 | Q5: 311.59 | R5: 790.28 | S5: 0.2672345 | T5: 0.037843636 | U5: 0.034508411 | V5: 0.0033349268 | W5: 0.031173485 | X5: =WORKDAY(DATE(2025,8,2),INT(D5/390)) -> 45960 | Y5: =WORKDAY(DATE(2025,8,2),INT(P5/390)) -> 45960 | Z5: {=_xlfn.XLOOKUP(INT(X5),INT($AE$2:$AE$1000),$AG$2:$AG$1000,"")} -> 16.91 | AE5: =IF(ISNUMBER(AF5),DATE(YEAR(AF5),DAY(AF5),MONTH(AF5)),DATE(RIGHT(AF5,4),LEFT(AF5,2),MID(AF5,4,2))) -> 45875 | AF5: 45816 | AG5: 16.77 | AJ5: >=20 | AK5: =AL5*AM5 -> 0.60012575 | AL5: =COUNTIFS(Z:Z,">=20") -> 48 | AM5: =AVERAGEIFS(W:W,Z:Z,">=20") -> 0.01250262 | AN5: =COUNTIFS(Z:Z,">=20",T:T,">0")/COUNTIFS(Z:Z,">=20") -> 0.72916667
A6: 0 | B6: JPM | C6: GS | D6: 25380 | E6: 305.665 | F6: 775.68 | G6: 305.69557 | H6: 775.60243 | I6: -3.6905639 | J6: 0.66743015 | K6: 0.032715555 | L6: -0.0086044522 | M6: LONG | N6: 12 | O6: signal | P6: 25392 | Q6: 307.425 | R6: 778.79 | S6: 0.21702582 | T6: 0.03081953 | U6: 0.027476236 | V6: 0.0033349268 | W6: 0.024141309 | X6: =WORKDAY(DATE(2025,8,2),INT(D6/390)) -> 45961 | Y6: =WORKDAY(DATE(2025,8,2),INT(P6/390)) -> 45961 | Z6: {=_xlfn.XLOOKUP(INT(X6),INT($AE$2:$AE$1000),$AG$2:$AG$1000,"")} -> 17.44 | AE6: =IF(ISNUMBER(AF6),DATE(YEAR(AF6),DAY(AF6),MONTH(AF6)),DATE(RIGHT(AF6,4),LEFT(AF6,2),MID(AF6,4,2))) -> 45876 | AF6: 45846 | AG6: 16.57
A7: 0 | B7: JPM | C7: GS | D7: 25694 | E7: 308.605 | F7: 791.07 | G7: 308.57414 | H7: 791.14911 | I7: 3.6289486 | J7: 0.66743015 | K7: -0.032403882 | L7: 0.0084370555 | M7: SHORT | N7: 37 | O7: signal | P7: 25731 | Q7: 309.34 | R7: 792.03 | S7: 0.21396878 | T7: -0.01571728 | U7: -0.019055332 | V7: 0.0033347938 | W7: -0.022390126 | X7: =WORKDAY(DATE(2025,8,2),INT(D7/390)) -> 45961 | Y7: =WORKDAY(DATE(2025,8,2),INT(P7/390)) -> 45961 | Z7: {=_xlfn.XLOOKUP(INT(X7),INT($AE$2:$AE$1000),$AG$2:$AG$1000,"")} -> 17.44 | AE7: =IF(ISNUMBER(AF7),DATE(YEAR(AF7),DAY(AF7),MONTH(AF7)),DATE(RIGHT(AF7,4),LEFT(AF7,2),MID(AF7,4,2))) -> 45877 | AF7: 45877 | AG7: 15.15
A8: 0 | B8: JPM | C8: GS | D8: 25752 | E8: 310.22 | F8: 793.57 | G8: 310.18898 | H8: 793.64936 | I8: 3.587045 | J8: 0.66743015 | K8: -0.032235188 | L8: 0.0084104761 | M8: SHORT | N8: 6 | O8: signal | P8: 25758 | Q8: 309.595 | R8: 792.46 | S8: 0.10046321 | T8: 0.010811364 | U8: 0.007479452 | V8: 0.0033347938 | W8: 0.0041446582 | X8: =WORKDAY(DATE(2025,8,2),INT(D8/390)) -> 45964 | Y8: =WORKDAY(DATE(2025,8,2),INT(P8/390)) -> 45964 | Z8: {=_xlfn.XLOOKUP(INT(X8),INT($AE$2:$AE$1000),$AG$2:$AG$1000,"")} -> 17.17 | AE8: =IF(ISNUMBER(AF8),DATE(YEAR(AF8),DAY(AF8),MONTH(AF8)),DATE(RIGHT(AF8,4),LEFT(AF8,2),MID(AF8,4,2))) -> 45880 | AF8: 45969 | AG8: 16.25
A9: 0 | B9: JPM | C9: GS | D9: 26937 | E9: 316.57 | F9: 798.58 | G9: 316.60166 | H9: 798.50014 | I9: -3.6665215 | J9: 0.66743015 | K9: 0.03158859 | L9: -0.0083577118 | M9: LONG | N9: 5 | O9: signal | P9: 26942 | Q9: 319.07 | R9: 804.4 | S9: -0.22070535 | T9: 0.030329593 | U9: 0.026981971 | V9: 0.0033349268 | W9: 0.023647044 | X9: =WORKDAY(DATE(2025,8,2),INT(D9/390)) -> 45967 | Y9: =WORKDAY(DATE(2025,8,2),INT(P9/390)) -> 45967 | Z9: {=_xlfn.XLOOKUP(INT(X9),INT($AE$2:$AE$1000),$AG$2:$AG$1000,"")} -> 19.5 | AE9: =IF(ISNUMBER(AF9),DATE(YEAR(AF9),DAY(AF9),MONTH(AF9)),DATE(RIGHT(AF9,4),LEFT(AF9,2),MID(AF9,4,2))) -> 45881 | AF9: 45999 | AG9: 14.73
A10: 0 | B10: JPM | C10: GS | D10: 27327 | E10: 318.785 | F10: 801.62 | G10: 318.75312 | H10: 801.70016 | I10: 3.8655947 | J10: 0.66743015 | K10: -0.031369105 | L10: 0.0083260167 | M10: SHORT | N10: 5 | O10: signal | P10: 27332 | Q10: 316.99 | R10: 797.74 | S10: 0.091473395 | T10: 0.024002598 | U10: 0.020676599 | V10: 0.0033347938 | W10: 0.017341805 | X10: =WORKDAY(DATE(2025,8,2),INT(D10/390)) -> 45968 | Y10: =WORKDAY(DATE(2025,8,2),INT(P10/390)) -> 45968 | Z10: {=_xlfn.XLOOKUP(INT(X10),INT($AE$2:$AE$1000),$AG$2:$AG$1000,"")} -> 19.08 | AE10: =IF(ISNUMBER(AF10),DATE(YEAR(AF10),DAY(AF10),MONTH(AF10)),DATE(RIGHT(AF10,4),LEFT(AF10,2),MID(AF10,4,2))) -> 45882 | AF10: 08/13/2025 | AG10: 14.49 | AJ10: Metric | AK10: OOS H1 | AL10: OOS H2
A11: 0 | B11: JPM | C11: GS | D11: 27717 | E11: 316.63 | F11: 816.83 | G11: 316.66166 | H11: 816.74832 | I11: -4.1191154 | J11: 0.66743015 | K11: 0.031582604 | L11: -0.0081709799 | M11: LONG | N11: 8 | O11: signal | P11: 27725 | Q11: 320.43 | R11: 829.34 | S11: -0.091250949 | T11: 0.017794938 | U11: 0.014437855 | V11: 0.0033349268 | W11: 0.011102928 | X11: =WORKDAY(DATE(2025,8,2),INT(D11/390)) -> 45971 | Y11: =WORKDAY(DATE(2025,8,2),INT(P11/390)) -> 45971 | Z11: {=_xlfn.XLOOKUP(INT(X11),INT($AE$2:$AE$1000),$AG$2:$AG$1000,"")} -> 17.6 | AE11: =IF(ISNUMBER(AF11),DATE(YEAR(AF11),DAY(AF11),MONTH(AF11)),DATE(RIGHT(AF11,4),LEFT(AF11,2),MID(AF11,4,2))) -> 45883 | AF11: 08/14/2025 | AG11: 14.83 | AJ11: Trades | AK11: =COUNTIF(D:D,"<55503") -> 76 | AL11: =COUNTIF(D:D,">=55503") -> 96
A12: 1 | B12: JPM | C12: GS | D12: 27901 | E12: 321.49 | F12: 832.19 | G12: 321.45785 | H12: 832.27322 | I12: 5.2836493 | J12: 0.65390315 | K12: -0.031105167 | L12: 0.0078576185 | M12: SHORT | N12: 23 | O12: signal | P12: 27924 | Q12: 321.12 | R12: 832.625 | S12: 0.47150671 | T12: 0.014926976 | U12: 0.011619978 | V12: 0.0033077371 | W12: 0.0083122414 | X12: =WORKDAY(DATE(2025,8,2),INT(D12/390)) -> 45971 | Y12: =WORKDAY(DATE(2025,8,2),INT(P12/390)) -> 45971 | Z12: {=_xlfn.XLOOKUP(INT(X12),INT($AE$2:$AE$1000),$AG$2:$AG$1000,"")} -> 17.6 | AE12: =IF(ISNUMBER(AF12),DATE(YEAR(AF12),DAY(AF12),MONTH(AF12)),DATE(RIGHT(AF12,4),LEFT(AF12,2),MID(AF12,4,2))) -> 45884 | AF12: 08/15/2025 | AG12: 15.09 | AJ12: Gross P&L | AK12: =SUMIF(D:D,"<55503",T:T) -> 0.65726357 | AL12: =SUMIF(D:D,">=55503",T:T) -> 2.8359255
A13: 1 | B13: JPM | C13: GS | D13: 28497 | E13: 305.71 | F13: 787.29 | G13: 305.67943 | H13: 787.36873 | I13: 3.9612488 | J13: 0.65390315 | K13: -0.032710739 | L13: 0.0083057469 | M13: SHORT | N13: 7 | O13: signal | P13: 28504 | Q13: 304.365 | R13: 786.38 | S13: 0.030918091 | T13: 0.036437714 | U13: 0.033135063 | V13: 0.0033077371 | W13: 0.029827326 | X13: =WORKDAY(DATE(2025,8,2),INT(D13/390)) -> 45973 | Y13: =WORKDAY(DATE(2025,8,2),INT(P13/390)) -> 45973 | Z13: {=_xlfn.XLOOKUP(INT(X13),INT($AE$2:$AE$1000),$AG$2:$AG$1000,"")} -> 17.51 | AE13: =IF(ISNUMBER(AF13),DATE(YEAR(AF13),DAY(AF13),MONTH(AF13)),DATE(RIGHT(AF13,4),LEFT(AF13,2),MID(AF13,4,2))) -> 45887 | AF13: 08/18/2025 | AG13: 14.99 | AJ13: Net P&L | AK13: =SUMIF(D:D,"<55503",U:U) -> 0.38859164 | AL13: =SUMIF(D:D,">=55503",U:U) -> 2.4645231
A14: 1 | B14: JPM | C14: GS | D14: 28630 | E14: 304.8 | F14: 797.315 | G14: 304.83048 | H14: 797.23527 | I14: -3.6261084 | J14: 0.65390315 | K14: 0.032808399 | L14: -0.0082013151 | M14: LONG | N14: 9 | O14: signal | P14: 28639 | Q14: 305.47 | R14: 796.03 | S14: 0.26313253 | T14: 0.032520317 | U14: 0.029211367 | V14: 0.0033078755 | W14: 0.025903491 | X14: =WORKDAY(DATE(2025,8,2),INT(D14/390)) -> 45973 | Y14: =WORKDAY(DATE(2025,8,2),INT(P14/390)) -> 45973 | Z14: {=_xlfn.XLOOKUP(INT(X14),INT($AE$2:$AE$1000),$AG$2:$AG$1000,"")} -> 17.51 | AE14: =IF(ISNUMBER(AF14),DATE(YEAR(AF14),DAY(AF14),MONTH(AF14)),DATE(RIGHT(AF14,4),LEFT(AF14,2),MID(AF14,4,2))) -> 45888 | AF14: 08/19/2025 | AG14: 15.57 | AJ14: Avg gross P&L/trade | AK14: =AVERAGEIF(D:D,"<55503",T:T) -> 0.0086482048 | AL14: =AVERAGEIF(D:D,">=55503",T:T) -> 0.02954089
A15: 1 | B15: JPM | C15: GS | D15: 28708 | E15: 304.81 | F15: 797.11 | G15: 304.84048 | H15: 797.03029 | I15: -3.55602 | J15: 0.65390315 | K15: 0.032807323 | L15: -0.0082034243 | M15: LONG | N15: 27 | O15: signal | P15: 28735 | Q15: 304.57 | R15: 796.62 | S15: 0.12160767 | T15: -0.0038540795 | U15: -0.0071606965 | V15: 0.0033078755 | W15: -0.010468572 | X15: =WORKDAY(DATE(2025,8,2),INT(D15/390)) -> 45973 | Y15: =WORKDAY(DATE(2025,8,2),INT(P15/390)) -> 45973 | Z15: {=_xlfn.XLOOKUP(INT(X15),INT($AE$2:$AE$1000),$AG$2:$AG$1000,"")} -> 17.51 | AE15: =IF(ISNUMBER(AF15),DATE(YEAR(AF15),DAY(AF15),MONTH(AF15)),DATE(RIGHT(AF15,4),LEFT(AF15,2),MID(AF15,4,2))) -> 45889 | AF15: 08/20/2025 | AG15: 15.69 | AJ15: Avg net P&L/trade | AK15: =AVERAGEIF(D:D,"<55503",U:U) -> 0.0051130479 | AL15: =AVERAGEIF(D:D,">=55503",U:U) -> 0.025672116
A16: 1 | B16: JPM | C16: GS | D16: 29594 | E16: 301.3 | F16: 781.25 | G16: 301.26987 | H16: 781.32812 | I16: 3.5359515 | J16: 0.65390315 | K16: -0.033189512 | L16: 0.0083699603 | M16: SHORT | N16: 5 | O16: signal | P16: 29599 | Q16: 300.495 | R16: 781.25 | S16: -0.42317359 | T16: 0.026717557 | U16: 0.023412423 | V16: 0.0033077371 | W16: 0.020104686 | X16: =WORKDAY(DATE(2025,8,2),INT(D16/390)) -> 45975 | Y16: =WORKDAY(DATE(2025,8,2),INT(P16/390)) -> 45975 | Z16: {=_xlfn.XLOOKUP(INT(X16),INT($AE$2:$AE$1000),$AG$2:$AG$1000,"")} -> 19.83 | AE16: =IF(ISNUMBER(AF16),DATE(YEAR(AF16),DAY(AF16),MONTH(AF16)),DATE(RIGHT(AF16,4),LEFT(AF16,2),MID(AF16,4,2))) -> 45890 | AF16: 08/21/2025 | AG16: 16.6 | AJ16: Net PF | AK16: =SUMIFS(U:U,D:D,"<55503",U:U,">0")/ABS(SUMIFS(U:U,D:D,"<55503",U:U,"<0")) -> 1.5002724 | AL16: =SUMIFS(U:U,D:D,">=55503",U:U,">0")/ABS(SUMIFS(U:U,D:D,">=55503",U:U,"<0")) -> 5.6560542
A17: 1 | B17: JPM | C17: GS | D17: 29667 | E17: 300.82 | F17: 776.07 | G17: 300.78992 | H17: 776.14761 | I17: 4.3180527 | J17: 0.65390315 | K17: -0.033242471 | L17: 0.0084258269 | M17: SHORT | N17: 24 | O17: signal | P17: 29691 | Q17: 302.36 | R17: 779.065 | S17: 0.36508655 | T17: -0.025958053 | U17: -0.029273502 | V17: 0.0033077371 | W17: -0.032581239 | X17: =WORKDAY(DATE(2025,8,2),INT(D17/390)) -> 45978 | Y17: =WORKDAY(DATE(2025,8,2),INT(P17/390)) -> 45978 | Z17: {=_xlfn.XLOOKUP(INT(X17),INT($AE$2:$AE$1000),$AG$2:$AG$1000,"")} -> 22.38 | AE17: =IF(ISNUMBER(AF17),DATE(YEAR(AF17),DAY(AF17),MONTH(AF17)),DATE(RIGHT(AF17,4),LEFT(AF17,2),MID(AF17,4,2))) -> 45891 | AF17: 08/22/2025 | AG17: 14.22 | AJ17: Win rate | AK17: =COUNTIFS(D:D,"<55503",U:U,">0")/COUNTIF(D:D,"<55503") -> 0.63157895 | AL17: =COUNTIFS(D:D,">=55503",U:U,">0")/COUNTIF(D:D,">=55503") -> 0.75
A18: 1 | B18: JPM | C18: GS | D18: 30059 | E18: 307.04 | F18: 805.745 | G18: 307.0707 | H18: 805.66443 | I18: -3.8618259 | J18: 0.65390315 | K18: 0.032569046 | L18: -0.0081155099 | M18: LONG | N18: 6 | O18: signal | P18: 30065 | Q18: 308.48 | R18: 807.56 | S18: -0.319723 | T18: 0.032169776 | U18: 0.028855807 | V18: 0.0033078755 | W18: 0.025547932 | X18: =WORKDAY(DATE(2025,8,2),INT(D18/390)) -> 45979 | Y18: =WORKDAY(DATE(2025,8,2),INT(P18/390)) -> 45979 | Z18: {=_xlfn.XLOOKUP(INT(X18),INT($AE$2:$AE$1000),$AG$2:$AG$1000,"")} -> 24.69 | AE18: =IF(ISNUMBER(AF18),DATE(YEAR(AF18),DAY(AF18),MONTH(AF18)),DATE(RIGHT(AF18,4),LEFT(AF18,2),MID(AF18,4,2))) -> 45894 | AF18: 08/25/2025 | AG18: 14.79 | AJ18: Avg winner | AK18: =AVERAGEIFS(U:U,D:D,"<55503",U:U,">0") -> 0.024278162 | AL18: =AVERAGEIFS(U:U,D:D,">=55503",U:U,">0") -> 0.041581096
A19: 1 | B19: JPM | C19: GS | D19: 31217 | E19: 297.97 | F19: 792.37 | G19: 297.9998 | H19: 792.29076 | I19: -3.574562 | J19: 0.65390315 | K19: 0.033560426 | L19: -0.0082524976 | M19: LONG | N19: 10 | O19: signal | P19: 31227 | Q19: 299.32 | R19: 795.235 | S19: -0.43617298 | T19: 0.021663169 | U19: 0.018348468 | V19: 0.0033078755 | W19: 0.015040592 | X19: =WORKDAY(DATE(2025,8,2),INT(D19/390)) -> 45982 | Y19: =WORKDAY(DATE(2025,8,2),INT(P19/390)) -> 45982 | Z19: {=_xlfn.XLOOKUP(INT(X19),INT($AE$2:$AE$1000),$AG$2:$AG$1000,"")} -> 23.43 | AE19: =IF(ISNUMBER(AF19),DATE(YEAR(AF19),DAY(AF19),MONTH(AF19)),DATE(RIGHT(AF19,4),LEFT(AF19,2),MID(AF19,4,2))) -> 45895 | AF19: 08/26/2025 | AG19: 14.62 | AJ19: Avg loser | AK19: =AVERAGEIFS(U:U,D:D,"<55503",U:U,"<0") -> -0.027741433 | AL19: =AVERAGEIFS(U:U,D:D,">=55503",U:U,"<0") -> -0.022054826
A20: 2 | B20: BAC | C20: WFC | D20: 31801 | E20: 53.09 | F20: 85.965 | G20: 53.095309 | H20: 85.956404 | I20: -5.2946208 | J20: 0.73858207 | K20: 0.18835939 | L20: -0.085916602 | M20: LONG | N20: 23 | O20: signal | P20: 31824 | Q20: 53.09 | R20: 86 | S20: -0.49061199 | T20: -0.0030070811 | U20: -0.0064845459 | V20: 0.0034772164 | W20: -0.0099617624 | X20: =WORKDAY(DATE(2025,8,2),INT(D20/390)) -> 45985 | Y20: =WORKDAY(DATE(2025,8,2),INT(P20/390)) -> 45985 | Z20: {=_xlfn.XLOOKUP(INT(X20),INT($AE$2:$AE$1000),$AG$2:$AG$1000,"")} -> 20.52 | AE20: =IF(ISNUMBER(AF20),DATE(YEAR(AF20),DAY(AF20),MONTH(AF20)),DATE(RIGHT(AF20,4),LEFT(AF20,2),MID(AF20,4,2))) -> 45896 | AF20: 08/27/2025 | AG20: 14.85 | AJ20: Avg holding time | AK20: =AVERAGEIF(D:D,"<55503",N:N) -> 16.578947 | AL20: =AVERAGEIF(D:D,">=55503",N:N) -> 13.34375
A21: 2 | B21: BAC | C21: WFC | D21: 32007 | E21: 53.05 | F21: 85.48 | G21: 53.044695 | H21: 85.488548 | I21: 4.5358082 | J21: 0.73858207 | K21: -0.18850141 | L21: 0.08640408 | M21: SHORT | N21: 48 | O21: signal | P21: 32055 | Q21: 53.64 | R21: 85.89 | S21: 0.45483687 | T21: -0.075790161 | U21: -0.07928199 | V21: 0.0034771119 | W21: -0.082759102 | X21: =WORKDAY(DATE(2025,8,2),INT(D21/390)) -> 45986 | Y21: =WORKDAY(DATE(2025,8,2),INT(P21/390)) -> 45986 | Z21: {=_xlfn.XLOOKUP(INT(X21),INT($AE$2:$AE$1000),$AG$2:$AG$1000,"")} -> 18.56 | AE21: =IF(ISNUMBER(AF21),DATE(YEAR(AF21),DAY(AF21),MONTH(AF21)),DATE(RIGHT(AF21,4),LEFT(AF21,2),MID(AF21,4,2))) -> 45897 | AF21: 08/28/2025 | AG21: 14.43 | AJ21: Avg |entry Z| | AK21: {=SUMPRODUCT((D2:D998<55503)*ABS(I2:I998))/COUNTIF(D2:D998,"<55503")} -> 4.1580935 | AL21: {=SUMPRODUCT((D2:D998>=55503)*ABS(I2:I998))/COUNTIF(D2:D998,">=55503")} -> 4.1719751
A22: 2 | B22: BAC | C22: WFC | D22: 32217 | E22: 53.525 | F22: 85.885 | G22: 53.530352 | H22: 85.876412 | I22: -4.2270289 | J22: 0.73858207 | K22: 0.18682858 | L22: -0.085996632 | M22: LONG | N22: 1 | O22: signal | P22: 32218 | Q22: 53.54 | R22: 85.66 | S22: 0.16301468 | T22: 0.022151671 | U22: 0.018676161 | V22: 0.0034772164 | W22: 0.015198945 | X22: =WORKDAY(DATE(2025,8,2),INT(D22/390)) -> 45986 | Y22: =WORKDAY(DATE(2025,8,2),INT(P22/390)) -> 45986 | Z22: {=_xlfn.XLOOKUP(INT(X22),INT($AE$2:$AE$1000),$AG$2:$AG$1000,"")} -> 18.56 | AE22: =IF(ISNUMBER(AF22),DATE(YEAR(AF22),DAY(AF22),MONTH(AF22)),DATE(RIGHT(AF22,4),LEFT(AF22,2),MID(AF22,4,2))) -> 45898 | AF22: 08/29/2025 | AG22: 15.36
A23: 2 | B23: BAC | C23: WFC | D23: 32614 | E23: 53.25 | F23: 85.77 | G23: 53.255325 | H23: 85.761423 | I23: -3.6888174 | J23: 0.73858207 | K23: 0.18779343 | L23: -0.086111936 | M23: LONG | N23: 17 | O23: signal | P23: 32631 | Q23: 53.135 | R23: 85.39 | S23: -0.28159101 | T23: 0.011126291 | U23: 0.0076545592 | V23: 0.0034772164 | W23: 0.0041773427 | X23: =WORKDAY(DATE(2025,8,2),INT(D23/390)) -> 45987 | Y23: =WORKDAY(DATE(2025,8,2),INT(P23/390)) -> 45987 | Z23: {=_xlfn.XLOOKUP(INT(X23),INT($AE$2:$AE$1000),$AG$2:$AG$1000,"")} -> 17.19 | AE23: =IF(ISNUMBER(AF23),DATE(YEAR(AF23),DAY(AF23),MONTH(AF23)),DATE(RIGHT(AF23,4),LEFT(AF23,2),MID(AF23,4,2))) -> 45901 | AF23: 45666 | AG23: 16.12
A24: 2 | B24: BAC | C24: WFC | D24: 32998 | E24: 53.3 | F24: 86.31 | G24: 53.29467 | H24: 86.318631 | I24: 4.1634247 | J24: 0.73858207 | K24: -0.18761726 | L24: 0.085573175 | M24: SHORT | N24: 17 | O24: signal | P24: 33015 | Q24: 53.525 | R24: 86.83 | S24: 0.4746937 | T24: 0.0022841673 | U24: -0.0012016681 | V24: 0.0034771119 | W24: -0.0046787799 | X24: =WORKDAY(DATE(2025,8,2),INT(D24/390)) -> 45988 | Y24: =WORKDAY(DATE(2025,8,2),INT(P24/390)) -> 45988 | Z24: {=_xlfn.XLOOKUP(INT(X24),INT($AE$2:$AE$1000),$AG$2:$AG$1000,"")} -> 17.21 | AE24: =IF(ISNUMBER(AF24),DATE(YEAR(AF24),DAY(AF24),MONTH(AF24)),DATE(RIGHT(AF24,4),LEFT(AF24,2),MID(AF24,4,2))) -> 45902 | AF24: 45697 | AG24: 17.17
A25: 2 | B25: BAC | C25: WFC | D25: 34559 | E25: 54.005 | F25: 89.76 | G25: 53.9996 | H25: 89.768976 | I25: 3.5672352 | J25: 0.73858207 | K25: -0.18516804 | L25: 0.082284099 | M25: SHORT | N25: 5 | O25: signal | P25: 34564 | Q25: 53.83 | R25: 89.755 | S25: 0.11894705 | T25: 0.031992987 | U25: 0.028519104 | V25: 0.0034771119 | W25: 0.025041992 | X25: =WORKDAY(DATE(2025,8,2),INT(D25/390)) -> 45994 | Y25: =WORKDAY(DATE(2025,8,2),INT(P25/390)) -> 45994 | Z25: {=_xlfn.XLOOKUP(INT(X25),INT($AE$2:$AE$1000),$AG$2:$AG$1000,"")} -> 16.08 | AE25: =IF(ISNUMBER(AF25),DATE(YEAR(AF25),DAY(AF25),MONTH(AF25)),DATE(RIGHT(AF25,4),LEFT(AF25,2),MID(AF25,4,2))) -> 45903 | AF25: 45725 | AG25: 16.35
A26: 2 | B26: BAC | C26: WFC | D26: 35304 | E26: 53.915 | F26: 90.32 | G26: 53.920392 | H26: 90.310968 | I26: -3.5605368 | J26: 0.73858207 | K26: 0.18547714 | L26: -0.081773923 | M26: LONG | N26: 6 | O26: signal | P26: 35310 | Q26: 54.27 | R26: 90.385 | S26: 0.059936539 | T26: 0.06052908 | U26: 0.0570448 | V26: 0.0034772164 | W26: 0.053567583 | X26: =WORKDAY(DATE(2025,8,2),INT(D26/390)) -> 45996 | Y26: =WORKDAY(DATE(2025,8,2),INT(P26/390)) -> 45996 | Z26: {=_xlfn.XLOOKUP(INT(X26),INT($AE$2:$AE$1000),$AG$2:$AG$1000,"")} -> 15.41 | AE26: =IF(ISNUMBER(AF26),DATE(YEAR(AF26),DAY(AF26),MONTH(AF26)),DATE(RIGHT(AF26,4),LEFT(AF26,2),MID(AF26,4,2))) -> 45904 | AF26: 45756 | AG26: 15.3
A27: 2 | B27: BAC | C27: WFC | D27: 35659 | E27: 54.485 | F27: 93.055 | G27: 54.479551 | H27: 93.064306 | I27: 3.9191208 | J27: 0.73858207 | K27: -0.18353675 | L27: 0.079370488 | M27: SHORT | N27: 66 | O27: signal | P27: 35725 | Q27: 54.545 | R27: 92.655 | S27: 0.45326715 | T27: -0.0427604 | U27: -0.046235491 | V27: 0.0034771119 | W27: -0.049712603 | X27: =WORKDAY(DATE(2025,8,2),INT(D27/390)) -> 45999 | Y27: =WORKDAY(DATE(2025,8,2),INT(P27/390)) -> 45999 | Z27: {=_xlfn.XLOOKUP(INT(X27),INT($AE$2:$AE$1000),$AG$2:$AG$1000,"")} -> 16.66 | AE27: =IF(ISNUMBER(AF27),DATE(YEAR(AF27),DAY(AF27),MONTH(AF27)),DATE(RIGHT(AF27,4),LEFT(AF27,2),MID(AF27,4,2))) -> 45905 | AF27: 45786 | AG27: 15.18
A28: 3 | B28: BAC | C28: WFC | D28: 36509 | E28: 54.965 | F28: 93.105 | G28: 54.970497 | H28: 93.09569 | I28: -4.8712868 | J28: 0.67544695 | K28: 0.18193396 | L28: -0.072546796 | M28: LONG | N28: 7 | O28: signal | P28: 36516 | Q28: 55.35 | R28: 93.03 | S28: -0.41313051 | T28: 0.075485584 | U28: 0.072128229 | V28: 0.0033509588 | W28: 0.06877727 | X28: =WORKDAY(DATE(2025,8,2),INT(D28/390)) -> 46001 | Y28: =WORKDAY(DATE(2025,8,2),INT(P28/390)) -> 46001 | Z28: {=_xlfn.XLOOKUP(INT(X28),INT($AE$2:$AE$1000),$AG$2:$AG$1000,"")} -> 15.77 | AE28: =IF(ISNUMBER(AF28),DATE(YEAR(AF28),DAY(AF28),MONTH(AF28)),DATE(RIGHT(AF28,4),LEFT(AF28,2),MID(AF28,4,2))) -> 45908 | AF28: 45878 | AG28: 15.11
A29: 3 | B29: BAC | C29: WFC | D29: 37290 | E29: 54.595 | F29: 93.11 | G29: 54.600459 | H29: 93.100689 | I29: -3.9272584 | J29: 0.67544695 | K29: 0.18316696 | L29: -0.0725429 | M29: LONG | N29: 25 | O29: signal | P29: 37315 | Q29: 55.1 | R29: 93.705 | S29: 0.14678068 | T29: 0.049336287 | U29: 0.045971827 | V29: 0.0033509588 | W29: 0.042620868 | X29: =WORKDAY(DATE(2025,8,2),INT(D29/390)) -> 46003 | Y29: =WORKDAY(DATE(2025,8,2),INT(P29/390)) -> 46003 | Z29: {=_xlfn.XLOOKUP(INT(X29),INT($AE$2:$AE$1000),$AG$2:$AG$1000,"")} -> 15.74 | AE29: =IF(ISNUMBER(AF29),DATE(YEAR(AF29),DAY(AF29),MONTH(AF29)),DATE(RIGHT(AF29,4),LEFT(AF29,2),MID(AF29,4,2))) -> 45909 | AF29: 45909 | AG29: 15.04
A30: 3 | B30: BAC | C30: WFC | D30: 37679 | E30: 54.57 | F30: 91.7 | G30: 54.564543 | H30: 91.70917 | I30: 4.6807257 | J30: 0.67544695 | K30: -0.18325087 | L30: 0.073658336 | M30: SHORT | N30: 22 | O30: signal | P30: 37701 | Q30: 54.75 | R30: 92.075 | S30: 0.41292147 | T30: -0.0053632805 | U30: -0.0087202351 | V30: 0.003350829 | W30: -0.012071064 | X30: =WORKDAY(DATE(2025,8,2),INT(D30/390)) -> 46006 | Y30: =WORKDAY(DATE(2025,8,2),INT(P30/390)) -> 46006 | Z30: {=_xlfn.XLOOKUP(INT(X30),INT($AE$2:$AE$1000),$AG$2:$AG$1000,"")} -> 16.5 | AE30: =IF(ISNUMBER(AF30),DATE(YEAR(AF30),DAY(AF30),MONTH(AF30)),DATE(RIGHT(AF30,4),LEFT(AF30,2),MID(AF30,4,2))) -> 45910 | AF30: 45939 | AG30: 15.35
A31: 3 | B31: BAC | C31: WFC | D31: 38190 | E31: 55.87 | F31: 94.01 | G31: 55.864413 | H31: 94.019401 | I31: 3.6342178 | J31: 0.67544695 | K31: -0.17898693 | L31: 0.071848415 | M31: SHORT | N31: 16 | O31: signal | P31: 38206 | Q31: 55.915 | R31: 94.115 | S31: 0.48719907 | T31: -0.0005103285 | U31: -0.0038627822 | V31: 0.003350829 | W31: -0.0072136112 | X31: =WORKDAY(DATE(2025,8,2),INT(D31/390)) -> 46007 | Y31: =WORKDAY(DATE(2025,8,2),INT(P31/390)) -> 46007 | Z31: {=_xlfn.XLOOKUP(INT(X31),INT($AE$2:$AE$1000),$AG$2:$AG$1000,"")} -> 16.48 | AE31: =IF(ISNUMBER(AF31),DATE(YEAR(AF31),DAY(AF31),MONTH(AF31)),DATE(RIGHT(AF31,4),LEFT(AF31,2),MID(AF31,4,2))) -> 45911 | AF31: 45970 | AG31: 14.71
A32: 3 | B32: BAC | C32: WFC | D32: 38306 | E32: 55.98 | F32: 93.99 | G32: 55.985598 | H32: 93.980601 | I32: -4.0638487 | J32: 0.67544695 | K32: 0.17863523 | L32: -0.071863703 | M32: LONG | N32: 27 | O32: signal | P32: 38333 | Q32: 55.955 | R32: 93.96 | S32: 0.017472686 | T32: -0.0023099696 | U32: -0.0056602013 | V32: 0.0033509588 | W32: -0.0090111601 | X32: =WORKDAY(DATE(2025,8,2),INT(D32/390)) -> 46008 | Y32: =WORKDAY(DATE(2025,8,2),INT(P32/390)) -> 46008 | Z32: {=_xlfn.XLOOKUP(INT(X32),INT($AE$2:$AE$1000),$AG$2:$AG$1000,"")} -> 17.62 | AE32: =IF(ISNUMBER(AF32),DATE(YEAR(AF32),DAY(AF32),MONTH(AF32)),DATE(RIGHT(AF32,4),LEFT(AF32,2),MID(AF32,4,2))) -> 45912 | AF32: 46000 | AG32: 14.76
A33: 3 | B33: BAC | C33: WFC | D33: 38659 | E33: 55.95 | F33: 94.22 | G33: 55.955595 | H33: 94.210578 | I33: -3.6283825 | J33: 0.67544695 | K33: 0.17873101 | L33: -0.071688277 | M33: LONG | N33: 15 | O33: signal | P33: 38674 | Q33: 56.025 | R33: 94.29 | S33: 0.17646003 | T33: 0.0083866464 | U33: 0.0050339102 | V33: 0.0033509588 | W33: 0.0016829514 | X33: =WORKDAY(DATE(2025,8,2),INT(D33/390)) -> 46009 | Y33: =WORKDAY(DATE(2025,8,2),INT(P33/390)) -> 46009 | Z33: {=_xlfn.XLOOKUP(INT(X33),INT($AE$2:$AE$1000),$AG$2:$AG$1000,"")} -> 16.87 | AE33: =IF(ISNUMBER(AF33),DATE(YEAR(AF33),DAY(AF33),MONTH(AF33)),DATE(RIGHT(AF33,4),LEFT(AF33,2),MID(AF33,4,2))) -> 45915 | AF33: 09/15/2025 | AG33: 15.69
A34: 3 | B34: BAC | C34: WFC | D34: 39059 | E34: 56.42 | F34: 95.27 | G34: 56.414358 | H34: 95.279527 | I34: 3.7111055 | J34: 0.67544695 | K34: -0.17724211 | L34: 0.070898178 | M34: SHORT | N34: 9 | O34: signal | P34: 39068 | Q34: 56.34 | R34: 95.295 | S34: 0.16521923 | T34: 0.015951823 | U34: 0.01260217 | V34: 0.003350829 | W34: 0.0092513413 | X34: =WORKDAY(DATE(2025,8,2),INT(D34/390)) -> 46010 | Y34: =WORKDAY(DATE(2025,8,2),INT(P34/390)) -> 46010 | Z34: {=_xlfn.XLOOKUP(INT(X34),INT($AE$2:$AE$1000),$AG$2:$AG$1000,"")} -> 14.91 | AE34: =IF(ISNUMBER(AF34),DATE(YEAR(AF34),DAY(AF34),MONTH(AF34)),DATE(RIGHT(AF34,4),LEFT(AF34,2),MID(AF34,4,2))) -> 45916 | AF34: 09/16/2025 | AG34: 16.36
A35: 3 | B35: BAC | C35: WFC | D35: 39449 | E35: 56.095 | F35: 95.37 | G35: 56.100609 | H35: 95.360463 | I35: -3.6509999 | J35: 0.67544695 | K35: 0.17826901 | L35: -0.070823838 | M35: LONG | N35: 23 | O35: signal | P35: 39472 | Q35: 55.91 | R35: 94.92 | S35: -0.48824636 | T35: -0.0011090393 | U35: -0.0044534481 | V35: 0.0033509588 | W35: -0.0078044069 | X35: =WORKDAY(DATE(2025,8,2),INT(D35/390)) -> 46013 | Y35: =WORKDAY(DATE(2025,8,2),INT(P35/390)) -> 46013 | Z35: {=_xlfn.XLOOKUP(INT(X35),INT($AE$2:$AE$1000),$AG$2:$AG$1000,"")} -> 14.08 | AE35: =IF(ISNUMBER(AF35),DATE(YEAR(AF35),DAY(AF35),MONTH(AF35)),DATE(RIGHT(AF35,4),LEFT(AF35,2),MID(AF35,4,2))) -> 45917 | AF35: 09/17/2025 | AG35: 15.72
A36: 4 | B36: BAC | C36: WFC | D36: 39601 | E36: 55.465 | F36: 94.535 | G36: 55.459454 | H36: 94.544453 | I36: 5.2938913 | J36: 0.65333461 | K36: -0.18029388 | L36: 0.069110341 | M36: SHORT | N36: 23 | O36: signal | P36: 39624 | Q36: 55.43 | R36: 94.45 | S36: 0.48129623 | T36: 0.00043590681 | U36: -0.0028695439 | V36: 0.0033065999 | W36: -0.0061761438 | X36: =WORKDAY(DATE(2025,8,2),INT(D36/390)) -> 46013 | Y36: =WORKDAY(DATE(2025,8,2),INT(P36/390)) -> 46013 | Z36: {=_xlfn.XLOOKUP(INT(X36),INT($AE$2:$AE$1000),$AG$2:$AG$1000,"")} -> 14.08 | AE36: =IF(ISNUMBER(AF36),DATE(YEAR(AF36),DAY(AF36),MONTH(AF36)),DATE(RIGHT(AF36,4),LEFT(AF36,2),MID(AF36,4,2))) -> 45918 | AF36: 09/18/2025 | AG36: 15.7
A37: 4 | B37: BAC | C37: WFC | D37: 39839 | E37: 55.6 | F37: 94.82 | G37: 55.59444 | H37: 94.829482 | I37: 5.0316061 | J37: 0.65333461 | K37: -0.17985612 | L37: 0.068902616 | M37: SHORT | N37: 15 | O37: signal | P37: 39854 | Q37: 55.325 | R37: 94.34 | S37: -0.086236821 | T37: 0.016387176 | U37: 0.01308876 | V37: 0.0033065999 | W37: 0.0097821602 | X37: =WORKDAY(DATE(2025,8,2),INT(D37/390)) -> 46014 | Y37: =WORKDAY(DATE(2025,8,2),INT(P37/390)) -> 46014 | Z37: {=_xlfn.XLOOKUP(INT(X37),INT($AE$2:$AE$1000),$AG$2:$AG$1000,"")} -> 14 | AE37: =IF(ISNUMBER(AF37),DATE(YEAR(AF37),DAY(AF37),MONTH(AF37)),DATE(RIGHT(AF37,4),LEFT(AF37,2),MID(AF37,4,2))) -> 45919 | AF37: 09/19/2025 | AG37: 15.45
A38: 4 | B38: BAC | C38: WFC | D38: 41009 | E38: 56.28 | F38: 95.5 | G38: 56.274372 | H38: 95.50955 | I38: 5.0228281 | J38: 0.65333461 | K38: -0.17768301 | L38: 0.068412001 | M38: SHORT | N38: 27 | O38: signal | P38: 41036 | Q38: 57.19 | R38: 96.84 | S38: 0.39209777 | T38: -0.070019462 | U38: -0.073351467 | V38: 0.0033065999 | W38: -0.076658067 | X38: =WORKDAY(DATE(2025,8,2),INT(D38/390)) -> 46017 | Y38: =WORKDAY(DATE(2025,8,2),INT(P38/390)) -> 46017 | Z38: {=_xlfn.XLOOKUP(INT(X38),INT($AE$2:$AE$1000),$AG$2:$AG$1000,"")} -> 13.6 | AE38: =IF(ISNUMBER(AF38),DATE(YEAR(AF38),DAY(AF38),MONTH(AF38)),DATE(RIGHT(AF38,4),LEFT(AF38,2),MID(AF38,4,2))) -> 45922 | AF38: 09/22/2025 | AG38: 16.1
A39: 4 | B39: BAC | C39: WFC | D39: 41201 | E39: 57.27 | F39: 97.02 | G39: 57.264273 | H39: 97.029702 | I39: 3.6553078 | J39: 0.65333461 | K39: -0.17461149 | L39: 0.067340198 | M39: SHORT | N39: 8 | O39: signal | P39: 41209 | Q39: 57.21 | R39: 97.1 | S39: 0.10476352 | T39: 0.015863905 | U39: 0.012557745 | V39: 0.0033065999 | W39: 0.0092511451 | X39: =WORKDAY(DATE(2025,8,2),INT(D39/390)) -> 46017 | Y39: =WORKDAY(DATE(2025,8,2),INT(P39/390)) -> 46017 | Z39: {=_xlfn.XLOOKUP(INT(X39),INT($AE$2:$AE$1000),$AG$2:$AG$1000,"")} -> 13.6 | AE39: =IF(ISNUMBER(AF39),DATE(YEAR(AF39),DAY(AF39),MONTH(AF39)),DATE(RIGHT(AF39,4),LEFT(AF39,2),MID(AF39,4,2))) -> 45923 | AF39: 09/23/2025 | AG39: 16.64
A40: 4 | B40: BAC | C40: WFC | D40: 41399 | E40: 57.19 | F40: 95.59 | G40: 57.184281 | H40: 95.599559 | I40: 5.0111564 | J40: 0.65333461 | K40: -0.17485574 | L40: 0.068347589 | M40: SHORT | N40: 15 | O40: signal | P40: 41414 | Q40: 56.91 | R40: 95.525 | S40: 0.46103593 | T40: 0.044517015 | U40: 0.041215686 | V40: 0.0033065999 | W40: 0.037909086 | X40: =WORKDAY(DATE(2025,8,2),INT(D40/390)) -> 46020 | Y40: =WORKDAY(DATE(2025,8,2),INT(P40/390)) -> 46020 | Z40: {=_xlfn.XLOOKUP(INT(X40),INT($AE$2:$AE$1000),$AG$2:$AG$1000,"")} -> 14.2 | AE40: =IF(ISNUMBER(AF40),DATE(YEAR(AF40),DAY(AF40),MONTH(AF40)),DATE(RIGHT(AF40,4),LEFT(AF40,2),MID(AF40,4,2))) -> 45924 | AF40: 09/24/2025 | AG40: 16.18
...

Sheet Analysis
L1: Exit timestamp | M1: Cumulative Gross PnL | N1: Cumulative Slipped PnL | O1: Cumulative Net PnL | Q1: min holding minutes | R1: max holding minutes | S1: Mean Net PnL | T1: Number of trades
B2: Rough Analysis of the baseline strategy | J2: Figures | L2: =Trades!P2 -> 24214 | M2: =Trades!T2 -> 0.024154984 | N2: =Trades!U2 -> 0.020822539 | O2: =Trades!W2 -> 0.017487745 | Q2: 0 | R2: 3 | S2: =AVERAGEIFS(Trades!W:W,Trades!N:N,">="&Q2,Trades!N:N,"<="&R2) -> 0.065848141 | T2: =COUNTIFS(Trades!N:N,">="&Q2,Trades!N:N,"<="&R2) -> 17
L3: =Trades!P3 -> 24606 | M3: =M2+Trades!T3 -> 0.067822224 | N3: =N2+Trades!U3 -> 0.061157159 | O3: =O2+Trades!W3 -> 0.054487572 | Q3: 4 | R3: 7 | S3: =AVERAGEIFS(Trades!W:W,Trades!N:N,">="&Q3,Trades!N:N,"<="&R3) -> 0.03239684 | T3: =COUNTIFS(Trades!N:N,">="&Q3,Trades!N:N,"<="&R3) -> 36
B4: Column1 | C4: Gross | D4: Slipped | E4: Net (Transaction costs) | L4: =Trades!P4 -> 24848 | M4: =M3+Trades!T4 -> 0.072054022 | N4: =N3+Trades!U4 -> 0.062055967 | O4: =O3+Trades!W4 -> 0.052051586 | Q4: 8 | R4: 11 | S4: =AVERAGEIFS(Trades!W:W,Trades!N:N,">="&Q4,Trades!N:N,"<="&R4) -> 0.024198474 | T4: =COUNTIFS(Trades!N:N,">="&Q4,Trades!N:N,"<="&R4) -> 23
B5: Overall PnL | C5: =SUM(Trades!T2:T9652) -> 3.493189 | D5: =SUM(Trades!U2:U9652) -> 2.8531148 | E5: =SUM(Trades!W2:W9652) -> 2.2131071 | L5: =Trades!P5 -> 24996 | M5: =M4+Trades!T5 -> 0.10989766 | N5: =N4+Trades!U5 -> 0.096564379 | O5: =O4+Trades!W5 -> 0.083225071 | Q5: 12 | R5: 15 | S5: =AVERAGEIFS(Trades!W:W,Trades!N:N,">="&Q5,Trades!N:N,"<="&R5) -> 0.019780891 | T5: =COUNTIFS(Trades!N:N,">="&Q5,Trades!N:N,"<="&R5) -> 23
B6: Mean PnL | C6: =AVERAGE(Trades!T:T) -> 0.020309239 | D6: =AVERAGE(Trades!U:U) -> 0.016587876 | E6: =AVERAGE(Trades!W:W) -> 0.012866902 | L6: =Trades!P6 -> 25392 | M6: =M5+Trades!T6 -> 0.14071719 | N6: =N5+Trades!U6 -> 0.12404061 | O6: =O5+Trades!W6 -> 0.10736638 | Q6: 16 | R6: 19 | S6: =AVERAGEIFS(Trades!W:W,Trades!N:N,">="&Q6,Trades!N:N,"<="&R6) -> -0.0038241363 | T6: =COUNTIFS(Trades!N:N,">="&Q6,Trades!N:N,"<="&R6) -> 17
B7: Median PnL | C7: =MEDIAN(Trades!T:T) -> 0.016668201 | D7: =MEDIAN(Trades!U:U) -> 0.013015848 | E7: =MEDIAN(Trades!W:W) -> 0.0092512432 | L7: =Trades!P7 -> 25731 | M7: =M6+Trades!T7 -> 0.12499991 | N7: =N6+Trades!U7 -> 0.10498528 | O7: =O6+Trades!W7 -> 0.084976254 | Q7: 20 | R7: 23 | S7: =AVERAGEIFS(Trades!W:W,Trades!N:N,">="&Q7,Trades!N:N,"<="&R7) -> -0.0080220137 | T7: =COUNTIFS(Trades!N:N,">="&Q7,Trades!N:N,"<="&R7) -> 26
B8: Max drawdown | C8: =MIN(Trades!T:T) -> -0.087068107 | D8: =MIN(Trades!U:U) -> -0.091191822 | E8: =MIN(Trades!W:W) -> -0.095289891 | L8: =Trades!P8 -> 25758 | M8: =M7+Trades!T8 -> 0.13581127 | N8: =N7+Trades!U8 -> 0.11246473 | O8: =O7+Trades!W8 -> 0.089120912 | Q8: 24 | R8: 27 | S8: =AVERAGEIFS(Trades!W:W,Trades!N:N,">="&Q8,Trades!N:N,"<="&R8) -> -0.022393823 | T8: =COUNTIFS(Trades!N:N,">="&Q8,Trades!N:N,"<="&R8) -> 15
B9: Biggest Winner | C9: =MAX(Trades!T:T) -> 0.30702651 | D9: =MAX(Trades!U:U) -> 0.30311966 | E9: =MAX(Trades!W:W) -> 0.29918211 | L9: =Trades!P9 -> 26942 | M9: =M8+Trades!T9 -> 0.16614087 | N9: =N8+Trades!U9 -> 0.13944671 | O9: =O8+Trades!W9 -> 0.11276796 | Q9: 28 | R9: 34 | S9: =AVERAGEIFS(Trades!W:W,Trades!N:N,">="&Q9,Trades!N:N,"<="&R9) -> -0.016174126 | T9: =COUNTIFS(Trades!N:N,">="&Q9,Trades!N:N,"<="&R9) -> 8
B10: Win rate | C10: =COUNTIF(Trades!T:T,">0")/(COUNTIF(Trades!T:T,">0")+COUNTIF(Trades!T:T,"<0")) -> 0.74418605 | D10: =COUNTIF(Trades!U:U,">0")/(COUNTIF(Trades!U:U,">0")+COUNTIF(Trades!U:U,"<0")) -> 0.69767442 | E10: =COUNTIF(Trades!W:W,">0")/(COUNTIF(Trades!W:W,">0")+COUNTIF(Trades!W:W,"<0")) -> 0.65697674 | L10: =Trades!P10 -> 27332 | M10: =M9+Trades!T10 -> 0.19014346 | N10: =N9+Trades!U10 -> 0.1601233 | O10: =O9+Trades!W10 -> 0.13010976 | Q10: 35 | R10: 40 | S10: =AVERAGEIFS(Trades!W:W,Trades!N:N,">="&Q10,Trades!N:N,"<="&R10) -> -0.045173001 | T10: =COUNTIFS(Trades!N:N,">="&Q10,Trades!N:N,"<="&R10) -> 4
B11: Profit Factor | C11: =SUMIF(Trades!T:T,">0",Trades!T:T)/ABS(SUMIF(Trades!T:T,"<0",Trades!T:T)) -> 4.0983255 | D11: =SUMIF(Trades!U:U,">0",Trades!U:U)/ABS(SUMIF(Trades!U:U,"<0",Trades!U:U)) -> 3.1844938 | E11: =SUMIF(Trades!W:W,">0",Trades!W:W)/ABS(SUMIF(Trades!W:W,"<0",Trades!W:W)) -> 2.4623543
L12: =Trades!P11 -> 27725 | M12: =M10+Trades!T11 -> 0.2079384 | N12: =N10+Trades!U11 -> 0.17456116 | O12: =O10+Trades!W11 -> 0.14121269 | Q12: 41 | R12: 47 | S12: =AVERAGEIFS(Trades!W:W,Trades!N:N,">="&Q12,Trades!N:N,"<="&R12) -> -0.032076202 | T12: =COUNTIFS(Trades!N:N,">="&Q12,Trades!N:N,"<="&R12) -> 1
B13: Column1 | C13: Column2 | L13: =Trades!P12 -> 27924 | M13: =M12+Trades!T12 -> 0.22286538 | N13: =N12+Trades!U12 -> 0.18618114 | O13: =O12+Trades!W12 -> 0.14952493
B14: Number of Trades | C14: =COUNTA(Trades!A:A)-1 -> 172 | L14: =Trades!P13 -> 28504 | M14: =M13+Trades!T13 -> 0.25930309 | N14: =N13+Trades!U13 -> 0.2193162 | O14: =O13+Trades!W13 -> 0.17935226
B15: Mean holding time | C15: =AVERAGE(Trades!N:N) -> 14.773256 | L15: =Trades!P14 -> 28639 | M15: =M14+Trades!T14 -> 0.29182341 | N15: =N14+Trades!U14 -> 0.24852757 | O15: =O14+Trades!W14 -> 0.20525575
B16: Median holding time | C16: =MEDIAN(Trades!N:N) -> 13 | L16: =Trades!P15 -> 28735 | M16: =M15+Trades!T15 -> 0.28796933 | N16: =N15+Trades!U15 -> 0.24136687 | O16: =O15+Trades!W15 -> 0.19478718
B17: Max holding time | C17: =MAX(Trades!N:N) -> 66 | L17: =Trades!P16 -> 29599 | M17: =M16+Trades!T16 -> 0.31468689 | N17: =N16+Trades!U16 -> 0.26477929 | O17: =O16+Trades!W16 -> 0.21489186
L18: =Trades!P17 -> 29691 | M18: =M17+Trades!T17 -> 0.28872883 | N18: =N17+Trades!U17 -> 0.23550579 | O18: =O17+Trades!W17 -> 0.18231062
B19: Column1 | C19: Positive | D19: Negative | L19: =Trades!P18 -> 30065 | M19: =M18+Trades!T18 -> 0.32089861 | N19: =N18+Trades!U18 -> 0.2643616 | O19: =O18+Trades!W18 -> 0.20785855
B20: Mean entry z score | C20: =AVERAGEIF(Trades!I:I,">0",Trades!I:I) -> 4.1598565 | D20: =AVERAGEIF(Trades!I:I,"<0",Trades!I:I) -> -4.1734012 | L20: =Trades!P19 -> 31227 | M20: =M19+Trades!T19 -> 0.34256178 | N20: =N19+Trades!U19 -> 0.28271007 | O20: =O19+Trades!W19 -> 0.22289915
B21: Median entry z score | C21: {=MEDIAN(_xlfn._xlws.FILTER(Trades!I:I,Trades!I:I>0))} -> 3.9703404 | D21: {=MEDIAN(_xlfn._xlws.FILTER(Trades!I:I,Trades!I:I<0))} -> -3.9798413 | L21: =Trades!P20 -> 31824 | M21: =M20+Trades!T20 -> 0.3395547 | N21: =N20+Trades!U20 -> 0.27622552 | O21: =O20+Trades!W20 -> 0.21293738
B22: max entry z score | C22: =_xlfn.MAXIFS(Trades!I:I,Trades!I:I,">0") -> 5.2946422 | D22: =_xlfn.MINIFS(Trades!I:I,Trades!I:I,"<0") -> -5.29465 | L22: =Trades!P21 -> 32055 | M22: =M21+Trades!T21 -> 0.26376454 | N22: =N21+Trades!U21 -> 0.19694353 | O22: =O21+Trades!W21 -> 0.13017828
B23: Mean exit z score | C23: =AVERAGEIF(Trades!S:S,">0",Trades!S:S) -> 0.276759 | D23: =AVERAGEIF(Trades!S:S,"<0",Trades!S:S) -> -0.30373698 | L23: =Trades!P22 -> 32218 | M23: =M22+Trades!T22 -> 0.28591621 | N23: =N22+Trades!U22 -> 0.21561969 | O23: =O22+Trades!W22 -> 0.14537723
B24: Median exit z score | C24: {=MEDIAN(_xlfn._xlws.FILTER(Trades!S:S,Trades!S:S>0))} -> 0.28602685 | D24: {=MEDIAN(_xlfn._xlws.FILTER(Trades!S:S,Trades!S:S<0))} -> -0.31610595 | L24: =Trades!P23 -> 32631 | M24: =M23+Trades!T23 -> 0.2970425 | N24: =N23+Trades!U23 -> 0.22327425 | O24: =O23+Trades!W23 -> 0.14955457
B25: max exit z score | C25: =_xlfn.MAXIFS(Trades!S:S,Trades!S:S,">0") -> 0.49471769 | D25: =_xlfn.MINIFS(Trades!S:S,Trades!S:S,"<0") -> -0.49975108 | L25: =Trades!P24 -> 33015 | M25: =M24+Trades!T24 -> 0.29932667 | N25: =N24+Trades!U24 -> 0.22207258 | O25: =O24+Trades!W24 -> 0.14487579
G26: 1 | H26: Edge is there, but wiped out by costs | L26: =Trades!P25 -> 34564 | M26: =M25+Trades!T25 -> 0.33131965 | N26: =N25+Trades!U25 -> 0.25059169 | O26: =O25+Trades!W25 -> 0.16991778
B27: Column1 | C27: Long | D27: Short | E27: Signal | F27: Forced | L27: =Trades!P26 -> 35310 | M27: =M26+Trades!T26 -> 0.39184873 | N27: =N26+Trades!U26 -> 0.30763649 | O27: =O26+Trades!W26 -> 0.22348536
B28: PnL (gross) | C28: =SUMIF(Trades!M:M,"LONG",Trades!T:T) -> 1.5203962 | D28: =SUMIF(Trades!M:M,"SHORT",Trades!T:T) -> 1.9727929 | E28: =SUMIF(Trades!O:O,"Signal",Trades!T:T) -> 3.493189 | F28: =SUMIF(Trades!O:O,"Forced",Trades!T:T) -> 0 | L28: =Trades!P27 -> 35725 | M28: =M27+Trades!T27 -> 0.34908833 | N28: =N27+Trades!U27 -> 0.261401 | O28: =O27+Trades!W27 -> 0.17377276
B29: Number | C29: =COUNTIF(Trades!M:M,"LONG") -> 76 | D29: =COUNTIF(Trades!M:M,"SHORT") -> 96 | E29: =COUNTIF(Trades!O:O,"Signal") -> 172 | F29: =COUNTIF(Trades!O:O,"Forced") -> 0 | L29: =Trades!P28 -> 36516 | M29: =M28+Trades!T28 -> 0.42457391 | N29: =N28+Trades!U28 -> 0.33352923 | O29: =O28+Trades!W28 -> 0.24255003
L30: =Trades!P29 -> 37315 | M30: =M29+Trades!T29 -> 0.4739102 | N30: =N29+Trades!U29 -> 0.37950105 | O30: =O29+Trades!W29 -> 0.2851709
B31: min Holding time | C31: Max Holding time | D31: Win rate | L31: =Trades!P30 -> 37701 | M31: =M30+Trades!T30 -> 0.46854692 | N31: =N30+Trades!U30 -> 0.37078082 | O31: =O30+Trades!W30 -> 0.27309984
B32: 0 | C32: 3 | D32: =COUNTIFS(Trades!N:N,">="&B32,Trades!N:N,"<="&C32,Trades!T:T,">0")/(COUNTIFS(Trades!N:N,">="&B32,Trades!N:N,"<="&C32,Trades!T:T,">0")+COUNTIFS(Trades!N:N,">="&B32,Trades!N:N,"<="&C32,Trades!T:T,"<0")) -> 1 | L32: =Trades!P31 -> 38206 | M32: =M31+Trades!T31 -> 0.46803659 | N32: =N31+Trades!U31 -> 0.36691804 | O32: =O31+Trades!W31 -> 0.26588623
B33: 4 | C33: 7 | D33: =COUNTIFS(Trades!N:N,">="&B33,Trades!N:N,"<="&C33,Trades!T:T,">0")/(COUNTIFS(Trades!N:N,">="&B33,Trades!N:N,"<="&C33,Trades!T:T,">0")+COUNTIFS(Trades!N:N,">="&B33,Trades!N:N,"<="&C33,Trades!T:T,"<0")) -> 1 | L33: =Trades!P32 -> 38333 | M33: =M32+Trades!T32 -> 0.46572662 | N33: =N32+Trades!U32 -> 0.36125783 | O33: =O32+Trades!W32 -> 0.25687507
B34: 8 | C34: 11 | D34: =COUNTIFS(Trades!N:N,">="&B34,Trades!N:N,"<="&C34,Trades!T:T,">0")/(COUNTIFS(Trades!N:N,">="&B34,Trades!N:N,"<="&C34,Trades!T:T,">0")+COUNTIFS(Trades!N:N,">="&B34,Trades!N:N,"<="&C34,Trades!T:T,"<0")) -> 1 | L34: =Trades!P33 -> 38674 | M34: =M33+Trades!T33 -> 0.47411327 | N34: =N33+Trades!U33 -> 0.36629174 | O34: =O33+Trades!W33 -> 0.25855802
B35: 12 | C35: 15 | D35: =COUNTIFS(Trades!N:N,">="&B35,Trades!N:N,"<="&C35,Trades!T:T,">0")/(COUNTIFS(Trades!N:N,">="&B35,Trades!N:N,"<="&C35,Trades!T:T,">0")+COUNTIFS(Trades!N:N,">="&B35,Trades!N:N,"<="&C35,Trades!T:T,"<0")) -> 0.91304348 | L35: =Trades!P34 -> 39068 | M35: =M34+Trades!T34 -> 0.49006509 | N35: =N34+Trades!U34 -> 0.37889391 | O35: =O34+Trades!W34 -> 0.26780936
B36: 16 | C36: 1000000 | D36: =COUNTIFS(Trades!N:N,">="&B36,Trades!N:N,"<="&C36,Trades!T:T,">0")/(COUNTIFS(Trades!N:N,">="&B36,Trades!N:N,"<="&C36,Trades!T:T,">0")+COUNTIFS(Trades!N:N,">="&B36,Trades!N:N,"<="&C36,Trades!T:T,"<0")) -> 0.42465753 | L36: =Trades!P35 -> 39472 | M36: =M35+Trades!T35 -> 0.48895605 | N36: =N35+Trades!U35 -> 0.37444047 | O36: =O35+Trades!W35 -> 0.26000495
L37: =Trades!P36 -> 39624 | M37: =M36+Trades!T36 -> 0.48939196 | N37: =N36+Trades!U36 -> 0.37157092 | O37: =O36+Trades!W36 -> 0.25382881
L38: =Trades!P37 -> 39854 | M38: =M37+Trades!T37 -> 0.50577914 | N38: =N37+Trades!U37 -> 0.38465968 | O38: =O37+Trades!W37 -> 0.26361097
B39: Conclusion: | L39: =Trades!P38 -> 41036 | M39: =M38+Trades!T38 -> 0.43575968 | N39: =N38+Trades!U38 -> 0.31130822 | O39: =O38+Trades!W38 -> 0.1869529
B40: "The baseline strategy exhibits a positive gross trading edge, but this edge is insufficient to overcome the assumed transaction costs and slippage. Under the baseline execution assumptions, implementation frictions are the primary driver of the strategy's negative net performance." | L40: =Trades!P39 -> 41209 | M40: =M39+Trades!T39 -> 0.45162358 | N40: =N39+Trades!U39 -> 0.32386596 | O40: =O39+Trades!W39 -> 0.19620405
...

Sheet Comparison with multiple
B2: Metric | C2: Value | J2: Daily PnL table
B3: Net P&L | C3: =SUM(Trades!W2:W9652) -> 2.2131071
B4: Number of trades | C4: =COUNTA(Trades!A:A)-1 -> 172 | I4: {=_xlfn.LET( _xlpm.dates,_xlfn.SEQUENCE(DATE(2026,8,2)-DATE(2025,8,2)+1,,DATE(2025,8,2)), _xlfn._xlws.FILTER(_xlpm.dates,WEEKDAY(_xlpm.dates,2)<=5) )} -> 45873 | J4: {=SUMIFS('trades edited'!$W$2:$W$100000,'trades edited'!$Y$2:$Y$100000,_xlfn.ANCHORARRAY(I4))} -> 0
B5: P&L/trade | C5: =AVERAGE(Trades!W:W) -> 0.012866902 | I5: 45874 | J5: 0
B6: Daily P&L volatility | C6: =_xlfn.STDEV.S(_xlfn.ANCHORARRAY(J4)) -> 0.036810942 | I6: 45875 | J6: 0
B7: Sharpe-like measure | C7: =AVERAGE(_xlfn.ANCHORARRAY(J4))/_xlfn.STDEV.S(_xlfn.ANCHORARRAY(J4))*SQRT(252) -> 3.6707299 | I7: 45876 | J7: 0
B8: Max drawdown | C8: =MIN(Trades!W:W) -> -0.095289891 | I8: 45877 | J8: 0
B9: Max drawdown / total P&L | C9: =C8/C3 -> -0.043057062 | I9: 45880 | J9: 0
B10: Worst day | I10: 45881 | J10: 0
B11: Max concurrent positions | I11: 45882 | J11: 0
B12: Max gross exposure | I12: 45883 | J12: 0
I13: 45884 | J13: 0
I14: 45887 | J14: 0
I15: 45888 | J15: 0
I16: 45889 | J16: 0
I17: 45890 | J17: 0
I18: 45891 | J18: 0
I19: 45894 | J19: 0
I20: 45895 | J20: 0
I21: 45896 | J21: 0
I22: 45897 | J22: 0
I23: 45898 | J23: 0
I24: 45901 | J24: 0
... I263: 46234 | J263: 0
