Workbook

Sheet Trades
A1: window_id | B1: stock1 | C1: stock2 | D1: entry_timestamp | E1: entry_price_1 | F1: entry_price_2 | G1: entry_price_1_slipped | H1: entry_price_2_slipped | I1: entry_zscore | J1: hedge_ratio_entry | K1: position_size_1 | L1: position_size_2 | M1: direction | N1: holding_minutes | O1: exit_reason | P1: exit_timestamp | Q1: exit_price_1 | R1: exit_price_2 | S1: exit_zscore | T1: gross_pnl | U1: gross_pnl_slipped | V1: transaction_costs | W1: net_pnl
A2: 0 | B2: JPM | C2: USB | D2: 24221 | E2: 125.96 | F2: 42.885 | G2: 125.89702 | H2: 42.906442 | I2: 5.0954302 | J2: 0.44350025 | K2: -0.079390283 | L2: 0.10341617 | M2: SHORT | N2: 17 | O2: signal | P2: 24238 | Q2: 125.16 | R2: 42.48 | S2: 0.3822661 | T2: 0.021628676 | U2: 0.0072463717 | V2: 0.002886444 | W2: 0.0043599277
A3: 0 | B3: JPM | C3: USB | D3: 24611 | E3: 124.9 | F3: 42.03 | G3: 124.83755 | H3: 42.051015 | I3: 3.8158805 | J3: 0.44350025 | K3: -0.080064051 | L3: 0.10551993 | M3: SHORT | N3: 9 | O3: signal | P3: 24620 | Q3: 124.85 | R3: 42.305 | S3: 0.10836649 | T3: 0.033021183 | U3: 0.018573673 | V3: 0.002886444 | W3: 0.015687229
A4: 0 | B4: JPM | C4: USB | D4: 25001 | E4: 126.03 | F4: 42.51 | G4: 125.96698 | H4: 42.531255 | I4: 4.0339978 | J4: 0.44350025 | K4: -0.079346187 | L4: 0.10432845 | M4: SHORT | N4: 14 | O4: signal | P4: 25015 | Q4: 126.39 | R4: 42.79 | S4: 0.4591878 | T4: 0.0006473394 | U4: -0.013816551 | V4: 0.002886444 | W4: -0.016702995
A5: 0 | B5: JPM | C5: USB | D5: 25391 | E5: 127.51 | F5: 42.82 | G5: 127.44625 | H5: 42.84141 | I5: 4.1961131 | J5: 0.44350025 | K5: -0.078425222 | L5: 0.10357316 | M5: SHORT | N5: 17 | O5: signal | P5: 25408 | Q5: 127.19 | R5: 42.65 | S5: 0.45998303 | T5: 0.0074886344 | U5: -0.0069250164 | V5: 0.002886444 | W5: -0.0098114604
A6: 0 | B6: JPM | C6: USB | D6: 25759 | E6: 127.95 | F6: 42.93 | G6: 128.01397 | H6: 42.908535 | I6: -3.5120796 | J6: 0.44350025 | K6: 0.07815553 | L6: -0.10330777 | M6: LONG | N6: 8 | O6: signal | P6: 25767 | Q6: 128.075 | R6: 42.87 | S6: 0.48964696 | T6: 0.015967907 | U6: 0.0015311193 | V6: 0.002887557 | W6: -0.0013564377
A7: 0 | B7: JPM | C7: USB | D7: 26055 | E7: 129.52 | F7: 42.94 | G7: 129.45524 | H7: 42.96147 | I7: 3.9665501 | J7: 0.44350025 | K7: -0.077208153 | L7: 0.10328371 | M7: SHORT | N7: 16 | O7: signal | P7: 26071 | Q7: 129.435 | R7: 42.92 | S7: 0.41542634 | T7: 0.0044970188 | U7: -0.0099336696 | V7: 0.002886444 | W7: -0.012820114
A8: 0 | B8: JPM | C8: USB | D8: 26566 | E8: 127.19 | F8: 42.1 | G8: 127.2536 | H8: 42.07895 | I8: -3.6898053 | J8: 0.44350025 | K8: 0.078622533 | L8: -0.10534448 | M8: LONG | N8: 10 | O8: signal | P8: 26576 | Q8: 129.11 | R8: 42.63 | S8: 0.22009333 | T8: 0.09512269 | U8: 0.080584294 | V8: 0.002887557 | W8: 0.077696737
A9: 0 | B9: JPM | C9: USB | D9: 26956 | E9: 131.66 | F9: 43.12 | G9: 131.59417 | H9: 43.14156 | I9: 4.3572878 | J9: 0.44350025 | K9: -0.075953213 | L9: 0.10285256 | M9: SHORT | N9: 19 | O9: signal | P9: 26975 | Q9: 131.65 | R9: 43.215 | S9: 0.0073755512 | T9: 0.010530526 | U9: -0.0039089826 | V9: 0.002886444 | W9: -0.0067954266
A10: 0 | B10: JPM | C10: USB | D10: 27303 | E10: 131.265 | F10: 43.27 | G10: 131.19937 | H10: 43.291635 | I10: 3.8577795 | J10: 0.44350025 | K10: -0.07618177 | L10: 0.10249601 | M10: SHORT | N10: 8 | O10: signal | P10: 27311 | Q10: 131.21 | R10: 43.36 | S10: 0.068480925 | T10: 0.013414639 | U10: -0.0010228812 | V10: 0.002886444 | W10: -0.0039093252
A11: 0 | B11: JPM | C11: USB | D11: 27346 | E11: 130.86 | F11: 43.58 | G11: 130.92543 | H11: 43.55821 | I11: -3.8881717 | J11: 0.44350025 | K11: 0.076417545 | L11: -0.10176692 | M11: LONG | N11: 23 | O11: signal | P11: 27369 | Q11: 130.8 | R11: 43.775 | S11: -0.39608722 | T11: -0.024429603 | U11: -0.038872235 | V11: 0.002887557 | W11: -0.041759792
A12: 1 | B12: JPM | C12: USB | D12: 27901 | E12: 130.29 | F12: 43.52 | G12: 130.22485 | H12: 43.54176 | I12: 5.2941174 | J12: 0.35667904 | K12: -0.076751861 | L12: 0.081957501 | M12: SHORT | N12: 24 | O12: signal | P12: 27925 | Q12: 130.3 | R12: 43.42 | S12: 0.4502307 | T12: -0.0089632687 | U12: -0.022526345 | V12: 0.0027127148 | W12: -0.02523906
A13: 1 | B13: JPM | C13: USB | D13: 28128 | E13: 133.71 | F13: 44.19 | G13: 133.64315 | H13: 44.212095 | I13: 5.0567268 | J13: 0.35667904 | K13: -0.074788722 | L13: 0.080714878 | M13: SHORT | N13: 21 | O13: signal | P13: 28149 | Q13: 133.07 | R13: 44.15 | S13: 0.44059942 | T13: 0.044636187 | U13: 0.031094943 | V13: 0.0027127148 | W13: 0.028382228
... A576: 66 | B576: USB | C576: TFC | D576: 285025 | E576: 47.765 | F576: 45.45 | G576: 47.788883 | H576: 45.427275 | I576: -4.7880122 | J576: 1.1033864 | K576: 0.20935832 | L576: -0.24276928 | M576: LONG | N576: 29 | O576: signal | P576: 285054 | Q576: 47.815 | R576: 45.54 | S576: -0.4846789 | T576: -0.011381319 | U576: -0.032431341 | V576: 0.0042066693 | W576: -0.036638011

Sheet Analysis
L1: Exit timestamp | M1: Cumulative Gross PnL | N1: Cumulative Slipped PnL | O1: Cumulative Net PnL | Q1: min holding minutes | R1: max holding minutes | S1: Mean Net PnL | T1: Number of trades
B2: Rough Analysis of the baseline strategy | J2: Figures | L2: =Trades!P2 -> 24238 | M2: =Trades!T2 -> 0.021628676 | N2: =Trades!U2 -> 0.0072463717 | O2: =Trades!W2 -> 0.0043599277 | Q2: 0 | R2: 3 | S2: =AVERAGEIFS(Trades!W:W,Trades!N:N,">="&Q2,Trades!N:N,"<="&R2) -> 0.041925103 | T2: =COUNTIFS(Trades!N:N,">="&Q2,Trades!N:N,"<="&R2) -> 54
L3: =Trades!P3 -> 24620 | M3: =M2+Trades!T3 -> 0.054649859 | N3: =N2+Trades!U3 -> 0.025820044 | O3: =O2+Trades!W3 -> 0.020047156 | Q3: 4 | R3: 7 | S3: =AVERAGEIFS(Trades!W:W,Trades!N:N,">="&Q3,Trades!N:N,"<="&R3) -> 0.026221146 | T3: =COUNTIFS(Trades!N:N,">="&Q3,Trades!N:N,"<="&R3) -> 101
B4: Column1 | C4: Gross | D4: Slipped | E4: Net (Transaction costs) | L4: =Trades!P4 -> 25015 | M4: =M3+Trades!T4 -> 0.055297198 | N4: =N3+Trades!U4 -> 0.012003493 | O4: =O3+Trades!W4 -> 0.0033441609 | Q4: 8 | R4: 11 | S4: =AVERAGEIFS(Trades!W:W,Trades!N:N,">="&Q4,Trades!N:N,"<="&R4) -> 0.022615722 | T4: =COUNTIFS(Trades!N:N,">="&Q4,Trades!N:N,"<="&R4) -> 70
B5: Overall PnL | C5: =SUM(Trades!T2:T9652) -> 11.564936 | D5: =SUM(Trades!U2:U9652) -> 1.3132758 | E5: =SUM(Trades!W2:W9652) -> -0.7371206 | L5: =Trades!P5 -> 25408 | M5: =M4+Trades!T5 -> 0.062785833 | N5: =N4+Trades!U5 -> 0.0050784765 | O5: =O4+Trades!W5 -> -0.0064672995 | Q5: 12 | R5: 15 | S5: =AVERAGEIFS(Trades!W:W,Trades!N:N,">="&Q5,Trades!N:N,"<="&R5) -> 0.0063197382 | T5: =COUNTIFS(Trades!N:N,">="&Q5,Trades!N:N,"<="&R5) -> 64
B6: Mean PnL | C6: =AVERAGE(Trades!T:T) -> 0.020112932 | D6: =AVERAGE(Trades!U:U) -> 0.0022839579 | E6: =AVERAGE(Trades!W:W) -> -0.0012819489 | L6: =Trades!P6 -> 25767 | M6: =M5+Trades!T6 -> 0.07875374 | N6: =N5+Trades!U6 -> 0.0066095958 | O6: =O5+Trades!W6 -> -0.0078237372 | Q6: 16 | R6: 19 | S6: =AVERAGEIFS(Trades!W:W,Trades!N:N,">="&Q6,Trades!N:N,"<="&R6) -> -0.010115724 | T6: =COUNTIFS(Trades!N:N,">="&Q6,Trades!N:N,"<="&R6) -> 73 | W6: inflection points around 86299 and 163000
B7: Median PnL | C7: =MEDIAN(Trades!T:T) -> 0.013666419 | D7: =MEDIAN(Trades!U:U) -> -0.0032018717 | E7: =MEDIAN(Trades!W:W) -> -0.0065326685 | L7: =Trades!P7 -> 26071 | M7: =M6+Trades!T7 -> 0.083250759 | N7: =N6+Trades!U7 -> -0.0033240737 | O7: =O6+Trades!W7 -> -0.020643851 | Q7: 20 | R7: 23 | S7: =AVERAGEIFS(Trades!W:W,Trades!N:N,">="&Q7,Trades!N:N,"<="&R7) -> -0.015753091 | T7: =COUNTIFS(Trades!N:N,">="&Q7,Trades!N:N,"<="&R7) -> 103
B8: Max drawdown | C8: =MIN(Trades!T:T) -> -0.38368833 | D8: =MIN(Trades!U:U) -> -0.39930393 | E8: =MIN(Trades!W:W) -> -0.40235707 | L8: =Trades!P8 -> 26576 | M8: =M7+Trades!T8 -> 0.17837345 | N8: =N7+Trades!U8 -> 0.07726022 | O8: =O7+Trades!W8 -> 0.057052886 | Q8: 24 | R8: 27 | S8: =AVERAGEIFS(Trades!W:W,Trades!N:N,">="&Q8,Trades!N:N,"<="&R8) -> -0.016174578 | T8: =COUNTIFS(Trades!N:N,">="&Q8,Trades!N:N,"<="&R8) -> 38
B9: Biggest Winner | C9: =MAX(Trades!T:T) -> 0.51144834 | D9: =MAX(Trades!U:U) -> 0.50057409 | E9: =MAX(Trades!W:W) -> 0.4983492 | L9: =Trades!P9 -> 26975 | M9: =M8+Trades!T9 -> 0.18890397 | N9: =N8+Trades!U9 -> 0.073351237 | O9: =O8+Trades!W9 -> 0.050257459 | Q9: 28 | R9: 34 | S9: =AVERAGEIFS(Trades!W:W,Trades!N:N,">="&Q9,Trades!N:N,"<="&R9) -> -0.060487258 | T9: =COUNTIFS(Trades!N:N,">="&Q9,Trades!N:N,"<="&R9) -> 33
B10: Win rate | C10: =COUNTIF(Trades!T:T,">0")/(COUNTIF(Trades!T:T,">0")+COUNTIF(Trades!T:T,"<0")) -> 0.70782609 | D10: =COUNTIF(Trades!U:U,">0")/(COUNTIF(Trades!U:U,">0")+COUNTIF(Trades!U:U,"<0")) -> 0.44347826 | E10: =COUNTIF(Trades!W:W,">0")/(COUNTIF(Trades!W:W,">0")+COUNTIF(Trades!W:W,"<0")) -> 0.39130435 | L10: =Trades!P10 -> 27311 | M10: =M9+Trades!T10 -> 0.20231861 | N10: =N9+Trades!U10 -> 0.072328356 | O10: =O9+Trades!W10 -> 0.046348134 | Q10: 35 | R10: 40 | S10: =AVERAGEIFS(Trades!W:W,Trades!N:N,">="&Q10,Trades!N:N,"<="&R10) -> -0.073627931 | T10: =COUNTIFS(Trades!N:N,">="&Q10,Trades!N:N,"<="&R10) -> 15
B11: Profit Factor | C11: =SUMIF(Trades!T:T,">0",Trades!T:T)/ABS(SUMIF(Trades!T:T,"<0",Trades!T:T)) -> 2.7627934 | D11: =SUMIF(Trades!U:U,">0",Trades!U:U)/ABS(SUMIF(Trades!U:U,"<0",Trades!U:U)) -> 1.1231917 | E11: =SUMIF(Trades!W:W,">0",Trades!W:W)/ABS(SUMIF(Trades!W:W,"<0",Trades!W:W)) -> 0.9377272
L12: =Trades!P11 -> 27369 | M12: =M10+Trades!T11 -> 0.17788901 | N12: =N10+Trades!U11 -> 0.033456121 | O12: =O10+Trades!W11 -> 0.0045883419 | Q12: 41 | R12: 47 | S12: =AVERAGEIFS(Trades!W:W,Trades!N:N,">="&Q12,Trades!N:N,"<="&R12) -> -0.050185328 | T12: =COUNTIFS(Trades!N:N,">="&Q12,Trades!N:N,"<="&R12) -> 11
B13: Column1 | C13: Column2 | L13: =Trades!P12 -> 27925 | M13: =M12+Trades!T12 -> 0.16892574 | N13: =N12+Trades!U12 -> 0.010929776 | O13: =O12+Trades!W12 -> -0.020650718
B14: Number of Trades | C14: =COUNTA(Trades!A:A)-1 -> 575 | L14: =Trades!P13 -> 28149 | M14: =M13+Trades!T13 -> 0.21356193 | N14: =N13+Trades!U13 -> 0.042024719 | O14: =O13+Trades!W13 -> 0.0077315105
B15: Mean holding time | C15: =AVERAGE(Trades!N:N) -> 16.466087 | L15: =Trades!P14 -> 28530 | M15: =M14+Trades!T14 -> 0.22536839 | N15: =N14+Trades!U14 -> 0.040255894 | O15: =O14+Trades!W14 -> 0.0032499701
B16: Median holding time | C16: =MEDIAN(Trades!N:N) -> 15 | L16: =Trades!P15 -> 29068 | M16: =M15+Trades!T15 -> 0.24404893 | N16: =N15+Trades!U15 -> 0.045380984 | O16: =O15+Trades!W15 -> 0.0056623457
B17: Max holding time | C17: =MAX(Trades!N:N) -> 83 | L17: =Trades!P16 -> 29310 | M17: =M16+Trades!T16 -> 0.28044725 | N17: =N16+Trades!U16 -> 0.068260031 | O17: =O16+Trades!W16 -> 0.025828678
L18: =Trades!P17 -> 30086 | M18: =M17+Trades!T17 -> 0.35219505 | N18: =N17+Trades!U17 -> 0.12644128 | O18: =O17+Trades!W17 -> 0.081295922
B19: Column1 | C19: Positive | D19: Negative | L19: =Trades!P18 -> 30485 | M19: =M18+Trades!T18 -> 0.40765905 | N19: =N18+Trades!U18 -> 0.16838226 | O19: =O18+Trades!W18 -> 0.12052419
B20: Mean entry z score | C20: =AVERAGEIF(Trades!I:I,">0",Trades!I:I) -> 4.2298865 | D20: =AVERAGEIF(Trades!I:I,"<0",Trades!I:I) -> -4.230327 | L20: =Trades!P19 -> 31268 | M20: =M19+Trades!T19 -> 0.40685956 | N20: =N19+Trades!U19 -> 0.1540119 | O20: =O19+Trades!W19 -> 0.10344111
B21: Median entry z score | C21: {=MEDIAN(_xlfn._xlws.FILTER(Trades!I:I,Trades!I:I>0))} -> 4.0651845 | D21: {=MEDIAN(_xlfn._xlws.FILTER(Trades!I:I,Trades!I:I<0))} -> -4.0472387 | L21: =Trades!P20 -> 31824 | M21: =M20+Trades!T20 -> 0.39185474 | N21: =N20+Trades!U20 -> 0.12406884 | O21: =O20+Trades!W20 -> 0.070510116
B22: max entry z score | C22: =_xlfn.MAXIFS(Trades!I:I,Trades!I:I,">0") -> 5.2946498 | D22: =_xlfn.MINIFS(Trades!I:I,Trades!I:I,"<0") -> -5.2946498 | L22: =Trades!P21 -> 32060 | M22: =M21+Trades!T21 -> 0.36648119 | N22: =N21+Trades!U21 -> 0.083748331 | O22: =O21+Trades!W21 -> 0.027202671
B23: Mean exit z score | C23: =AVERAGEIF(Trades!S:S,">0",Trades!S:S) -> 0.32368605 | D23: =AVERAGEIF(Trades!S:S,"<0",Trades!S:S) -> -0.31398701 | L23: =Trades!P22 -> 32632 | M23: =M22+Trades!T22 -> 0.39728427 | N23: =N22+Trades!U22 -> 0.099629623 | O23: =O22+Trades!W22 -> 0.040097031
B24: Median exit z score | C24: {=MEDIAN(_xlfn._xlws.FILTER(Trades!S:S,Trades!S:S>0))} -> 0.35747761 | D24: {=MEDIAN(_xlfn._xlws.FILTER(Trades!S:S,Trades!S:S<0))} -> -0.34113421 | L24: =Trades!P23 -> 33060 | M24: =M23+Trades!T23 -> 0.29549804 | N24: =N23+Trades!U23 -> -0.016930567 | O24: =O23+Trades!W23 -> -0.079451104
B25: max exit z score | C25: =_xlfn.MAXIFS(Trades!S:S,Trades!S:S,">0") -> 0.49977221 | D25: =_xlfn.MINIFS(Trades!S:S,Trades!S:S,"<0") -> -0.49989708 | L25: =Trades!P24 -> 33428 | M25: =M24+Trades!T24 -> 0.297587 | N25: =N24+Trades!U24 -> -0.029737353 | O25: =O24+Trades!W24 -> -0.095244821
G26: 1 | H26: Edge is there, but wiped out by costs | L26: =Trades!P25 -> 33829 | M26: =M25+Trades!T25 -> 0.18628045 | N26: =N25+Trades!U25 -> -0.15596906 | O26: =O25+Trades!W25 -> -0.22446447
B27: Column1 | C27: Long | D27: Short | E27: Signal | F27: Forced | L27: =Trades!P26 -> 34979 | M27: =M26+Trades!T26 -> 0.2474001 | N27: =N26+Trades!U26 -> -0.10977409 | O27: =O26+Trades!W26 -> -0.18125745
B28: PnL (gross) | C28: =SUMIF(Trades!M:M,"LONG",Trades!T:T) -> 5.5851098 | D28: =SUMIF(Trades!M:M,"SHORT",Trades!T:T) -> 5.9798264 | E28: =SUMIF(Trades!O:O,"Signal",Trades!T:T) -> 11.564936 | F28: =SUMIF(Trades!O:O,"Forced",Trades!T:T) -> 0 | L28: =Trades!P27 -> 35452 | M28: =M27+Trades!T27 -> 0.26284222 | N28: =N27+Trades!U27 -> -0.10927217 | O28: =O27+Trades!W27 -> -0.18374347
B29: Number | C29: =COUNTIF(Trades!M:M,"LONG") -> 264 | D29: =COUNTIF(Trades!M:M,"SHORT") -> 311 | E29: =COUNTIF(Trades!O:O,"Signal") -> 575 | F29: =COUNTIF(Trades!O:O,"Forced") -> 0 | L29: =Trades!P28 -> 35724 | M29: =M28+Trades!T28 -> 0.25107343 | N29: =N28+Trades!U28 -> -0.13635268 | O29: =O28+Trades!W28 -> -0.21388365
L30: =Trades!P29 -> 36164 | M30: =M29+Trades!T29 -> 0.20618327 | N30: =N29+Trades!U29 -> -0.19658101 | O30: =O29+Trades!W29 -> -0.27717259
B31: min Holding time | C31: Max Holding time | D31: Win rate | L31: =Trades!P30 -> 36926 | M31: =M30+Trades!T30 -> 0.24793015 | N31: =N30+Trades!U30 -> -0.17014857 | O31: =O30+Trades!W30 -> -0.25379983
B32: 0 | C32: 3 | D32: =COUNTIFS(Trades!N:N,">="&B32,Trades!N:N,"<="&C32,Trades!T:T,">0")/(COUNTIFS(Trades!N:N,">="&B32,Trades!N:N,"<="&C32,Trades!T:T,">0")+COUNTIFS(Trades!N:N,">="&B32,Trades!N:N,"<="&C32,Trades!T:T,"<0")) -> 1 | L32: =Trades!P31 -> 37317 | M32: =M31+Trades!T31 -> 0.28413631 | N32: =N31+Trades!U31 -> -0.14925451 | O32: =O31+Trades!W31 -> -0.23596638
B33: 4 | C33: 7 | D33: =COUNTIFS(Trades!N:N,">="&B33,Trades!N:N,"<="&C33,Trades!T:T,">0")/(COUNTIFS(Trades!N:N,">="&B33,Trades!N:N,"<="&C33,Trades!T:T,">0")+COUNTIFS(Trades!N:N,">="&B33,Trades!N:N,"<="&C33,Trades!T:T,"<0")) -> 1 | L33: =Trades!P32 -> 37709 | M33: =M32+Trades!T32 -> 0.40410377 | N33: =N32+Trades!U32 -> -0.044539576 | O33: =O32+Trades!W32 -> -0.13431112
B34: 8 | C34: 11 | D34: =COUNTIFS(Trades!N:N,">="&B34,Trades!N:N,"<="&C34,Trades!T:T,">0")/(COUNTIFS(Trades!N:N,">="&B34,Trades!N:N,"<="&C34,Trades!T:T,">0")+COUNTIFS(Trades!N:N,">="&B34,Trades!N:N,"<="&C34,Trades!T:T,"<0")) -> 0.98571429 | L34: =Trades!P33 -> 37813 | M34: =M33+Trades!T33 -> 0.43712822 | N34: =N33+Trades!U33 -> -0.026815728 | O34: =O33+Trades!W33 -> -0.11964694
B35: 12 | C35: 15 | D35: =COUNTIFS(Trades!N:N,">="&B35,Trades!N:N,"<="&C35,Trades!T:T,">0")/(COUNTIFS(Trades!N:N,">="&B35,Trades!N:N,"<="&C35,Trades!T:T,">0")+COUNTIFS(Trades!N:N,">="&B35,Trades!N:N,"<="&C35,Trades!T:T,"<0")) -> 0.953125 | L35: =Trades!P34 -> 38916 | M35: =M34+Trades!T34 -> 0.60900895 | N35: =N34+Trades!U34 -> 0.1297026 | O35: =O34+Trades!W34 -> 0.033810775
B36: 16 | C36: 1000000 | D36: =COUNTIFS(Trades!N:N,">="&B36,Trades!N:N,"<="&C36,Trades!T:T,">0")/(COUNTIFS(Trades!N:N,">="&B36,Trades!N:N,"<="&C36,Trades!T:T,">0")+COUNTIFS(Trades!N:N,">="&B36,Trades!N:N,"<="&C36,Trades!T:T,"<0")) -> 0.42657343 | L36: =Trades!P35 -> 39290 | M36: =M35+Trades!T35 -> 0.69915907 | N36: =N35+Trades!U35 -> 0.20461447 | O36: =O35+Trades!W35 -> 0.10566298
L37: =Trades!P36 -> 39624 | M37: =M36+Trades!T36 -> 0.70337534 | N37: =N36+Trades!U36 -> 0.18553241 | O37: =O36+Trades!W36 -> 0.081926607
L38: =Trades!P37 -> 39687 | M38: =M37+Trades!T37 -> 0.73829694 | N38: =N37+Trades!U37 -> 0.19720567 | O38: =O37+Trades!W37 -> 0.088945554
B39: Conclusion: | L39: =Trades!P38 -> 39890 | M39: =M38+Trades!T38 -> 0.73910625 | N39: =N38+Trades!U38 -> 0.17473406 | O39: =O38+Trades!W38 -> 0.061818984
B40: "The baseline strategy exhibits a positive gross trading edge, but this edge is insufficient to overcome the assumed transaction costs and slippage. Under the baseline execution assumptions, implementation frictions are the primary driver of the strategy's negative net performance." | L40: =Trades!P39 -> 41094 | M40: =M39+Trades!T39 -> 0.75633023 | N40: =N39+Trades!U39 -> 0.16866897 | O40: =O39+Trades!W39 -> 0.051098923
...

Sheet Phase Analysis
B2: Metric | C2: Phase 1 - Aug 2022 - June 2023 | D2: Phase 2 - June 2023 - April 2024 | E2: Phase 3 - April 2024 - Aug 2025
B3: Number of trades
B4: Gross P&L
B5: Gross P&L / trade
B6: Net P&L @ base slippage
B7: Net P&L @ 5bps
B8: Net PF @ 5bps
B9: Win rate
B10: Mean winner
B11: Mean loser
B12: Mean holding time
B13: Median holding time
B14: Mean |entry Z|
B15: Trading frequency
